index,ts_recv,ts_event,rtype,publisher_id,instrument_id,action,side,depth,price,size,flags,ts_in_delta,sequence,bid_px_00,bid_sz_00,bid_ct_00,ask_px_00,ask_sz_00,ask_ct_00,bid_px_01,bid_sz_01,bid_ct_01,ask_px_01,ask_sz_01,ask_ct_01,bid_px_02,bid_sz_02,bid_ct_02,ask_px_02,ask_sz_02,ask_ct_02,bid_px_03,bid_sz_03,bid_ct_03,ask_px_03,ask_sz_03,ask_ct_03,bid_px_04,bid_sz_04,bid_ct_04,ask_px_04,ask_sz_04,ask_ct_04,bid_px_05,bid_sz_05,bid_ct_05,ask_px_05,ask_sz_05,ask_ct_05,bid_px_06,bid_sz_06,bid_ct_06,ask_px_06,ask_sz_06,ask_ct_06,bid_px_07,bid_sz_07,bid_ct_07,ask_px_07,ask_sz_07,ask_ct_07,bid_px_08,bid_sz_08,bid_ct_08,ask_px_08,ask_sz_08,ask_ct_08,bid_px_09,bid_sz_09,bid_ct_09,ask_px_09,ask_sz_09,ask_ct_09,symbol,order_id
1113,2025-07-17T15:43:54.126111293Z,2025-07-17T15:43:54.126111293Z,10,2,1108,A,A,0,13.810000000,15,130,165683,253121467,13.26,100,1,13.81,15,1,13.04,2,1,13.83,15,1,13.03,100,1,13.84,100,1,12.73,100,1,14.07,2,1,12.71,100,1,14.17,100,1,12.50,700,1,14.40,100,1,12.46,200,1,14.56,900,1,12.43,700,1,14.60,700,1,12.42,700,1,14.64,100,1,12.37,700,1,14.68,1400,1,ARL,301867541
1114,2025-07-17T15:43:54.998073317Z,2025-07-17T15:43:54.998073317Z,10,2,1108,C,A,0,13.840000000,100,0,165616,253137948,13.26,100,1,13.81,15,1,13.04,2,1,13.83,15,1,13.03,100,1,14.07,2,1,12.73,100,1,14.17,100,1,12.71,100,1,14.40,100,1,12.50,700,1,14.56,900,1,12.46,200,1,14.60,700,1,12.43,700,1,14.64,100,1,12.42,700,1,14.68,1400,1,12.37,700,1,14.77,200,1,ARL,301746949
1115,2025-07-17T15:43:54.998073317Z,2025-07-17T15:43:54.998073317Z,10,2,1108,A,A,0,13.820000000,100,130,165616,253137948,13.26,100,1,13.81,15,1,13.04,2,1,13.82,100,1,13.03,100,1,13.83,15,1,12.73,100,1,14.07,2,1,12.71,100,1,14.17,100,1,12.50,700,1,14.40,100,1,12.46,200,1,14.56,900,1,12.43,700,1,14.60,700,1,12.42,700,1,14.64,100,1,12.37,700,1,14.68,1400,1,ARL,301885353
1116,2025-07-17T15:43:55.019007300Z,2025-07-17T15:43:55.019007300Z,10,2,1108,C,A,0,14.170000000,100,130,165441,253138492,13.26,100,1,13.81,15,1,13.04,2,1,13.82,100,1,13.03,100,1,13.83,15,1,12.73,100,1,14.07,2,1,12.71,100,1,14.40,100,1,12.50,700,1,14.56,900,1,12.46,200,1,14.60,700,1,12.43,700,1,14.64,100,1,12.42,700,1,14.68,1400,1,12.37,700,1,14.77,200,1,ARL,301452785
1117,2025-07-17T15:43:55.019060515Z,2025-07-17T15:43:55.019060515Z,10,2,1108,A,A,0,14.100000000,100,130,165420,253138493,13.26,100,1,13.81,15,1,13.04,2,1,13.82,100,1,13.03,100,1,13.83,15,1,12.73,100,1,14.07,2,1,12.71,100,1,14.10,100,1,12.50,700,1,14.40,100,1,12.46,200,1,14.56,900,1,12.43,700,1,14.60,700,1,12.42,700,1,14.64,100,1,12.37,700,1,14.68,1400,1,ARL,301886057
1118,2025-07-17T15:44:01.698626200Z,2025-07-17T15:44:01.698626200Z,10,2,1108,C,A,0,13.830000000,15,130,165267,253246317,13.26,100,1,13.81,15,1,13.04,2,1,13.82,100,1,13.03,100,1,14.07,2,1,12.73,100,1,14.10,100,1,12.71,100,1,14.40,100,1,12.50,700,1,14.56,900,1,12.46,200,1,14.60,700,1,12.43,700,1,14.64,100,1,12.42,700,1,14.68,1400,1,12.37,700,1,14.77,200,1,ARL,301746941
1119,2025-07-17T15:44:04.014712730Z,2025-07-17T15:44:04.014712730Z,10,2,1108,A,A,0,13.830000000,100,130,165426,253292355,13.26,100,1,13.81,15,1,13.04,2,1,13.82,100,1,13.03,100,1,13.83,100,1,12.73,100,1,14.07,2,1,12.71,100,1,14.10,100,1,12.50,700,1,14.40,100,1,12.46,200,1,14.56,900,1,12.43,700,1,14.60,700,1,12.42,700,1,14.64,100,1,12.37,700,1,14.68,1400,1,ARL,302078553
1120,2025-07-17T15:44:05.055461574Z,2025-07-17T15:44:05.055461574Z,10,2,1108,A,A,0,13.810000000,100,130,165374,253307083,13.26,100,1,13.81,115,1,13.04,2,1,13.82,100,1,13.03,100,1,13.83,100,1,12.73,100,1,14.07,2,1,12.71,100,1,14.10,100,1,12.50,700,1,14.40,100,1,12.46,200,1,14.56,900,1,12.43,700,1,14.60,700,1,12.42,700,1,14.64,100,1,12.37,700,1,14.68,1400,1,ARL,302100649
1121,2025-07-17T15:44:05.062266845Z,2025-07-17T15:44:05.062266845Z,10,2,1108,C,A,0,13.830000000,100,130,165104,253307147,13.26,100,1,13.81,115,1,13.04,2,1,13.82,100,1,13.03,100,1,14.07,2,1,12.73,100,1,14.10,100,1,12.71,100,1,14.40,100,1,12.50,700,1,14.56,900,1,12.46,200,1,14.60,700,1,12.43,700,1,14.64,100,1,12.42,700,1,14.68,1400,1,12.37,700,1,14.77,200,1,ARL,302078553
1122,2025-07-17T15:44:09.389548394Z,2025-07-17T15:44:09.389548394Z,10,2,1108,A,A,0,13.760000000,15,130,165336,253384422,13.26,100,1,13.76,15,1,13.04,2,1,13.81,115,1,13.03,100,1,13.82,100,1,12.73,100,1,14.07,2,1,12.71,100,1,14.10,100,1,12.50,700,1,14.40,100,1,12.46,200,1,14.56,900,1,12.43,700,1,14.60,700,1,12.42,700,1,14.64,100,1,12.37,700,1,14.68,1400,1,ARL,302205249
1123,2025-07-17T15:44:09.390329935Z,2025-07-17T15:44:09.390329935Z,10,2,1108,C,A,0,14.770000000,100,0,166205,253384438,13.26,100,1,13.76,15,1,13.04,2,1,13.81,115,1,13.03,100,1,13.82,100,1,12.73,100,1,14.07,2,1,12.71,100,1,14.10,100,1,12.50,700,1,14.40,100,1,12.46,200,1,14.56,900,1,12.43,700,1,14.60,700,1,12.42,700,1,14.64,100,1,12.37,700,1,14.68,1400,1,ARL,301671709
1124,2025-07-17T15:44:09.390329935Z,2025-07-17T15:44:09.390329935Z,10,2,1108,A,A,0,14.660000000,100,128,166205,253384438,13.26,100,1,13.76,15,1,13.04,2,1,13.81,115,1,13.03,100,1,13.82,100,1,12.73,100,1,14.07,2,1,12.71,100,1,14.10,100,1,12.50,700,1,14.40,100,1,12.46,200,1,14.56,900,1,12.43,700,1,14.60,700,1,12.42,700,1,14.64,100,1,12.37,700,1,14.66,100,1,ARL,302205289
1125,2025-07-17T15:44:09.390893172Z,2025-07-17T15:44:09.390893172Z,10,2,1108,C,A,0,14.770000000,100,0,165314,253384456,13.26,100,1,13.76,15,1,13.04,2,1,13.81,115,1,13.03,100,1,13.82,100,1,12.73,100,1,14.07,2,1,12.71,100,1,14.10,100,1,12.50,700,1,14.40,100,1,12.46,200,1,14.56,900,1,12.43,700,1,14.60,700,1,12.42,700,1,14.64,100,1,12.37,700,1,14.66,100,1,ARL,301671713
1126,2025-07-17T15:44:09.390893172Z,2025-07-17T15:44:09.390893172Z,10,2,1108,A,A,0,14.660000000,100,130,165314,253384456,13.26,100,1,13.76,15,1,13.04,2,1,13.81,115,1,13.03,100,1,13.82,100,1,12.73,100,1,14.07,2,1,12.71,100,1,14.10,100,1,12.50,700,1,14.40,100,1,12.46,200,1,14.56,900,1,12.43,700,1,14.60,700,1,12.42,700,1,14.64,100,1,12.37,700,1,14.66,200,1,ARL,302205309
1127,2025-07-17T15:44:09.395281780Z,2025-07-17T15:44:09.395281780Z,10,2,1108,C,A,0,13.820000000,100,0,165832,253384698,13.26,100,1,13.76,15,1,13.04,2,1,13.81,115,1,13.03,100,1,14.07,2,1,12.73,100,1,14.10,100,1,12.71,100,1,14.40,100,1,12.50,700,1,14.56,900,1,12.46,200,1,14.60,700,1,12.43,700,1,14.64,100,1,12.42,700,1,14.66,200,1,12.37,700,1,14.68,1400,1,ARL,301885353
1128,2025-07-17T15:44:09.395281780Z,2025-07-17T15:44:09.395281780Z,10,2,1108,A,A,0,13.770000000,100,130,165832,253384698,13.26,100,1,13.76,15,1,13.04,2,1,13.77,100,1,13.03,100,1,13.81,115,1,12.73,100,1,14.07,2,1,12.71,100,1,14.10,100,1,12.50,700,1,14.40,100,1,12.46,200,1,14.56,900,1,12.43,700,1,14.60,700,1,12.42,700,1,14.64,100,1,12.37,700,1,14.66,200,1,ARL,302205493
1129,2025-07-17T15:44:09.396030225Z,2025-07-17T15:44:09.396030225Z,10,2,1108,C,A,0,14.910000000,100,0,165422,253384731,13.26,100,1,13.76,15,1,13.04,2,1,13.77,100,1,13.03,100,1,13.81,115,1,12.73,100,1,14.07,2,1,12.71,100,1,14.10,100,1,12.50,700,1,14.40,100,1,12.46,200,1,14.56,900,1,12.43,700,1,14.60,700,1,12.42,700,1,14.64,100,1,12.37,700,1,14.66,200,1,ARL,301746969
1130,2025-07-17T15:44:09.396030225Z,2025-07-17T15:44:09.396030225Z,10,2,1108,A,A,0,14.840000000,100,130,165422,253384731,13.26,100,1,13.76,15,1,13.04,2,1,13.77,100,1,13.03,100,1,13.81,115,1,12.73,100,1,14.07,2,1,12.71,100,1,14.10,100,1,12.50,700,1,14.40,100,1,12.46,200,1,14.56,900,1,12.43,700,1,14.60,700,1,12.42,700,1,14.64,100,1,12.37,700,1,14.66,200,1,ARL,302205537
1131,2025-07-17T15:44:09.397845986Z,2025-07-17T15:44:09.397845986Z,10,2,1108,A,A,0,13.790000000,100,130,165200,253384788,13.26,100,1,13.76,15,1,13.04,2,1,13.77,100,1,13.03,100,1,13.79,100,1,12.73,100,1,13.81,115,1,12.71,100,1,14.07,2,1,12.50,700,1,14.10,100,1,12.46,200,1,14.40,100,1,12.43,700,1,14.56,900,1,12.42,700,1,14.60,700,1,12.37,700,1,14.64,100,1,ARL,302205561
1132,2025-07-17T15:44:09.404663816Z,2025-07-17T15:44:09.404663816Z,10,2,1108,C,A,0,13.810000000,100,130,165140,253385013,13.26,100,1,13.76,15,1,13.04,2,1,13.77,100,1,13.03,100,1,13.79,100,1,12.73,100,1,13.81,15,1,12.71,100,1,14.07,2,1,12.50,700,1,14.10,100,1,12.46,200,1,14.40,100,1,12.43,700,1,14.56,900,1,12.42,700,1,14.60,700,1,12.37,700,1,14.64,100,1,ARL,302100649
1133,2025-07-17T15:44:20.402370565Z,2025-07-17T15:44:20.402370565Z,10,2,1108,C,A,0,13.810000000,15,130,165266,253562230,13.26,100,1,13.76,15,1,13.04,2,1,13.77,100,1,13.03,100,1,13.79,100,1,12.73,100,1,14.07,2,1,12.71,100,1,14.10,100,1,12.50,700,1,14.40,100,1,12.46,200,1,14.56,900,1,12.43,700,1,14.60,700,1,12.42,700,1,14.64,100,1,12.37,700,1,14.66,200,1,ARL,301867541
1134,2025-07-17T15:44:21.405320730Z,2025-07-17T15:44:21.405320730Z,10,2,1108,A,A,0,13.740000000,15,130,165392,253582427,13.26,100,1,13.74,15,1,13.04,2,1,13.76,15,1,13.03,100,1,13.77,100,1,12.73,100,1,13.79,100,1,12.71,100,1,14.07,2,1,12.50,700,1,14.10,100,1,12.46,200,1,14.40,100,1,12.43,700,1,14.56,900,1,12.42,700,1,14.60,700,1,12.37,700,1,14.64,100,1,ARL,302458113
1135,2025-07-17T15:44:21.843070079Z,2025-07-17T15:44:21.843070079Z,10,2,1108,C,A,0,13.770000000,100,0,165832,253590641,13.26,100,1,13.74,15,1,13.04,2,1,13.76,15,1,13.03,100,1,13.79,100,1,12.73,100,1,14.07,2,1,12.71,100,1,14.10,100,1,12.50,700,1,14.40,100,1,12.46,200,1,14.56,900,1,12.43,700,1,14.60,700,1,12.42,700,1,14.64,100,1,12.37,700,1,14.66,200,1,ARL,302205493
1136,2025-07-17T15:44:21.843070079Z,2025-07-17T15:44:21.843070079Z,10,2,1108,A,A,0,13.750000000,100,130,165832,253590641,13.26,100,1,13.74,15,1,13.04,2,1,13.75,100,1,13.03,100,1,13.76,15,1,12.73,100,1,13.79,100,1,12.71,100,1,14.07,2,1,12.50,700,1,14.10,100,1,12.46,200,1,14.40,100,1,12.43,700,1,14.56,900,1,12.42,700,1,14.60,700,1,12.37,700,1,14.64,100,1,ARL,302466045
1137,2025-07-17T15:44:21.855250804Z,2025-07-17T15:44:21.855250804Z,10,2,1108,C,A,0,14.100000000,100,130,165289,253590837,13.26,100,1,13.74,15,1,13.04,2,1,13.75,100,1,13.03,100,1,13.76,15,1,12.73,100,1,13.79,100,1,12.71,100,1,14.07,2,1,12.50,700,1,14.40,100,1,12.46,200,1,14.56,900,1,12.43,700,1,14.60,700,1,12.42,700,1,14.64,100,1,12.37,700,1,14.66,200,1,ARL,301886057
1138,2025-07-17T15:44:21.855305995Z,2025-07-17T15:44:21.855305995Z,10,2,1108,A,A,0,14.030000000,100,130,165163,253590838,13.26,100,1,13.74,15,1,13.04,2,1,13.75,100,1,13.03,100,1,13.76,15,1,12.73,100,1,13.79,100,1,12.71,100,1,14.03,100,1,12.50,700,1,14.07,2,1,12.46,200,1,14.40,100,1,12.43,700,1,14.56,900,1,12.42,700,1,14.60,700,1,12.37,700,1,14.64,100,1,ARL,302466157
1139,2025-07-17T15:44:24.446910206Z,2025-07-17T15:44:24.446910206Z,10,2,1108,A,A,0,13.770000000,100,130,165326,253614407,13.26,100,1,13.74,15,1,13.04,2,1,13.75,100,1,13.03,100,1,13.76,15,1,12.73,100,1,13.77,100,1,12.71,100,1,13.79,100,1,12.50,700,1,14.03,100,1,12.46,200,1,14.07,2,1,12.43,700,1,14.40,100,1,12.42,700,1,14.56,900,1,12.37,700,1,14.60,700,1,ARL,302500469
1140,2025-07-17T15:44:24.465390625Z,2025-07-17T15:44:24.465390625Z,10,2,1108,C,A,0,13.790000000,100,130,165193,253614591,13.26,100,1,13.74,15,1,13.04,2,1,13.75,100,1,13.03,100,1,13.76,15,1,12.73,100,1,13.77,100,1,12.71,100,1,14.03,100,1,12.50,700,1,14.07,2,1,12.46,200,1,14.40,100,1,12.43,700,1,14.56,900,1,12.42,700,1,14.60,700,1,12.37,700,1,14.64,100,1,ARL,302205561
1141,2025-07-17T15:44:30.846657613Z,2025-07-17T15:44:30.846657613Z,10,2,1108,C,A,0,13.760000000,15,130,165370,253704439,13.26,100,1,13.74,15,1,13.04,2,1,13.75,100,1,13.03,100,1,13.77,100,1,12.73,100,1,14.03,100,1,12.71,100,1,14.07,2,1,12.50,700,1,14.40,100,1,12.46,200,1,14.56,900,1,12.43,700,1,14.60,700,1,12.42,700,1,14.64,100,1,12.37,700,1,14.66,200,1,ARL,302205249
1142,2025-07-17T15:44:31.849618640Z,2025-07-17T15:44:31.849618640Z,10,2,1108,A,A,0,13.720000000,15,130,166053,253721156,13.26,100,1,13.72,15,1,13.04,2,1,13.74,15,1,13.03,100,1,13.75,100,1,12.73,100,1,13.77,100,1,12.71,100,1,14.03,100,1,12.50,700,1,14.07,2,1,12.46,200,1,14.40,100,1,12.43,700,1,14.56,900,1,12.42,700,1,14.60,700,1,12.37,700,1,14.64,100,1,ARL,302649021
1143,2025-07-17T15:44:31.849756452Z,2025-07-17T15:44:31.849756452Z,10,2,1108,A,A,0,13.750000000,100,130,165405,253721157,13.26,100,1,13.72,15,1,13.04,2,1,13.74,15,1,13.03,100,1,13.75,200,1,12.73,100,1,13.77,100,1,12.71,100,1,14.03,100,1,12.50,700,1,14.07,2,1,12.46,200,1,14.40,100,1,12.43,700,1,14.56,900,1,12.42,700,1,14.60,700,1,12.37,700,1,14.64,100,1,ARL,302649029
1144,2025-07-17T15:44:31.909959614Z,2025-07-17T15:44:31.909959614Z,10,2,1108,C,A,0,13.770000000,100,130,165364,253722140,13.26,100,1,13.72,15,1,13.04,2,1,13.74,15,1,13.03,100,1,13.75,200,1,12.73,100,1,14.03,100,1,12.71,100,1,14.07,2,1,12.50,700,1,14.40,100,1,12.46,200,1,14.56,900,1,12.43,700,1,14.60,700,1,12.42,700,1,14.64,100,1,12.37,700,1,14.66,200,1,ARL,302500469
1145,2025-07-17T15:44:32.484331764Z,2025-07-17T15:44:32.484331764Z,10,2,1108,C,A,0,13.750000000,100,0,165466,253730877,13.26,100,1,13.72,15,1,13.04,2,1,13.74,15,1,13.03,100,1,13.75,100,1,12.73,100,1,14.03,100,1,12.71,100,1,14.07,2,1,12.50,700,1,14.40,100,1,12.46,200,1,14.56,900,1,12.43,700,1,14.60,700,1,12.42,700,1,14.64,100,1,12.37,700,1,14.66,200,1,ARL,302466045
1146,2025-07-17T15:44:32.484331764Z,2025-07-17T15:44:32.484331764Z,10,2,1108,A,A,0,13.730000000,100,130,165466,253730877,13.26,100,1,13.72,15,1,13.04,2,1,13.73,100,1,13.03,100,1,13.74,15,1,12.73,100,1,13.75,100,1,12.71,100,1,14.03,100,1,12.50,700,1,14.07,2,1,12.46,200,1,14.40,100,1,12.43,700,1,14.56,900,1,12.42,700,1,14.60,700,1,12.37,700,1,14.64,100,1,ARL,302662769
1147,2025-07-17T15:44:32.485072552Z,2025-07-17T15:44:32.485072552Z,10,2,1108,C,A,0,14.840000000,100,0,165657,253730907,13.26,100,1,13.72,15,1,13.04,2,1,13.73,100,1,13.03,100,1,13.74,15,1,12.73,100,1,13.75,100,1,12.71,100,1,14.03,100,1,12.50,700,1,14.07,2,1,12.46,200,1,14.40,100,1,12.43,700,1,14.56,900,1,12.42,700,1,14.60,700,1,12.37,700,1,14.64,100,1,ARL,302205537
1148,2025-07-17T15:44:32.485072552Z,2025-07-17T15:44:32.485072552Z,10,2,1108,A,A,0,14.790000000,100,130,165657,253730907,13.26,100,1,13.72,15,1,13.04,2,1,13.73,100,1,13.03,100,1,13.74,15,1,12.73,100,1,13.75,100,1,12.71,100,1,14.03,100,1,12.50,700,1,14.07,2,1,12.46,200,1,14.40,100,1,12.43,700,1,14.56,900,1,12.42,700,1,14.60,700,1,12.37,700,1,14.64,100,1,ARL,302662821
1149,2025-07-17T15:44:33.389222513Z,2025-07-17T15:44:33.389222513Z,10,2,1108,A,A,0,14.280000000,100,130,165301,253745665,13.26,100,1,13.72,15,1,13.04,2,1,13.73,100,1,13.03,100,1,13.74,15,1,12.73,100,1,13.75,100,1,12.71,100,1,14.03,100,1,12.50,700,1,14.07,2,1,12.46,200,1,14.28,100,1,12.43,700,1,14.40,100,1,12.42,700,1,14.56,900,1,12.37,700,1,14.60,700,1,ARL,302681357
1150,2025-07-17T15:44:33.389223581Z,2025-07-17T15:44:33.389223581Z,10,2,1108,C,A,0,14.560000000,100,130,165449,253745666,13.26,100,1,13.72,15,1,13.04,2,1,13.73,100,1,13.03,100,1,13.74,15,1,12.73,100,1,13.75,100,1,12.71,100,1,14.03,100,1,12.50,700,1,14.07,2,1,12.46,200,1,14.28,100,1,12.43,700,1,14.40,100,1,12.42,700,1,14.56,800,1,12.37,700,1,14.60,700,1,ARL,146960005
1151,2025-07-17T15:44:36.362022168Z,2025-07-17T15:44:36.362022168Z,10,2,1108,C,A,0,13.740000000,15,130,165505,253783635,13.26,100,1,13.72,15,1,13.04,2,1,13.73,100,1,13.03,100,1,13.75,100,1,12.73,100,1,14.03,100,1,12.71,100,1,14.07,2,1,12.50,700,1,14.28,100,1,12.46,200,1,14.40,100,1,12.43,700,1,14.56,800,1,12.42,700,1,14.60,700,1,12.37,700,1,14.64,100,1,ARL,302458113
1152,2025-07-17T15:44:37.364212109Z,2025-07-17T15:44:37.364212109Z,10,2,1108,A,A,0,13.700000000,15,130,165310,253797506,13.26,100,1,13.70,15,1,13.04,2,1,13.72,15,1,13.03,100,1,13.73,100,1,12.73,100,1,13.75,100,1,12.71,100,1,14.03,100,1,12.50,700,1,14.07,2,1,12.46,200,1,14.28,100,1,12.43,700,1,14.40,100,1,12.42,700,1,14.56,800,1,12.37,700,1,14.60,700,1,ARL,302750929
1153,2025-07-17T15:44:37.364353897Z,2025-07-17T15:44:37.364353897Z,10,2,1108,A,A,0,13.730000000,100,130,165170,253797510,13.26,100,1,13.70,15,1,13.04,2,1,13.72,15,1,13.03,100,1,13.73,200,1,12.73,100,1,13.75,100,1,12.71,100,1,14.03,100,1,12.50,700,1,14.07,2,1,12.46,200,1,14.28,100,1,12.43,700,1,14.40,100,1,12.42,700,1,14.56,800,1,12.37,700,1,14.60,700,1,ARL,302750937
1154,2025-07-17T15:44:37.457954350Z,2025-07-17T15:44:37.457954350Z,10,2,1108,C,A,0,13.750000000,100,130,165144,253798432,13.26,100,1,13.70,15,1,13.04,2,1,13.72,15,1,13.03,100,1,13.73,200,1,12.73,100,1,14.03,100,1,12.71,100,1,14.07,2,1,12.50,700,1,14.28,100,1,12.46,200,1,14.40,100,1,12.43,700,1,14.56,800,1,12.42,700,1,14.60,700,1,12.37,700,1,14.64,100,1,ARL,302649029
1155,2025-07-17T15:44:38.432294362Z,2025-07-17T15:44:38.432294362Z,10,2,1108,C,A,0,13.730000000,100,0,166147,253807786,13.26,100,1,13.70,15,1,13.04,2,1,13.72,15,1,13.03,100,1,13.73,100,1,12.73,100,1,14.03,100,1,12.71,100,1,14.07,2,1,12.50,700,1,14.28,100,1,12.46,200,1,14.40,100,1,12.43,700,1,14.56,800,1,12.42,700,1,14.60,700,1,12.37,700,1,14.64,100,1,ARL,302662769
1156,2025-07-17T15:44:38.432294362Z,2025-07-17T15:44:38.432294362Z,10,2,1108,A,A,0,13.710000000,100,130,166147,253807786,13.26,100,1,13.70,15,1,13.04,2,1,13.71,100,1,13.03,100,1,13.72,15,1,12.73,100,1,13.73,100,1,12.71,100,1,14.03,100,1,12.50,700,1,14.07,2,1,12.46,200,1,14.28,100,1,12.43,700,1,14.40,100,1,12.42,700,1,14.56,800,1,12.37,700,1,14.60,700,1,ARL,302763889
1157,2025-07-17T15:44:38.439088042Z,2025-07-17T15:44:38.439088042Z,10,2,1108,C,A,0,15.920000000,100,0,165933,253808105,13.26,100,1,13.70,15,1,13.04,2,1,13.71,100,1,13.03,100,1,13.72,15,1,12.73,100,1,13.73,100,1,12.71,100,1,14.03,100,1,12.50,700,1,14.07,2,1,12.46,200,1,14.28,100,1,12.43,700,1,14.40,100,1,12.42,700,1,14.56,800,1,12.37,700,1,14.60,700,1,ARL,301747301
1158,2025-07-17T15:44:38.439088042Z,2025-07-17T15:44:38.439088042Z,10,2,1108,A,A,0,15.770000000,100,130,165933,253808105,13.26,100,1,13.70,15,1,13.04,2,1,13.71,100,1,13.03,100,1,13.72,15,1,12.73,100,1,13.73,100,1,12.71,100,1,14.03,100,1,12.50,700,1,14.07,2,1,12.46,200,1,14.28,100,1,12.43,700,1,14.40,100,1,12.42,700,1,14.56,800,1,12.37,700,1,14.60,700,1,ARL,302764121
1159,2025-07-17T15:44:38.440156077Z,2025-07-17T15:44:38.440156077Z,10,2,1108,C,A,0,17.580000000,100,0,165620,253808122,13.26,100,1,13.70,15,1,13.04,2,1,13.71,100,1,13.03,100,1,13.72,15,1,12.73,100,1,13.73,100,1,12.71,100,1,14.03,100,1,12.50,700,1,14.07,2,1,12.46,200,1,14.28,100,1,12.43,700,1,14.40,100,1,12.42,700,1,14.56,800,1,12.37,700,1,14.60,700,1,ARL,301747261
1160,2025-07-17T15:44:38.440156077Z,2025-07-17T15:44:38.440156077Z,10,2,1108,A,A,0,17.420000000,100,130,165620,253808122,13.26,100,1,13.70,15,1,13.04,2,1,13.71,100,1,13.03,100,1,13.72,15,1,12.73,100,1,13.73,100,1,12.71,100,1,14.03,100,1,12.50,700,1,14.07,2,1,12.46,200,1,14.28,100,1,12.43,700,1,14.40,100,1,12.42,700,1,14.56,800,1,12.37,700,1,14.60,700,1,ARL,302764137
1161,2025-07-17T15:44:43.019083502Z,2025-07-17T15:44:43.019083502Z,10,2,1108,C,A,0,13.700000000,15,128,178715,253875920,13.26,100,1,13.71,100,1,13.04,2,1,13.72,15,1,13.03,100,1,13.73,100,1,12.73,100,1,14.03,100,1,12.71,100,1,14.07,2,1,12.50,700,1,14.28,100,1,12.46,200,1,14.40,100,1,12.43,700,1,14.56,800,1,12.42,700,1,14.60,700,1,12.37,700,1,14.64,100,1,ARL,302750929
1162,2025-07-17T15:44:43.019184132Z,2025-07-17T15:44:43.019184132Z,10,2,1108,C,A,0,13.720000000,15,128,168526,253876010,13.26,100,1,13.71,100,1,13.04,2,1,13.73,100,1,13.03,100,1,14.03,100,1,12.73,100,1,14.07,2,1,12.71,100,1,14.28,100,1,12.50,700,1,14.40,100,1,12.46,200,1,14.56,800,1,12.43,700,1,14.60,700,1,12.42,700,1,14.64,100,1,12.37,700,1,14.66,200,1,ARL,302649021
1163,2025-07-17T15:44:44.075843113Z,2025-07-17T15:44:44.075843113Z,10,2,1108,A,A,0,13.700000000,15,128,166886,253892869,13.26,100,1,13.70,15,1,13.04,2,1,13.71,100,1,13.03,100,1,13.73,100,1,12.73,100,1,14.03,100,1,12.71,100,1,14.07,2,1,12.50,700,1,14.28,100,1,12.46,200,1,14.40,100,1,12.43,700,1,14.56,800,1,12.42,700,1,14.60,700,1,12.37,700,1,14.64,100,1,ARL,302867209
1164,2025-07-17T15:44:44.781464821Z,2025-07-17T15:44:44.781464821Z,10,2,1108,C,A,0,13.700000000,15,130,165911,253901222,13.26,100,1,13.71,100,1,13.04,2,1,13.73,100,1,13.03,100,1,14.03,100,1,12.73,100,1,14.07,2,1,12.71,100,1,14.28,100,1,12.50,700,1,14.40,100,1,12.46,200,1,14.56,800,1,12.43,700,1,14.60,700,1,12.42,700,1,14.64,100,1,12.37,700,1,14.66,200,1,ARL,302867209
1165,2025-07-17T15:44:53.143083969Z,2025-07-17T15:44:53.143083969Z,10,2,1108,C,A,0,13.730000000,100,130,165301,254011871,13.26,100,1,13.71,100,1,13.04,2,1,14.03,100,1,13.03,100,1,14.07,2,1,12.73,100,1,14.28,100,1,12.71,100,1,14.40,100,1,12.50,700,1,14.56,800,1,12.46,200,1,14.60,700,1,12.43,700,1,14.64,100,1,12.42,700,1,14.66,200,1,12.37,700,1,14.68,1400,1,ARL,302750937
1166,2025-07-17T15:44:57.191023026Z,2025-07-17T15:44:57.191023026Z,10,2,1108,A,A,0,13.750000000,100,130,165444,254079162,13.26,100,1,13.71,100,1,13.04,2,1,13.75,100,1,13.03,100,1,14.03,100,1,12.73,100,1,14.07,2,1,12.71,100,1,14.28,100,1,12.50,700,1,14.40,100,1,12.46,200,1,14.56,800,1,12.43,700,1,14.60,700,1,12.42,700,1,14.64,100,1,12.37,700,1,14.66,200,1,ARL,303118785
1167,2025-07-17T15:45:07.065587919Z,2025-07-17T15:45:07.065587919Z,10,2,1108,C,A,0,13.710000000,100,128,168655,254244597,13.26,100,1,13.75,100,1,13.04,2,1,14.03,100,1,13.03,100,1,14.07,2,1,12.73,100,1,14.28,100,1,12.71,100,1,14.40,100,1,12.50,700,1,14.56,800,1,12.46,200,1,14.60,700,1,12.43,700,1,14.64,100,1,12.42,700,1,14.66,200,1,12.37,700,1,14.68,1400,1,ARL,302763889
1168,2025-07-17T15:45:07.079966224Z,2025-07-17T15:45:07.079966224Z,10,2,1108,C,A,0,13.750000000,100,130,165281,254245492,13.26,100,1,14.03,100,1,13.04,2,1,14.07,2,1,13.03,100,1,14.28,100,1,12.73,100,1,14.40,100,1,12.71,100,1,14.56,800,1,12.50,700,1,14.60,700,1,12.46,200,1,14.64,100,1,12.43,700,1,14.66,200,1,12.42,700,1,14.68,1400,1,12.37,700,1,14.79,100,1,ARL,303118785
1169,2025-07-17T15:45:07.080521807Z,2025-07-17T15:45:07.080521807Z,10,2,1108,C,A,0,14.660000000,100,0,165408,254245505,13.26,100,1,14.03,100,1,13.04,2,1,14.07,2,1,13.03,100,1,14.28,100,1,12.73,100,1,14.40,100,1,12.71,100,1,14.56,800,1,12.50,700,1,14.60,700,1,12.46,200,1,14.64,100,1,12.43,700,1,14.66,100,1,12.42,700,1,14.68,1400,1,12.37,700,1,14.79,100,1,ARL,302205289
1170,2025-07-17T15:45:07.080521807Z,2025-07-17T15:45:07.080521807Z,10,2,1108,A,A,0,14.890000000,100,130,165408,254245505,13.26,100,1,14.03,100,1,13.04,2,1,14.07,2,1,13.03,100,1,14.28,100,1,12.73,100,1,14.40,100,1,12.71,100,1,14.56,800,1,12.50,700,1,14.60,700,1,12.46,200,1,14.64,100,1,12.43,700,1,14.66,100,1,12.42,700,1,14.68,1400,1,12.37,700,1,14.79,100,1,ARL,303330477
1171,2025-07-17T15:45:07.080706110Z,2025-07-17T15:45:07.080706110Z,10,2,1108,C,A,0,14.790000000,100,0,166135,254245511,13.26,100,1,14.03,100,1,13.04,2,1,14.07,2,1,13.03,100,1,14.28,100,1,12.73,100,1,14.40,100,1,12.71,100,1,14.56,800,1,12.50,700,1,14.60,700,1,12.46,200,1,14.64,100,1,12.43,700,1,14.66,100,1,12.42,700,1,14.68,1400,1,12.37,700,1,14.81,200,1,ARL,302662821
1172,2025-07-17T15:45:07.080706110Z,2025-07-17T15:45:07.080706110Z,10,2,1108,A,A,0,15.060000000,100,130,166135,254245511,13.26,100,1,14.03,100,1,13.04,2,1,14.07,2,1,13.03,100,1,14.28,100,1,12.73,100,1,14.40,100,1,12.71,100,1,14.56,800,1,12.50,700,1,14.60,700,1,12.46,200,1,14.64,100,1,12.43,700,1,14.66,100,1,12.42,700,1,14.68,1400,1,12.37,700,1,14.81,200,1,ARL,303330485
1173,2025-07-17T15:45:07.081407507Z,2025-07-17T15:45:07.081407507Z,10,2,1108,C,A,0,14.810000000,100,0,170557,254245568,13.26,100,1,14.03,100,1,13.04,2,1,14.07,2,1,13.03,100,1,14.28,100,1,12.73,100,1,14.40,100,1,12.71,100,1,14.56,800,1,12.50,700,1,14.60,700,1,12.46,200,1,14.64,100,1,12.43,700,1,14.66,100,1,12.42,700,1,14.68,1400,1,12.37,700,1,14.81,100,1,ARL,301747001
1174,2025-07-17T15:45:07.081407507Z,2025-07-17T15:45:07.081407507Z,10,2,1108,A,A,0,14.960000000,100,128,170557,254245568,13.26,100,1,14.03,100,1,13.04,2,1,14.07,2,1,13.03,100,1,14.28,100,1,12.73,100,1,14.40,100,1,12.71,100,1,14.56,800,1,12.50,700,1,14.60,700,1,12.46,200,1,14.64,100,1,12.43,700,1,14.66,100,1,12.42,700,1,14.68,1400,1,12.37,700,1,14.81,100,1,ARL,303330509
1175,2025-07-17T15:45:07.081441134Z,2025-07-17T15:45:07.081441134Z,10,2,1108,C,A,0,14.660000000,100,0,166836,254245576,13.26,100,1,14.03,100,1,13.04,2,1,14.07,2,1,13.03,100,1,14.28,100,1,12.73,100,1,14.40,100,1,12.71,100,1,14.56,800,1,12.50,700,1,14.60,700,1,12.46,200,1,14.64,100,1,12.43,700,1,14.68,1400,1,12.42,700,1,14.81,100,1,12.37,700,1,14.89,100,1,ARL,302205309
1176,2025-07-17T15:45:07.081441134Z,2025-07-17T15:45:07.081441134Z,10,2,1108,A,A,0,14.890000000,100,130,166836,254245576,13.26,100,1,14.03,100,1,13.04,2,1,14.07,2,1,13.03,100,1,14.28,100,1,12.73,100,1,14.40,100,1,12.71,100,1,14.56,800,1,12.50,700,1,14.60,700,1,12.46,200,1,14.64,100,1,12.43,700,1,14.68,1400,1,12.42,700,1,14.81,100,1,12.37,700,1,14.89,200,1,ARL,303330521
1177,2025-07-17T15:45:07.083732443Z,2025-07-17T15:45:07.083732443Z,10,2,1108,C,A,0,17.420000000,100,0,166556,254246327,13.26,100,1,14.03,100,1,13.04,2,1,14.07,2,1,13.03,100,1,14.28,100,1,12.73,100,1,14.40,100,1,12.71,100,1,14.56,800,1,12.50,700,1,14.60,700,1,12.46,200,1,14.64,100,1,12.43,700,1,14.68,1400,1,12.42,700,1,14.81,100,1,12.37,700,1,14.89,200,1,ARL,302764137
1178,2025-07-17T15:45:07.083732443Z,2025-07-17T15:45:07.083732443Z,10,2,1108,A,A,0,17.760000000,100,130,166556,254246327,13.26,100,1,14.03,100,1,13.04,2,1,14.07,2,1,13.03,100,1,14.28,100,1,12.73,100,1,14.40,100,1,12.71,100,1,14.56,800,1,12.50,700,1,14.60,700,1,12.46,200,1,14.64,100,1,12.43,700,1,14.68,1400,1,12.42,700,1,14.81,100,1,12.37,700,1,14.89,200,1,ARL,303331309
1179,2025-07-17T15:45:07.085057258Z,2025-07-17T15:45:07.085057258Z,10,2,1108,C,A,0,14.030000000,100,130,165267,254246434,13.26,100,1,14.07,2,1,13.04,2,1,14.28,100,1,13.03,100,1,14.40,100,1,12.73,100,1,14.56,800,1,12.71,100,1,14.60,700,1,12.50,700,1,14.64,100,1,12.46,200,1,14.68,1400,1,12.43,700,1,14.81,100,1,12.42,700,1,14.89,200,1,12.37,700,1,14.96,100,1,ARL,302466157
1180,2025-07-17T15:45:07.085109545Z,2025-07-17T15:45:07.085109545Z,10,2,1108,A,A,0,14.260000000,100,130,165307,254246437,13.26,100,1,14.07,2,1,13.04,2,1,14.26,100,1,13.03,100,1,14.28,100,1,12.73,100,1,14.40,100,1,12.71,100,1,14.56,800,1,12.50,700,1,14.60,700,1,12.46,200,1,14.64,100,1,12.43,700,1,14.68,1400,1,12.42,700,1,14.81,100,1,12.37,700,1,14.89,200,1,ARL,303331401
1181,2025-07-17T15:45:07.086368957Z,2025-07-17T15:45:07.086368957Z,10,2,1108,C,A,0,14.640000000,100,130,165743,254246501,13.26,100,1,14.07,2,1,13.04,2,1,14.26,100,1,13.03,100,1,14.28,100,1,12.73,100,1,14.40,100,1,12.71,100,1,14.56,800,1,12.50,700,1,14.60,700,1,12.46,200,1,14.68,1400,1,12.43,700,1,14.81,100,1,12.42,700,1,14.89,200,1,12.37,700,1,14.96,100,1,ARL,301747005
1182,2025-07-17T15:45:07.086494745Z,2025-07-17T15:45:07.086494745Z,10,2,1108,A,A,0,14.780000000,100,130,165580,254246502,13.26,100,1,14.07,2,1,13.04,2,1,14.26,100,1,13.03,100,1,14.28,100,1,12.73,100,1,14.40,100,1,12.71,100,1,14.56,800,1,12.50,700,1,14.60,700,1,12.46,200,1,14.68,1400,1,12.43,700,1,14.78,100,1,12.42,700,1,14.81,100,1,12.37,700,1,14.89,200,1,ARL,303331425
1183,2025-07-17T15:45:07.087223859Z,2025-07-17T15:45:07.087223859Z,10,2,1108,C,A,0,15.770000000,100,0,165607,254246529,13.26,100,1,14.07,2,1,13.04,2,1,14.26,100,1,13.03,100,1,14.28,100,1,12.73,100,1,14.40,100,1,12.71,100,1,14.56,800,1,12.50,700,1,14.60,700,1,12.46,200,1,14.68,1400,1,12.43,700,1,14.78,100,1,12.42,700,1,14.81,100,1,12.37,700,1,14.89,200,1,ARL,302764121
1184,2025-07-17T15:45:07.087223859Z,2025-07-17T15:45:07.087223859Z,10,2,1108,A,A,0,16.080000000,100,130,165607,254246529,13.26,100,1,14.07,2,1,13.04,2,1,14.26,100,1,13.03,100,1,14.28,100,1,12.73,100,1,14.40,100,1,12.71,100,1,14.56,800,1,12.50,700,1,14.60,700,1,12.46,200,1,14.68,1400,1,12.43,700,1,14.78,100,1,12.42,700,1,14.81,100,1,12.37,700,1,14.89,200,1,ARL,303331429
1185,2025-07-17T15:45:07.133812895Z,2025-07-17T15:45:07.133812895Z,10,2,1108,C,A,0,14.810000000,100,0,165593,254250625,13.26,100,1,14.07,2,1,13.04,2,1,14.26,100,1,13.03,100,1,14.28,100,1,12.73,100,1,14.40,100,1,12.71,100,1,14.56,800,1,12.50,700,1,14.60,700,1,12.46,200,1,14.68,1400,1,12.43,700,1,14.78,100,1,12.42,700,1,14.89,200,1,12.37,700,1,14.96,100,1,ARL,301747957
1186,2025-07-17T15:45:07.133812895Z,2025-07-17T15:45:07.133812895Z,10,2,1108,A,A,0,14.960000000,100,130,165593,254250625,13.26,100,1,14.07,2,1,13.04,2,1,14.26,100,1,13.03,100,1,14.28,100,1,12.73,100,1,14.40,100,1,12.71,100,1,14.56,800,1,12.50,700,1,14.60,700,1,12.46,200,1,14.68,1400,1,12.43,700,1,14.78,100,1,12.42,700,1,14.89,200,1,12.37,700,1,14.96,200,1,ARL,303334253
1187,2025-07-17T15:45:07.469796155Z,2025-07-17T15:45:07.469796155Z,10,2,1108,A,A,0,14.080000000,100,130,165147,254258029,13.26,100,1,14.07,2,1,13.04,2,1,14.08,100,1,13.03,100,1,14.26,100,1,12.73,100,1,14.28,100,1,12.71,100,1,14.40,100,1,12.50,700,1,14.56,800,1,12.46,200,1,14.60,700,1,12.43,700,1,14.68,1400,1,12.42,700,1,14.78,100,1,12.37,700,1,14.89,200,1,ARL,303340405
1188,2025-07-17T15:45:08.094603115Z,2025-07-17T15:45:08.094603115Z,10,2,1108,C,A,0,14.890000000,100,0,165437,254266885,13.26,100,1,14.07,2,1,13.04,2,1,14.08,100,1,13.03,100,1,14.26,100,1,12.73,100,1,14.28,100,1,12.71,100,1,14.40,100,1,12.50,700,1,14.56,800,1,12.46,200,1,14.60,700,1,12.43,700,1,14.68,1400,1,12.42,700,1,14.78,100,1,12.37,700,1,14.89,100,1,ARL,303330521
1189,2025-07-17T15:45:08.094603115Z,2025-07-17T15:45:08.094603115Z,10,2,1108,A,A,0,15.100000000,100,130,165437,254266885,13.26,100,1,14.07,2,1,13.04,2,1,14.08,100,1,13.03,100,1,14.26,100,1,12.73,100,1,14.28,100,1,12.71,100,1,14.40,100,1,12.50,700,1,14.56,800,1,12.46,200,1,14.60,700,1,12.43,700,1,14.68,1400,1,12.42,700,1,14.78,100,1,12.37,700,1,14.89,100,1,ARL,303349309
1190,2025-07-17T15:45:08.103141155Z,2025-07-17T15:45:08.103141155Z,10,2,1108,C,A,0,14.890000000,100,0,165489,254266971,13.26,100,1,14.07,2,1,13.04,2,1,14.08,100,1,13.03,100,1,14.26,100,1,12.73,100,1,14.28,100,1,12.71,100,1,14.40,100,1,12.50,700,1,14.56,800,1,12.46,200,1,14.60,700,1,12.43,700,1,14.68,1400,1,12.42,700,1,14.78,100,1,12.37,700,1,14.96,200,1,ARL,303330477
1191,2025-07-17T15:45:08.103141155Z,2025-07-17T15:45:08.103141155Z,10,2,1108,A,A,0,15.100000000,100,130,165489,254266971,13.26,100,1,14.07,2,1,13.04,2,1,14.08,100,1,13.03,100,1,14.26,100,1,12.73,100,1,14.28,100,1,12.71,100,1,14.40,100,1,12.50,700,1,14.56,800,1,12.46,200,1,14.60,700,1,12.43,700,1,14.68,1400,1,12.42,700,1,14.78,100,1,12.37,700,1,14.96,200,1,ARL,303349377
1192,2025-07-17T15:45:24.186842413Z,2025-07-17T15:45:24.186842413Z,10,2,1108,C,A,0,15.100000000,100,0,165865,254547413,13.26,100,1,14.07,2,1,13.04,2,1,14.08,100,1,13.03,100,1,14.26,100,1,12.73,100,1,14.28,100,1,12.71,100,1,14.40,100,1,12.50,700,1,14.56,800,1,12.46,200,1,14.60,700,1,12.43,700,1,14.68,1400,1,12.42,700,1,14.78,100,1,12.37,700,1,14.96,200,1,ARL,303349309
1193,2025-07-17T15:45:24.186842413Z,2025-07-17T15:45:24.186842413Z,10,2,1108,A,A,0,14.880000000,100,130,165865,254547413,13.26,100,1,14.07,2,1,13.04,2,1,14.08,100,1,13.03,100,1,14.26,100,1,12.73,100,1,14.28,100,1,12.71,100,1,14.40,100,1,12.50,700,1,14.56,800,1,12.46,200,1,14.60,700,1,12.43,700,1,14.68,1400,1,12.42,700,1,14.78,100,1,12.37,700,1,14.88,100,1,ARL,303682385
1194,2025-07-17T15:45:24.187276389Z,2025-07-17T15:45:24.187276389Z,10,2,1108,C,A,0,15.100000000,100,0,165503,254547415,13.26,100,1,14.07,2,1,13.04,2,1,14.08,100,1,13.03,100,1,14.26,100,1,12.73,100,1,14.28,100,1,12.71,100,1,14.40,100,1,12.50,700,1,14.56,800,1,12.46,200,1,14.60,700,1,12.43,700,1,14.68,1400,1,12.42,700,1,14.78,100,1,12.37,700,1,14.88,100,1,ARL,303349377
1195,2025-07-17T15:45:24.187276389Z,2025-07-17T15:45:24.187276389Z,10,2,1108,A,A,0,14.880000000,100,130,165503,254547415,13.26,100,1,14.07,2,1,13.04,2,1,14.08,100,1,13.03,100,1,14.26,100,1,12.73,100,1,14.28,100,1,12.71,100,1,14.40,100,1,12.50,700,1,14.56,800,1,12.46,200,1,14.60,700,1,12.43,700,1,14.68,1400,1,12.42,700,1,14.78,100,1,12.37,700,1,14.88,200,1,ARL,303682389
1196,2025-07-17T15:45:37.509289536Z,2025-07-17T15:45:37.509289536Z,10,2,1108,A,A,0,13.940000000,15,130,165352,254851462,13.26,100,1,13.94,15,1,13.04,2,1,14.07,2,1,13.03,100,1,14.08,100,1,12.73,100,1,14.26,100,1,12.71,100,1,14.28,100,1,12.50,700,1,14.40,100,1,12.46,200,1,14.56,800,1,12.43,700,1,14.60,700,1,12.42,700,1,14.68,1400,1,12.37,700,1,14.78,100,1,ARL,304056997
1197,2025-07-17T15:45:37.997967775Z,2025-07-17T15:45:37.997967775Z,10,2,1108,C,A,0,14.080000000,100,0,165722,254864588,13.26,100,1,13.94,15,1,13.04,2,1,14.07,2,1,13.03,100,1,14.26,100,1,12.73,100,1,14.28,100,1,12.71,100,1,14.40,100,1,12.50,700,1,14.56,800,1,12.46,200,1,14.60,700,1,12.43,700,1,14.68,1400,1,12.42,700,1,14.78,100,1,12.37,700,1,14.88,200,1,ARL,303340405
1198,2025-07-17T15:45:37.997967775Z,2025-07-17T15:45:37.997967775Z,10,2,1108,A,A,0,13.950000000,100,130,165722,254864588,13.26,100,1,13.94,15,1,13.04,2,1,13.95,100,1,13.03,100,1,14.07,2,1,12.73,100,1,14.26,100,1,12.71,100,1,14.28,100,1,12.50,700,1,14.40,100,1,12.46,200,1,14.56,800,1,12.43,700,1,14.60,700,1,12.42,700,1,14.68,1400,1,12.37,700,1,14.78,100,1,ARL,304072245
1199,2025-07-17T15:45:44.700428155Z,2025-07-17T15:45:44.700428155Z,10,2,1108,A,A,0,13.890000000,15,130,165253,254999429,13.26,100,1,13.89,15,1,13.04,2,1,13.94,15,1,13.03,100,1,13.95,100,1,12.73,100,1,14.07,2,1,12.71,100,1,14.26,100,1,12.50,700,1,14.28,100,1,12.46,200,1,14.40,100,1,12.43,700,1,14.56,800,1,12.42,700,1,14.60,700,1,12.37,700,1,14.68,1400,1,ARL,304238913
1200,2025-07-17T15:45:45.262371701Z,2025-07-17T15:45:45.262371701Z,10,2,1108,C,A,0,13.950000000,100,0,165421,255010979,13.26,100,1,13.89,15,1,13.04,2,1,13.94,15,1,13.03,100,1,14.07,2,1,12.73,100,1,14.26,100,1,12.71,100,1,14.28,100,1,12.50,700,1,14.40,100,1,12.46,200,1,14.56,800,1,12.43,700,1,14.60,700,1,12.42,700,1,14.68,1400,1,12.37,700,1,14.78,100,1,ARL,304072245
1201,2025-07-17T15:45:45.262371701Z,2025-07-17T15:45:45.262371701Z,10,2,1108,A,A,0,13.900000000,100,130,165421,255010979,13.26,100,1,13.89,15,1,13.04,2,1,13.90,100,1,13.03,100,1,13.94,15,1,12.73,100,1,14.07,2,1,12.71,100,1,14.26,100,1,12.50,700,1,14.28,100,1,12.46,200,1,14.40,100,1,12.43,700,1,14.56,800,1,12.42,700,1,14.60,700,1,12.37,700,1,14.68,1400,1,ARL,304252313
1202,2025-07-17T15:45:45.263123432Z,2025-07-17T15:45:45.263123432Z,10,2,1108,C,A,0,15.060000000,100,0,165591,255010987,13.26,100,1,13.89,15,1,13.04,2,1,13.90,100,1,13.03,100,1,13.94,15,1,12.73,100,1,14.07,2,1,12.71,100,1,14.26,100,1,12.50,700,1,14.28,100,1,12.46,200,1,14.40,100,1,12.43,700,1,14.56,800,1,12.42,700,1,14.60,700,1,12.37,700,1,14.68,1400,1,ARL,303330485
1203,2025-07-17T15:45:45.263123432Z,2025-07-17T15:45:45.263123432Z,10,2,1108,A,A,0,14.980000000,100,130,165591,255010987,13.26,100,1,13.89,15,1,13.04,2,1,13.90,100,1,13.03,100,1,13.94,15,1,12.73,100,1,14.07,2,1,12.71,100,1,14.26,100,1,12.50,700,1,14.28,100,1,12.46,200,1,14.40,100,1,12.43,700,1,14.56,800,1,12.42,700,1,14.60,700,1,12.37,700,1,14.68,1400,1,ARL,304252333
1204,2025-07-17T15:45:45.274194870Z,2025-07-17T15:45:45.274194870Z,10,2,1108,C,A,0,14.260000000,100,130,165512,255011158,13.26,100,1,13.89,15,1,13.04,2,1,13.90,100,1,13.03,100,1,13.94,15,1,12.73,100,1,14.07,2,1,12.71,100,1,14.28,100,1,12.50,700,1,14.40,100,1,12.46,200,1,14.56,800,1,12.43,700,1,14.60,700,1,12.42,700,1,14.68,1400,1,12.37,700,1,14.78,100,1,ARL,303331401
1205,2025-07-17T15:45:45.274245387Z,2025-07-17T15:45:45.274245387Z,10,2,1108,A,A,0,14.180000000,100,130,165334,255011161,13.26,100,1,13.89,15,1,13.04,2,1,13.90,100,1,13.03,100,1,13.94,15,1,12.73,100,1,14.07,2,1,12.71,100,1,14.18,100,1,12.50,700,1,14.28,100,1,12.46,200,1,14.40,100,1,12.43,700,1,14.56,800,1,12.42,700,1,14.60,700,1,12.37,700,1,14.68,1400,1,ARL,304252469
1206,2025-07-17T15:45:58.419617935Z,2025-07-17T15:45:58.419617935Z,10,2,1108,C,A,0,13.940000000,15,130,165398,255183198,13.26,100,1,13.89,15,1,13.04,2,1,13.90,100,1,13.03,100,1,14.07,2,1,12.73,100,1,14.18,100,1,12.71,100,1,14.28,100,1,12.50,700,1,14.40,100,1,12.46,200,1,14.56,800,1,12.43,700,1,14.60,700,1,12.42,700,1,14.68,1400,1,12.37,700,1,14.78,100,1,ARL,304056997
1207,2025-07-17T15:45:58.420113307Z,2025-07-17T15:45:58.420113307Z,10,2,1108,C,A,0,14.880000000,100,0,165384,255183203,13.26,100,1,13.89,15,1,13.04,2,1,13.90,100,1,13.03,100,1,14.07,2,1,12.73,100,1,14.18,100,1,12.71,100,1,14.28,100,1,12.50,700,1,14.40,100,1,12.46,200,1,14.56,800,1,12.43,700,1,14.60,700,1,12.42,700,1,14.68,1400,1,12.37,700,1,14.78,100,1,ARL,303682389
1208,2025-07-17T15:45:58.420113307Z,2025-07-17T15:45:58.420113307Z,10,2,1108,A,A,0,14.770000000,100,130,165384,255183203,13.26,100,1,13.89,15,1,13.04,2,1,13.90,100,1,13.03,100,1,14.07,2,1,12.73,100,1,14.18,100,1,12.71,100,1,14.28,100,1,12.50,700,1,14.40,100,1,12.46,200,1,14.56,800,1,12.43,700,1,14.60,700,1,12.42,700,1,14.68,1400,1,12.37,700,1,14.77,100,1,ARL,304503585
1209,2025-07-17T15:45:58.420590199Z,2025-07-17T15:45:58.420590199Z,10,2,1108,C,A,0,14.880000000,100,0,165690,255183204,13.26,100,1,13.89,15,1,13.04,2,1,13.90,100,1,13.03,100,1,14.07,2,1,12.73,100,1,14.18,100,1,12.71,100,1,14.28,100,1,12.50,700,1,14.40,100,1,12.46,200,1,14.56,800,1,12.43,700,1,14.60,700,1,12.42,700,1,14.68,1400,1,12.37,700,1,14.77,100,1,ARL,303682385
1210,2025-07-17T15:45:58.420590199Z,2025-07-17T15:45:58.420590199Z,10,2,1108,A,A,0,14.770000000,100,130,165690,255183204,13.26,100,1,13.89,15,1,13.04,2,1,13.90,100,1,13.03,100,1,14.07,2,1,12.73,100,1,14.18,100,1,12.71,100,1,14.28,100,1,12.50,700,1,14.40,100,1,12.46,200,1,14.56,800,1,12.43,700,1,14.60,700,1,12.42,700,1,14.68,1400,1,12.37,700,1,14.77,200,1,ARL,304503593
1211,2025-07-17T15:45:58.782726994Z,2025-07-17T15:45:58.782726994Z,10,2,1108,C,A,0,13.890000000,15,130,165115,255189425,13.26,100,1,13.90,100,1,13.04,2,1,14.07,2,1,13.03,100,1,14.18,100,1,12.73,100,1,14.28,100,1,12.71,100,1,14.40,100,1,12.50,700,1,14.56,800,1,12.46,200,1,14.60,700,1,12.43,700,1,14.68,1400,1,12.42,700,1,14.77,200,1,12.37,700,1,14.78,100,1,ARL,304238913
1212,2025-07-17T15:46:16.782892334Z,2025-07-17T15:46:16.782892334Z,10,2,1108,A,A,0,13.880000000,15,130,165282,255552962,13.26,100,1,13.88,15,1,13.04,2,1,13.90,100,1,13.03,100,1,14.07,2,1,12.73,100,1,14.18,100,1,12.71,100,1,14.28,100,1,12.50,700,1,14.40,100,1,12.46,200,1,14.56,800,1,12.43,700,1,14.60,700,1,12.42,700,1,14.68,1400,1,12.37,700,1,14.77,200,1,ARL,304949689
1213,2025-07-17T15:46:16.783160795Z,2025-07-17T15:46:16.783160795Z,10,2,1108,C,A,0,13.900000000,100,0,165446,255552970,13.26,100,1,13.88,15,1,13.04,2,1,14.07,2,1,13.03,100,1,14.18,100,1,12.73,100,1,14.28,100,1,12.71,100,1,14.40,100,1,12.50,700,1,14.56,800,1,12.46,200,1,14.60,700,1,12.43,700,1,14.68,1400,1,12.42,700,1,14.77,200,1,12.37,700,1,14.78,100,1,ARL,304252313
1214,2025-07-17T15:46:16.783160795Z,2025-07-17T15:46:16.783160795Z,10,2,1108,A,A,0,13.890000000,100,130,165446,255552970,13.26,100,1,13.88,15,1,13.04,2,1,13.89,100,1,13.03,100,1,14.07,2,1,12.73,100,1,14.18,100,1,12.71,100,1,14.28,100,1,12.50,700,1,14.40,100,1,12.46,200,1,14.56,800,1,12.43,700,1,14.60,700,1,12.42,700,1,14.68,1400,1,12.37,700,1,14.77,200,1,ARL,304949697
1215,2025-07-17T15:46:18.782732218Z,2025-07-17T15:46:18.782732218Z,10,2,1108,C,A,0,13.880000000,15,130,165352,255587336,13.26,100,1,13.89,100,1,13.04,2,1,14.07,2,1,13.03,100,1,14.18,100,1,12.73,100,1,14.28,100,1,12.71,100,1,14.40,100,1,12.50,700,1,14.56,800,1,12.46,200,1,14.60,700,1,12.43,700,1,14.68,1400,1,12.42,700,1,14.77,200,1,12.37,700,1,14.78,100,1,ARL,304949689
1216,2025-07-17T15:46:28.474001551Z,2025-07-17T15:46:28.474001551Z,10,2,1108,C,A,0,13.890000000,100,130,165346,255746167,13.26,100,1,14.07,2,1,13.04,2,1,14.18,100,1,13.03,100,1,14.28,100,1,12.73,100,1,14.40,100,1,12.71,100,1,14.56,800,1,12.50,700,1,14.60,700,1,12.46,200,1,14.68,1400,1,12.43,700,1,14.77,200,1,12.42,700,1,14.78,100,1,12.37,700,1,14.96,200,1,ARL,304949697
1217,2025-07-17T15:46:28.474561156Z,2025-07-17T15:46:28.474561156Z,10,2,1108,C,A,0,14.770000000,100,0,165438,255746173,13.26,100,1,14.07,2,1,13.04,2,1,14.18,100,1,13.03,100,1,14.28,100,1,12.73,100,1,14.40,100,1,12.71,100,1,14.56,800,1,12.50,700,1,14.60,700,1,12.46,200,1,14.68,1400,1,12.43,700,1,14.77,100,1,12.42,700,1,14.78,100,1,12.37,700,1,14.96,200,1,ARL,304503593
1218,2025-07-17T15:46:28.474561156Z,2025-07-17T15:46:28.474561156Z,10,2,1108,A,A,0,14.880000000,100,130,165438,255746173,13.26,100,1,14.07,2,1,13.04,2,1,14.18,100,1,13.03,100,1,14.28,100,1,12.73,100,1,14.40,100,1,12.71,100,1,14.56,800,1,12.50,700,1,14.60,700,1,12.46,200,1,14.68,1400,1,12.43,700,1,14.77,100,1,12.42,700,1,14.78,100,1,12.37,700,1,14.88,100,1,ARL,305184937
1219,2025-07-17T15:46:28.474730225Z,2025-07-17T15:46:28.474730225Z,10,2,1108,C,A,0,14.770000000,100,0,166235,255746176,13.26,100,1,14.07,2,1,13.04,2,1,14.18,100,1,13.03,100,1,14.28,100,1,12.73,100,1,14.40,100,1,12.71,100,1,14.56,800,1,12.50,700,1,14.60,700,1,12.46,200,1,14.68,1400,1,12.43,700,1,14.78,100,1,12.42,700,1,14.88,100,1,12.37,700,1,14.96,200,1,ARL,304503585
1220,2025-07-17T15:46:28.474730225Z,2025-07-17T15:46:28.474730225Z,10,2,1108,A,A,0,14.880000000,100,130,166235,255746176,13.26,100,1,14.07,2,1,13.04,2,1,14.18,100,1,13.03,100,1,14.28,100,1,12.73,100,1,14.40,100,1,12.71,100,1,14.56,800,1,12.50,700,1,14.60,700,1,12.46,200,1,14.68,1400,1,12.43,700,1,14.78,100,1,12.42,700,1,14.88,200,1,12.37,700,1,14.96,200,1,ARL,305184953
1221,2025-07-17T15:46:28.474736101Z,2025-07-17T15:46:28.474736101Z,10,2,1108,C,A,0,14.980000000,100,0,166053,255746178,13.26,100,1,14.07,2,1,13.04,2,1,14.18,100,1,13.03,100,1,14.28,100,1,12.73,100,1,14.40,100,1,12.71,100,1,14.56,800,1,12.50,700,1,14.60,700,1,12.46,200,1,14.68,1400,1,12.43,700,1,14.78,100,1,12.42,700,1,14.88,200,1,12.37,700,1,14.96,200,1,ARL,304252333
1222,2025-07-17T15:46:28.474736101Z,2025-07-17T15:46:28.474736101Z,10,2,1108,A,A,0,15.030000000,100,128,166053,255746178,13.26,100,1,14.07,2,1,13.04,2,1,14.18,100,1,13.03,100,1,14.28,100,1,12.73,100,1,14.40,100,1,12.71,100,1,14.56,800,1,12.50,700,1,14.60,700,1,12.46,200,1,14.68,1400,1,12.43,700,1,14.78,100,1,12.42,700,1,14.88,200,1,12.37,700,1,14.96,200,1,ARL,305184957
1223,2025-07-17T15:46:28.492716775Z,2025-07-17T15:46:28.492716775Z,10,2,1108,C,A,0,14.180000000,100,130,165205,255746619,13.26,100,1,14.07,2,1,13.04,2,1,14.28,100,1,13.03,100,1,14.40,100,1,12.73,100,1,14.56,800,1,12.71,100,1,14.60,700,1,12.50,700,1,14.68,1400,1,12.46,200,1,14.78,100,1,12.43,700,1,14.88,200,1,12.42,700,1,14.96,200,1,12.37,700,1,15.03,100,1,ARL,304252469
1224,2025-07-17T15:46:28.492765859Z,2025-07-17T15:46:28.492765859Z,10,2,1108,A,A,0,14.260000000,100,130,165420,255746621,13.26,100,1,14.07,2,1,13.04,2,1,14.26,100,1,13.03,100,1,14.28,100,1,12.73,100,1,14.40,100,1,12.71,100,1,14.56,800,1,12.50,700,1,14.60,700,1,12.46,200,1,14.68,1400,1,12.43,700,1,14.78,100,1,12.42,700,1,14.88,200,1,12.37,700,1,14.96,200,1,ARL,305185529
1225,2025-07-17T15:46:28.646108242Z,2025-07-17T15:46:28.646108242Z,10,2,1108,A,A,0,14.080000000,100,130,165225,255748568,13.26,100,1,14.07,2,1,13.04,2,1,14.08,100,1,13.03,100,1,14.26,100,1,12.73,100,1,14.28,100,1,12.71,100,1,14.40,100,1,12.50,700,1,14.56,800,1,12.46,200,1,14.60,700,1,12.43,700,1,14.68,1400,1,12.42,700,1,14.78,100,1,12.37,700,1,14.88,200,1,ARL,305187077
1226,2025-07-17T15:46:57.523859388Z,2025-07-17T15:46:57.523859388Z,10,2,1108,A,A,0,13.920000000,15,130,165270,256268482,13.26,100,1,13.92,15,1,13.04,2,1,14.07,2,1,13.03,100,1,14.08,100,1,12.73,100,1,14.26,100,1,12.71,100,1,14.28,100,1,12.50,700,1,14.40,100,1,12.46,200,1,14.56,800,1,12.43,700,1,14.60,700,1,12.42,700,1,14.68,1400,1,12.37,700,1,14.78,100,1,ARL,305862145
1227,2025-07-17T15:46:57.932677299Z,2025-07-17T15:46:57.932677299Z,10,2,1108,C,A,0,14.080000000,100,0,165695,256280751,13.26,100,1,13.92,15,1,13.04,2,1,14.07,2,1,13.03,100,1,14.26,100,1,12.73,100,1,14.28,100,1,12.71,100,1,14.40,100,1,12.50,700,1,14.56,800,1,12.46,200,1,14.60,700,1,12.43,700,1,14.68,1400,1,12.42,700,1,14.78,100,1,12.37,700,1,14.88,200,1,ARL,305187077
1228,2025-07-17T15:46:57.932677299Z,2025-07-17T15:46:57.932677299Z,10,2,1108,A,A,0,13.930000000,100,130,165695,256280751,13.26,100,1,13.92,15,1,13.04,2,1,13.93,100,1,13.03,100,1,14.07,2,1,12.73,100,1,14.26,100,1,12.71,100,1,14.28,100,1,12.50,700,1,14.40,100,1,12.46,200,1,14.56,800,1,12.43,700,1,14.60,700,1,12.42,700,1,14.68,1400,1,12.37,700,1,14.78,100,1,ARL,305878881
1229,2025-07-17T15:47:06.609290857Z,2025-07-17T15:47:06.609290857Z,10,2,1108,A,A,0,13.880000000,15,130,165394,256488374,13.26,100,1,13.88,15,1,13.04,2,1,13.92,15,1,13.03,100,1,13.93,100,1,12.73,100,1,14.07,2,1,12.71,100,1,14.26,100,1,12.50,700,1,14.28,100,1,12.46,200,1,14.40,100,1,12.43,700,1,14.56,800,1,12.42,700,1,14.60,700,1,12.37,700,1,14.68,1400,1,ARL,306121113
1230,2025-07-17T15:47:08.787529505Z,2025-07-17T15:47:08.787529505Z,10,2,1108,C,A,0,13.930000000,100,0,165639,256532991,13.26,100,1,13.88,15,1,13.04,2,1,13.92,15,1,13.03,100,1,14.07,2,1,12.73,100,1,14.26,100,1,12.71,100,1,14.28,100,1,12.50,700,1,14.40,100,1,12.46,200,1,14.56,800,1,12.43,700,1,14.60,700,1,12.42,700,1,14.68,1400,1,12.37,700,1,14.78,100,1,ARL,305878881
1231,2025-07-17T15:47:08.787529505Z,2025-07-17T15:47:08.787529505Z,10,2,1108,A,A,0,13.890000000,100,130,165639,256532991,13.26,100,1,13.88,15,1,13.04,2,1,13.89,100,1,13.03,100,1,13.92,15,1,12.73,100,1,14.07,2,1,12.71,100,1,14.26,100,1,12.50,700,1,14.28,100,1,12.46,200,1,14.40,100,1,12.43,700,1,14.56,800,1,12.42,700,1,14.60,700,1,12.37,700,1,14.68,1400,1,ARL,306170837
1232,2025-07-17T15:47:08.788275184Z,2025-07-17T15:47:08.788275184Z,10,2,1108,C,A,0,15.030000000,100,0,165578,256533005,13.26,100,1,13.88,15,1,13.04,2,1,13.89,100,1,13.03,100,1,13.92,15,1,12.73,100,1,14.07,2,1,12.71,100,1,14.26,100,1,12.50,700,1,14.28,100,1,12.46,200,1,14.40,100,1,12.43,700,1,14.56,800,1,12.42,700,1,14.60,700,1,12.37,700,1,14.68,1400,1,ARL,305184957
1233,2025-07-17T15:47:08.788275184Z,2025-07-17T15:47:08.788275184Z,10,2,1108,A,A,0,14.970000000,100,130,165578,256533005,13.26,100,1,13.88,15,1,13.04,2,1,13.89,100,1,13.03,100,1,13.92,15,1,12.73,100,1,14.07,2,1,12.71,100,1,14.26,100,1,12.50,700,1,14.28,100,1,12.46,200,1,14.40,100,1,12.43,700,1,14.56,800,1,12.42,700,1,14.60,700,1,12.37,700,1,14.68,1400,1,ARL,306170869
1234,2025-07-17T15:47:08.805818249Z,2025-07-17T15:47:08.805818249Z,10,2,1108,C,A,0,14.260000000,100,130,165157,256533442,13.26,100,1,13.88,15,1,13.04,2,1,13.89,100,1,13.03,100,1,13.92,15,1,12.73,100,1,14.07,2,1,12.71,100,1,14.28,100,1,12.50,700,1,14.40,100,1,12.46,200,1,14.56,800,1,12.43,700,1,14.60,700,1,12.42,700,1,14.68,1400,1,12.37,700,1,14.78,100,1,ARL,305185529
1235,2025-07-17T15:47:08.805868059Z,2025-07-17T15:47:08.805868059Z,10,2,1108,A,A,0,14.170000000,100,130,165714,256533443,13.26,100,1,13.88,15,1,13.04,2,1,13.89,100,1,13.03,100,1,13.92,15,1,12.73,100,1,14.07,2,1,12.71,100,1,14.17,100,1,12.50,700,1,14.28,100,1,12.46,200,1,14.40,100,1,12.43,700,1,14.56,800,1,12.42,700,1,14.60,700,1,12.37,700,1,14.68,1400,1,ARL,306171457
1236,2025-07-17T15:47:13.121288953Z,2025-07-17T15:47:13.121288953Z,10,2,1108,C,A,0,13.880000000,15,130,165402,256612694,13.26,100,1,13.89,100,1,13.04,2,1,13.92,15,1,13.03,100,1,14.07,2,1,12.73,100,1,14.17,100,1,12.71,100,1,14.28,100,1,12.50,700,1,14.40,100,1,12.46,200,1,14.56,800,1,12.43,700,1,14.60,700,1,12.42,700,1,14.68,1400,1,12.37,700,1,14.78,100,1,ARL,306121113
1237,2025-07-17T15:47:13.122396816Z,2025-07-17T15:47:13.122396816Z,10,2,1108,C,A,0,13.920000000,15,130,165717,256612757,13.26,100,1,13.89,100,1,13.04,2,1,14.07,2,1,13.03,100,1,14.17,100,1,12.73,100,1,14.28,100,1,12.71,100,1,14.40,100,1,12.50,700,1,14.56,800,1,12.46,200,1,14.60,700,1,12.43,700,1,14.68,1400,1,12.42,700,1,14.78,100,1,12.37,700,1,14.88,200,1,ARL,305862145
1238,2025-07-17T15:47:24.786310694Z,2025-07-17T15:47:24.786310694Z,10,2,1108,A,A,0,13.870000000,15,130,165572,256812416,13.26,100,1,13.87,15,1,13.04,2,1,13.89,100,1,13.03,100,1,14.07,2,1,12.73,100,1,14.17,100,1,12.71,100,1,14.28,100,1,12.50,700,1,14.40,100,1,12.46,200,1,14.56,800,1,12.43,700,1,14.60,700,1,12.42,700,1,14.68,1400,1,12.37,700,1,14.78,100,1,ARL,306519385
1239,2025-07-17T15:47:24.786580061Z,2025-07-17T15:47:24.786580061Z,10,2,1108,C,A,0,13.890000000,100,0,165596,256812420,13.26,100,1,13.87,15,1,13.04,2,1,14.07,2,1,13.03,100,1,14.17,100,1,12.73,100,1,14.28,100,1,12.71,100,1,14.40,100,1,12.50,700,1,14.56,800,1,12.46,200,1,14.60,700,1,12.43,700,1,14.68,1400,1,12.42,700,1,14.78,100,1,12.37,700,1,14.88,200,1,ARL,306170837
1240,2025-07-17T15:47:24.786580061Z,2025-07-17T15:47:24.786580061Z,10,2,1108,A,A,0,13.880000000,100,130,165596,256812420,13.26,100,1,13.87,15,1,13.04,2,1,13.88,100,1,13.03,100,1,14.07,2,1,12.73,100,1,14.17,100,1,12.71,100,1,14.28,100,1,12.50,700,1,14.40,100,1,12.46,200,1,14.56,800,1,12.43,700,1,14.60,700,1,12.42,700,1,14.68,1400,1,12.37,700,1,14.78,100,1,ARL,306519397
1241,2025-07-17T15:47:24.786759805Z,2025-07-17T15:47:24.786759805Z,10,2,1108,C,A,0,14.880000000,100,0,165924,256812422,13.26,100,1,13.87,15,1,13.04,2,1,13.88,100,1,13.03,100,1,14.07,2,1,12.73,100,1,14.17,100,1,12.71,100,1,14.28,100,1,12.50,700,1,14.40,100,1,12.46,200,1,14.56,800,1,12.43,700,1,14.60,700,1,12.42,700,1,14.68,1400,1,12.37,700,1,14.78,100,1,ARL,305184937
1242,2025-07-17T15:47:24.786759805Z,2025-07-17T15:47:24.786759805Z,10,2,1108,A,A,0,14.770000000,100,130,165924,256812422,13.26,100,1,13.87,15,1,13.04,2,1,13.88,100,1,13.03,100,1,14.07,2,1,12.73,100,1,14.17,100,1,12.71,100,1,14.28,100,1,12.50,700,1,14.40,100,1,12.46,200,1,14.56,800,1,12.43,700,1,14.60,700,1,12.42,700,1,14.68,1400,1,12.37,700,1,14.77,100,1,ARL,306519409
1243,2025-07-17T15:47:24.800449950Z,2025-07-17T15:47:24.800449950Z,10,2,1108,C,A,0,14.880000000,100,0,166054,256812578,13.26,100,1,13.87,15,1,13.04,2,1,13.88,100,1,13.03,100,1,14.07,2,1,12.73,100,1,14.17,100,1,12.71,100,1,14.28,100,1,12.50,700,1,14.40,100,1,12.46,200,1,14.56,800,1,12.43,700,1,14.60,700,1,12.42,700,1,14.68,1400,1,12.37,700,1,14.77,100,1,ARL,305184953
1244,2025-07-17T15:47:24.800449950Z,2025-07-17T15:47:24.800449950Z,10,2,1108,A,A,0,14.750000000,100,130,166054,256812578,13.26,100,1,13.87,15,1,13.04,2,1,13.88,100,1,13.03,100,1,14.07,2,1,12.73,100,1,14.17,100,1,12.71,100,1,14.28,100,1,12.50,700,1,14.40,100,1,12.46,200,1,14.56,800,1,12.43,700,1,14.60,700,1,12.42,700,1,14.68,1400,1,12.37,700,1,14.75,100,1,ARL,306519741
1245,2025-07-17T15:47:27.860107552Z,2025-07-17T15:47:27.860107552Z,10,2,1108,A,A,0,13.830000000,15,130,165340,256866835,13.26,100,1,13.83,15,1,13.04,2,1,13.87,15,1,13.03,100,1,13.88,100,1,12.73,100,1,14.07,2,1,12.71,100,1,14.17,100,1,12.50,700,1,14.28,100,1,12.46,200,1,14.40,100,1,12.43,700,1,14.56,800,1,12.42,700,1,14.60,700,1,12.37,700,1,14.68,1400,1,ARL,306587393
1246,2025-07-17T15:47:31.406863918Z,2025-07-17T15:47:31.406863918Z,10,2,1108,C,A,0,13.880000000,100,0,165394,256910124,13.26,100,1,13.83,15,1,13.04,2,1,13.87,15,1,13.03,100,1,14.07,2,1,12.73,100,1,14.17,100,1,12.71,100,1,14.28,100,1,12.50,700,1,14.40,100,1,12.46,200,1,14.56,800,1,12.43,700,1,14.60,700,1,12.42,700,1,14.68,1400,1,12.37,700,1,14.75,100,1,ARL,306519397
1247,2025-07-17T15:47:31.406863918Z,2025-07-17T15:47:31.406863918Z,10,2,1108,A,A,0,13.840000000,100,130,165394,256910124,13.26,100,1,13.83,15,1,13.04,2,1,13.84,100,1,13.03,100,1,13.87,15,1,12.73,100,1,14.07,2,1,12.71,100,1,14.17,100,1,12.50,700,1,14.28,100,1,12.46,200,1,14.40,100,1,12.43,700,1,14.56,800,1,12.42,700,1,14.60,700,1,12.37,700,1,14.68,1400,1,ARL,306647425
1248,2025-07-17T15:47:31.407605685Z,2025-07-17T15:47:31.407605685Z,10,2,1108,C,A,0,14.970000000,100,0,165425,256910129,13.26,100,1,13.83,15,1,13.04,2,1,13.84,100,1,13.03,100,1,13.87,15,1,12.73,100,1,14.07,2,1,12.71,100,1,14.17,100,1,12.50,700,1,14.28,100,1,12.46,200,1,14.40,100,1,12.43,700,1,14.56,800,1,12.42,700,1,14.60,700,1,12.37,700,1,14.68,1400,1,ARL,306170869
1249,2025-07-17T15:47:31.407605685Z,2025-07-17T15:47:31.407605685Z,10,2,1108,A,A,0,14.910000000,100,130,165425,256910129,13.26,100,1,13.83,15,1,13.04,2,1,13.84,100,1,13.03,100,1,13.87,15,1,12.73,100,1,14.07,2,1,12.71,100,1,14.17,100,1,12.50,700,1,14.28,100,1,12.46,200,1,14.40,100,1,12.43,700,1,14.56,800,1,12.42,700,1,14.60,700,1,12.37,700,1,14.68,1400,1,ARL,306647445
1250,2025-07-17T15:47:31.413325908Z,2025-07-17T15:47:31.413325908Z,10,2,1108,C,A,0,14.780000000,100,0,165569,256910184,13.26,100,1,13.83,15,1,13.04,2,1,13.84,100,1,13.03,100,1,13.87,15,1,12.73,100,1,14.07,2,1,12.71,100,1,14.17,100,1,12.50,700,1,14.28,100,1,12.46,200,1,14.40,100,1,12.43,700,1,14.56,800,1,12.42,700,1,14.60,700,1,12.37,700,1,14.68,1400,1,ARL,303331425
1251,2025-07-17T15:47:31.413325908Z,2025-07-17T15:47:31.413325908Z,10,2,1108,A,A,0,14.640000000,100,130,165569,256910184,13.26,100,1,13.83,15,1,13.04,2,1,13.84,100,1,13.03,100,1,13.87,15,1,12.73,100,1,14.07,2,1,12.71,100,1,14.17,100,1,12.50,700,1,14.28,100,1,12.46,200,1,14.40,100,1,12.43,700,1,14.56,800,1,12.42,700,1,14.60,700,1,12.37,700,1,14.64,100,1,ARL,306647521
1252,2025-07-17T15:47:31.433320466Z,2025-07-17T15:47:31.433320466Z,10,2,1108,C,A,0,14.960000000,100,0,165817,256910721,13.26,100,1,13.83,15,1,13.04,2,1,13.84,100,1,13.03,100,1,13.87,15,1,12.73,100,1,14.07,2,1,12.71,100,1,14.17,100,1,12.50,700,1,14.28,100,1,12.46,200,1,14.40,100,1,12.43,700,1,14.56,800,1,12.42,700,1,14.60,700,1,12.37,700,1,14.64,100,1,ARL,303330509
1253,2025-07-17T15:47:31.433320466Z,2025-07-17T15:47:31.433320466Z,10,2,1108,A,A,0,14.810000000,100,130,165817,256910721,13.26,100,1,13.83,15,1,13.04,2,1,13.84,100,1,13.03,100,1,13.87,15,1,12.73,100,1,14.07,2,1,12.71,100,1,14.17,100,1,12.50,700,1,14.28,100,1,12.46,200,1,14.40,100,1,12.43,700,1,14.56,800,1,12.42,700,1,14.60,700,1,12.37,700,1,14.64,100,1,ARL,306649913
1254,2025-07-17T15:47:31.573963059Z,2025-07-17T15:47:31.573963059Z,10,2,1108,C,A,0,16.080000000,100,0,165445,256912087,13.26,100,1,13.83,15,1,13.04,2,1,13.84,100,1,13.03,100,1,13.87,15,1,12.73,100,1,14.07,2,1,12.71,100,1,14.17,100,1,12.50,700,1,14.28,100,1,12.46,200,1,14.40,100,1,12.43,700,1,14.56,800,1,12.42,700,1,14.60,700,1,12.37,700,1,14.64,100,1,ARL,303331429
1255,2025-07-17T15:47:31.573963059Z,2025-07-17T15:47:31.573963059Z,10,2,1108,A,A,0,15.920000000,100,130,165445,256912087,13.26,100,1,13.83,15,1,13.04,2,1,13.84,100,1,13.03,100,1,13.87,15,1,12.73,100,1,14.07,2,1,12.71,100,1,14.17,100,1,12.50,700,1,14.28,100,1,12.46,200,1,14.40,100,1,12.43,700,1,14.56,800,1,12.42,700,1,14.60,700,1,12.37,700,1,14.64,100,1,ARL,306652001
1256,2025-07-17T15:47:31.575209032Z,2025-07-17T15:47:31.575209032Z,10,2,1108,C,A,0,17.760000000,100,0,165449,256912094,13.26,100,1,13.83,15,1,13.04,2,1,13.84,100,1,13.03,100,1,13.87,15,1,12.73,100,1,14.07,2,1,12.71,100,1,14.17,100,1,12.50,700,1,14.28,100,1,12.46,200,1,14.40,100,1,12.43,700,1,14.56,800,1,12.42,700,1,14.60,700,1,12.37,700,1,14.64,100,1,ARL,303331309
1257,2025-07-17T15:47:31.575209032Z,2025-07-17T15:47:31.575209032Z,10,2,1108,A,A,0,17.580000000,100,130,165449,256912094,13.26,100,1,13.83,15,1,13.04,2,1,13.84,100,1,13.03,100,1,13.87,15,1,12.73,100,1,14.07,2,1,12.71,100,1,14.17,100,1,12.50,700,1,14.28,100,1,12.46,200,1,14.40,100,1,12.43,700,1,14.56,800,1,12.42,700,1,14.60,700,1,12.37,700,1,14.64,100,1,ARL,306652017
1258,2025-07-17T15:47:31.739930142Z,2025-07-17T15:47:31.739930142Z,10,2,1108,C,A,0,14.960000000,100,0,165572,256914067,13.26,100,1,13.83,15,1,13.04,2,1,13.84,100,1,13.03,100,1,13.87,15,1,12.73,100,1,14.07,2,1,12.71,100,1,14.17,100,1,12.50,700,1,14.28,100,1,12.46,200,1,14.40,100,1,12.43,700,1,14.56,800,1,12.42,700,1,14.60,700,1,12.37,700,1,14.64,100,1,ARL,303334253
1259,2025-07-17T15:47:31.739930142Z,2025-07-17T15:47:31.739930142Z,10,2,1108,A,A,0,14.810000000,100,130,165572,256914067,13.26,100,1,13.83,15,1,13.04,2,1,13.84,100,1,13.03,100,1,13.87,15,1,12.73,100,1,14.07,2,1,12.71,100,1,14.17,100,1,12.50,700,1,14.28,100,1,12.46,200,1,14.40,100,1,12.43,700,1,14.56,800,1,12.42,700,1,14.60,700,1,12.37,700,1,14.64,100,1,ARL,306653713
1260,2025-07-17T15:47:37.159424166Z,2025-07-17T15:47:37.159424166Z,10,2,1108,C,A,0,13.870000000,15,130,165638,256983942,13.26,100,1,13.83,15,1,13.04,2,1,13.84,100,1,13.03,100,1,14.07,2,1,12.73,100,1,14.17,100,1,12.71,100,1,14.28,100,1,12.50,700,1,14.40,100,1,12.46,200,1,14.56,800,1,12.43,700,1,14.60,700,1,12.42,700,1,14.64,100,1,12.37,700,1,14.68,1400,1,ARL,306519385
1261,2025-07-17T15:47:37.171834941Z,2025-07-17T15:47:37.171834941Z,10,2,1108,A,A,0,13.850000000,100,130,165499,256984053,13.26,100,1,13.83,15,1,13.04,2,1,13.84,100,1,13.03,100,1,13.85,100,1,12.73,100,1,14.07,2,1,12.71,100,1,14.17,100,1,12.50,700,1,14.28,100,1,12.46,200,1,14.40,100,1,12.43,700,1,14.56,800,1,12.42,700,1,14.60,700,1,12.37,700,1,14.64,100,1,ARL,306749753
1262,2025-07-17T15:47:38.161015969Z,2025-07-17T15:47:38.161015969Z,10,2,1108,A,A,0,13.790000000,15,130,165314,256998606,13.26,100,1,13.79,15,1,13.04,2,1,13.83,15,1,13.03,100,1,13.84,100,1,12.73,100,1,13.85,100,1,12.71,100,1,14.07,2,1,12.50,700,1,14.17,100,1,12.46,200,1,14.28,100,1,12.43,700,1,14.40,100,1,12.42,700,1,14.56,800,1,12.37,700,1,14.60,700,1,ARL,306770041
1263,2025-07-17T15:47:38.794795887Z,2025-07-17T15:47:38.794795887Z,10,2,1108,C,A,0,13.840000000,100,0,166358,257010989,13.26,100,1,13.79,15,1,13.04,2,1,13.83,15,1,13.03,100,1,13.85,100,1,12.73,100,1,14.07,2,1,12.71,100,1,14.17,100,1,12.50,700,1,14.28,100,1,12.46,200,1,14.40,100,1,12.43,700,1,14.56,800,1,12.42,700,1,14.60,700,1,12.37,700,1,14.64,100,1,ARL,306647425
1264,2025-07-17T15:47:38.794795887Z,2025-07-17T15:47:38.794795887Z,10,2,1108,A,A,0,13.800000000,100,128,166358,257010989,13.26,100,1,13.79,15,1,13.04,2,1,13.80,100,1,13.03,100,1,13.83,15,1,12.73,100,1,13.85,100,1,12.71,100,1,14.07,2,1,12.50,700,1,14.17,100,1,12.46,200,1,14.28,100,1,12.43,700,1,14.40,100,1,12.42,700,1,14.56,800,1,12.37,700,1,14.60,700,1,ARL,306784133
1265,2025-07-17T15:47:38.795557785Z,2025-07-17T15:47:38.795557785Z,10,2,1108,C,A,0,14.910000000,100,0,165785,257011058,13.26,100,1,13.79,15,1,13.04,2,1,13.80,100,1,13.03,100,1,13.83,15,1,12.73,100,1,13.85,100,1,12.71,100,1,14.07,2,1,12.50,700,1,14.17,100,1,12.46,200,1,14.28,100,1,12.43,700,1,14.40,100,1,12.42,700,1,14.56,800,1,12.37,700,1,14.60,700,1,ARL,306647445
1266,2025-07-17T15:47:38.795557785Z,2025-07-17T15:47:38.795557785Z,10,2,1108,A,A,0,14.870000000,100,130,165785,257011058,13.26,100,1,13.79,15,1,13.04,2,1,13.80,100,1,13.03,100,1,13.83,15,1,12.73,100,1,13.85,100,1,12.71,100,1,14.07,2,1,12.50,700,1,14.17,100,1,12.46,200,1,14.28,100,1,12.43,700,1,14.40,100,1,12.42,700,1,14.56,800,1,12.37,700,1,14.60,700,1,ARL,306784201
1267,2025-07-17T15:47:38.804458744Z,2025-07-17T15:47:38.804458744Z,10,2,1108,C,A,0,14.170000000,100,130,165514,257011716,13.26,100,1,13.79,15,1,13.04,2,1,13.80,100,1,13.03,100,1,13.83,15,1,12.73,100,1,13.85,100,1,12.71,100,1,14.07,2,1,12.50,700,1,14.28,100,1,12.46,200,1,14.40,100,1,12.43,700,1,14.56,800,1,12.42,700,1,14.60,700,1,12.37,700,1,14.64,100,1,ARL,306171457
1268,2025-07-17T15:47:38.804513793Z,2025-07-17T15:47:38.804513793Z,10,2,1108,A,A,0,14.080000000,100,130,165799,257011717,13.26,100,1,13.79,15,1,13.04,2,1,13.80,100,1,13.03,100,1,13.83,15,1,12.73,100,1,13.85,100,1,12.71,100,1,14.07,2,1,12.50,700,1,14.08,100,1,12.46,200,1,14.28,100,1,12.43,700,1,14.40,100,1,12.42,700,1,14.56,800,1,12.37,700,1,14.60,700,1,ARL,306784853
1269,2025-07-17T15:47:39.092305947Z,2025-07-17T15:47:39.092305947Z,10,2,1108,C,A,0,13.790000000,15,130,166112,257018687,13.26,100,1,13.80,100,1,13.04,2,1,13.83,15,1,13.03,100,1,13.85,100,1,12.73,100,1,14.07,2,1,12.71,100,1,14.08,100,1,12.50,700,1,14.28,100,1,12.46,200,1,14.40,100,1,12.43,700,1,14.56,800,1,12.42,700,1,14.60,700,1,12.37,700,1,14.64,100,1,ARL,306770041
1270,2025-07-17T15:47:39.095755335Z,2025-07-17T15:47:39.095755335Z,10,2,1108,C,A,0,13.830000000,15,130,165524,257018796,13.26,100,1,13.80,100,1,13.04,2,1,13.85,100,1,13.03,100,1,14.07,2,1,12.73,100,1,14.08,100,1,12.71,100,1,14.28,100,1,12.50,700,1,14.40,100,1,12.46,200,1,14.56,800,1,12.43,700,1,14.60,700,1,12.42,700,1,14.64,100,1,12.37,700,1,14.68,1400,1,ARL,306587393
1271,2025-07-17T15:48:08.909201576Z,2025-07-17T15:48:08.909201576Z,10,2,1108,A,A,0,13.830000000,100,130,165329,257603755,13.26,100,1,13.80,100,1,13.04,2,1,13.83,100,1,13.03,100,1,13.85,100,1,12.73,100,1,14.07,2,1,12.71,100,1,14.08,100,1,12.50,700,1,14.28,100,1,12.46,200,1,14.40,100,1,12.43,700,1,14.56,800,1,12.42,700,1,14.60,700,1,12.37,700,1,14.64,100,1,ARL,307567929
1272,2025-07-17T15:48:08.916555821Z,2025-07-17T15:48:08.916555821Z,10,2,1108,C,A,0,13.850000000,100,130,165277,257604057,13.26,100,1,13.80,100,1,13.04,2,1,13.83,100,1,13.03,100,1,14.07,2,1,12.73,100,1,14.08,100,1,12.71,100,1,14.28,100,1,12.50,700,1,14.40,100,1,12.46,200,1,14.56,800,1,12.43,700,1,14.60,700,1,12.42,700,1,14.64,100,1,12.37,700,1,14.68,1400,1,ARL,306749753
1273,2025-07-17T15:48:09.653308042Z,2025-07-17T15:48:09.653308042Z,10,2,1108,A,A,0,13.780000000,15,130,165423,257621095,13.26,100,1,13.78,15,1,13.04,2,1,13.80,100,1,13.03,100,1,13.83,100,1,12.73,100,1,14.07,2,1,12.71,100,1,14.08,100,1,12.50,700,1,14.28,100,1,12.46,200,1,14.40,100,1,12.43,700,1,14.56,800,1,12.42,700,1,14.60,700,1,12.37,700,1,14.64,100,1,ARL,307587873
1274,2025-07-17T15:48:11.166517494Z,2025-07-17T15:48:11.166517494Z,10,2,1108,C,A,0,13.780000000,15,128,171760,257644020,13.26,100,1,13.80,100,1,13.04,2,1,13.83,100,1,13.03,100,1,14.07,2,1,12.73,100,1,14.08,100,1,12.71,100,1,14.28,100,1,12.50,700,1,14.40,100,1,12.46,200,1,14.56,800,1,12.43,700,1,14.60,700,1,12.42,700,1,14.64,100,1,12.37,700,1,14.68,1400,1,ARL,307587873
1275,2025-07-17T15:48:13.508913083Z,2025-07-17T15:48:13.508913083Z,10,2,1108,A,A,0,13.780000000,15,130,165470,257727039,13.26,100,1,13.78,15,1,13.04,2,1,13.80,100,1,13.03,100,1,13.83,100,1,12.73,100,1,14.07,2,1,12.71,100,1,14.08,100,1,12.50,700,1,14.28,100,1,12.46,200,1,14.40,100,1,12.43,700,1,14.56,800,1,12.42,700,1,14.60,700,1,12.37,700,1,14.64,100,1,ARL,307714769
1276,2025-07-17T15:48:13.525788139Z,2025-07-17T15:48:13.525788139Z,10,2,1108,A,A,0,13.810000000,100,130,165406,257727301,13.26,100,1,13.78,15,1,13.04,2,1,13.80,100,1,13.03,100,1,13.81,100,1,12.73,100,1,13.83,100,1,12.71,100,1,14.07,2,1,12.50,700,1,14.08,100,1,12.46,200,1,14.28,100,1,12.43,700,1,14.40,100,1,12.42,700,1,14.56,800,1,12.37,700,1,14.60,700,1,ARL,307715101
1277,2025-07-17T15:48:13.532443045Z,2025-07-17T15:48:13.532443045Z,10,2,1108,C,A,0,13.830000000,100,130,165829,257727457,13.26,100,1,13.78,15,1,13.04,2,1,13.80,100,1,13.03,100,1,13.81,100,1,12.73,100,1,14.07,2,1,12.71,100,1,14.08,100,1,12.50,700,1,14.28,100,1,12.46,200,1,14.40,100,1,12.43,700,1,14.56,800,1,12.42,700,1,14.60,700,1,12.37,700,1,14.64,100,1,ARL,307567929
1278,2025-07-17T15:48:15.568378275Z,2025-07-17T15:48:15.568378275Z,10,2,1108,C,A,0,13.800000000,100,0,165879,257757458,13.26,100,1,13.78,15,1,13.04,2,1,13.81,100,1,13.03,100,1,14.07,2,1,12.73,100,1,14.08,100,1,12.71,100,1,14.28,100,1,12.50,700,1,14.40,100,1,12.46,200,1,14.56,800,1,12.43,700,1,14.60,700,1,12.42,700,1,14.64,100,1,12.37,700,1,14.68,1400,1,ARL,306784133
1279,2025-07-17T15:48:15.568378275Z,2025-07-17T15:48:15.568378275Z,10,2,1108,A,A,0,13.790000000,100,130,165879,257757458,13.26,100,1,13.78,15,1,13.04,2,1,13.79,100,1,13.03,100,1,13.81,100,1,12.73,100,1,14.07,2,1,12.71,100,1,14.08,100,1,12.50,700,1,14.28,100,1,12.46,200,1,14.40,100,1,12.43,700,1,14.56,800,1,12.42,700,1,14.60,700,1,12.37,700,1,14.64,100,1,ARL,307753241
1280,2025-07-17T15:48:24.009190157Z,2025-07-17T15:48:24.009190157Z,10,2,1108,A,A,0,13.750000000,15,130,165189,257928318,13.26,100,1,13.75,15,1,13.04,2,1,13.78,15,1,13.03,100,1,13.79,100,1,12.73,100,1,13.81,100,1,12.71,100,1,14.07,2,1,12.50,700,1,14.08,100,1,12.46,200,1,14.28,100,1,12.43,700,1,14.40,100,1,12.42,700,1,14.56,800,1,12.37,700,1,14.60,700,1,ARL,307964605
1281,2025-07-17T15:48:24.009357442Z,2025-07-17T15:48:24.009357442Z,10,2,1108,A,A,0,13.790000000,100,130,165191,257928319,13.26,100,1,13.75,15,1,13.04,2,1,13.78,15,1,13.03,100,1,13.79,200,1,12.73,100,1,13.81,100,1,12.71,100,1,14.07,2,1,12.50,700,1,14.08,100,1,12.46,200,1,14.28,100,1,12.43,700,1,14.40,100,1,12.42,700,1,14.56,800,1,12.37,700,1,14.60,700,1,ARL,307964609
1282,2025-07-17T15:48:24.009778967Z,2025-07-17T15:48:24.009778967Z,10,2,1108,C,A,0,13.790000000,100,0,165414,257928325,13.26,100,1,13.75,15,1,13.04,2,1,13.78,15,1,13.03,100,1,13.79,100,1,12.73,100,1,13.81,100,1,12.71,100,1,14.07,2,1,12.50,700,1,14.08,100,1,12.46,200,1,14.28,100,1,12.43,700,1,14.40,100,1,12.42,700,1,14.56,800,1,12.37,700,1,14.60,700,1,ARL,307753241
1283,2025-07-17T15:48:24.009778967Z,2025-07-17T15:48:24.009778967Z,10,2,1108,A,A,0,13.760000000,100,130,165414,257928325,13.26,100,1,13.75,15,1,13.04,2,1,13.76,100,1,13.03,100,1,13.78,15,1,12.73,100,1,13.79,100,1,12.71,100,1,13.81,100,1,12.50,700,1,14.07,2,1,12.46,200,1,14.08,100,1,12.43,700,1,14.28,100,1,12.42,700,1,14.40,100,1,12.37,700,1,14.56,800,1,ARL,307964621
1284,2025-07-17T15:48:24.009808793Z,2025-07-17T15:48:24.009808793Z,10,2,1108,C,A,0,13.810000000,100,130,165373,257928326,13.26,100,1,13.75,15,1,13.04,2,1,13.76,100,1,13.03,100,1,13.78,15,1,12.73,100,1,13.79,100,1,12.71,100,1,14.07,2,1,12.50,700,1,14.08,100,1,12.46,200,1,14.28,100,1,12.43,700,1,14.40,100,1,12.42,700,1,14.56,800,1,12.37,700,1,14.60,700,1,ARL,307715101
1285,2025-07-17T15:48:24.010390029Z,2025-07-17T15:48:24.010390029Z,10,2,1108,C,A,0,14.770000000,100,0,165387,257928333,13.26,100,1,13.75,15,1,13.04,2,1,13.76,100,1,13.03,100,1,13.78,15,1,12.73,100,1,13.79,100,1,12.71,100,1,14.07,2,1,12.50,700,1,14.08,100,1,12.46,200,1,14.28,100,1,12.43,700,1,14.40,100,1,12.42,700,1,14.56,800,1,12.37,700,1,14.60,700,1,ARL,306519409
1286,2025-07-17T15:48:24.010390029Z,2025-07-17T15:48:24.010390029Z,10,2,1108,A,A,0,14.650000000,100,130,165387,257928333,13.26,100,1,13.75,15,1,13.04,2,1,13.76,100,1,13.03,100,1,13.78,15,1,12.73,100,1,13.79,100,1,12.71,100,1,14.07,2,1,12.50,700,1,14.08,100,1,12.46,200,1,14.28,100,1,12.43,700,1,14.40,100,1,12.42,700,1,14.56,800,1,12.37,700,1,14.60,700,1,ARL,307964661
1287,2025-07-17T15:48:24.010512050Z,2025-07-17T15:48:24.010512050Z,10,2,1108,C,A,0,14.870000000,100,0,165472,257928340,13.26,100,1,13.75,15,1,13.04,2,1,13.76,100,1,13.03,100,1,13.78,15,1,12.73,100,1,13.79,100,1,12.71,100,1,14.07,2,1,12.50,700,1,14.08,100,1,12.46,200,1,14.28,100,1,12.43,700,1,14.40,100,1,12.42,700,1,14.56,800,1,12.37,700,1,14.60,700,1,ARL,306784201
1288,2025-07-17T15:48:24.010512050Z,2025-07-17T15:48:24.010512050Z,10,2,1108,A,A,0,14.830000000,100,130,165472,257928340,13.26,100,1,13.75,15,1,13.04,2,1,13.76,100,1,13.03,100,1,13.78,15,1,12.73,100,1,13.79,100,1,12.71,100,1,14.07,2,1,12.50,700,1,14.08,100,1,12.46,200,1,14.28,100,1,12.43,700,1,14.40,100,1,12.42,700,1,14.56,800,1,12.37,700,1,14.60,700,1,ARL,307964665
1289,2025-07-17T15:48:42.009788565Z,2025-07-17T15:48:42.009788565Z,10,2,1108,C,A,0,13.780000000,15,130,165481,258199397,13.26,100,1,13.75,15,1,13.04,2,1,13.76,100,1,13.03,100,1,13.79,100,1,12.73,100,1,14.07,2,1,12.71,100,1,14.08,100,1,12.50,700,1,14.28,100,1,12.46,200,1,14.40,100,1,12.43,700,1,14.56,800,1,12.42,700,1,14.60,700,1,12.37,700,1,14.64,100,1,ARL,307714769
1290,2025-07-17T15:48:42.011680742Z,2025-07-17T15:48:42.011680742Z,10,2,1108,C,A,0,14.750000000,100,0,165650,258199535,13.26,100,1,13.75,15,1,13.04,2,1,13.76,100,1,13.03,100,1,13.79,100,1,12.73,100,1,14.07,2,1,12.71,100,1,14.08,100,1,12.50,700,1,14.28,100,1,12.46,200,1,14.40,100,1,12.43,700,1,14.56,800,1,12.42,700,1,14.60,700,1,12.37,700,1,14.64,100,1,ARL,306519741
1291,2025-07-17T15:48:42.011680742Z,2025-07-17T15:48:42.011680742Z,10,2,1108,A,A,0,14.640000000,100,130,165650,258199535,13.26,100,1,13.75,15,1,13.04,2,1,13.76,100,1,13.03,100,1,13.79,100,1,12.73,100,1,14.07,2,1,12.71,100,1,14.08,100,1,12.50,700,1,14.28,100,1,12.46,200,1,14.40,100,1,12.43,700,1,14.56,800,1,12.42,700,1,14.60,700,1,12.37,700,1,14.64,200,1,ARL,308296381
1292,2025-07-17T15:48:42.016595806Z,2025-07-17T15:48:42.016595806Z,10,2,1108,A,A,0,13.770000000,100,130,165568,258199787,13.26,100,1,13.75,15,1,13.04,2,1,13.76,100,1,13.03,100,1,13.77,100,1,12.73,100,1,13.79,100,1,12.71,100,1,14.07,2,1,12.50,700,1,14.08,100,1,12.46,200,1,14.28,100,1,12.43,700,1,14.40,100,1,12.42,700,1,14.56,800,1,12.37,700,1,14.60,700,1,ARL,308296741
1293,2025-07-17T15:48:42.023266760Z,2025-07-17T15:48:42.023266760Z,10,2,1108,C,A,0,13.790000000,100,130,165647,258199990,13.26,100,1,13.75,15,1,13.04,2,1,13.76,100,1,13.03,100,1,13.77,100,1,12.73,100,1,14.07,2,1,12.71,100,1,14.08,100,1,12.50,700,1,14.28,100,1,12.46,200,1,14.40,100,1,12.43,700,1,14.56,800,1,12.42,700,1,14.60,700,1,12.37,700,1,14.64,200,1,ARL,307964609
1294,2025-07-17T15:48:46.749922127Z,2025-07-17T15:48:46.749922127Z,10,2,1108,A,A,0,13.730000000,15,128,166363,258260871,13.26,100,1,13.73,15,1,13.04,2,1,13.75,15,1,13.03,100,1,13.76,100,1,12.73,100,1,13.77,100,1,12.71,100,1,14.07,2,1,12.50,700,1,14.08,100,1,12.46,200,1,14.28,100,1,12.43,700,1,14.40,100,1,12.42,700,1,14.56,800,1,12.37,700,1,14.60,700,1,ARL,308374537
1295,2025-07-17T15:48:46.758385367Z,2025-07-17T15:48:46.758385367Z,10,2,1108,C,A,0,13.760000000,100,0,165666,258261154,13.26,100,1,13.73,15,1,13.04,2,1,13.75,15,1,13.03,100,1,13.77,100,1,12.73,100,1,14.07,2,1,12.71,100,1,14.08,100,1,12.50,700,1,14.28,100,1,12.46,200,1,14.40,100,1,12.43,700,1,14.56,800,1,12.42,700,1,14.60,700,1,12.37,700,1,14.64,200,1,ARL,307964621
1296,2025-07-17T15:48:46.758385367Z,2025-07-17T15:48:46.758385367Z,10,2,1108,A,A,0,13.740000000,100,130,165666,258261154,13.26,100,1,13.73,15,1,13.04,2,1,13.74,100,1,13.03,100,1,13.75,15,1,12.73,100,1,13.77,100,1,12.71,100,1,14.07,2,1,12.50,700,1,14.08,100,1,12.46,200,1,14.28,100,1,12.43,700,1,14.40,100,1,12.42,700,1,14.56,800,1,12.37,700,1,14.60,700,1,ARL,308374881
1297,2025-07-17T15:48:46.773503306Z,2025-07-17T15:48:46.773503306Z,10,2,1108,C,A,0,14.080000000,100,130,165682,258261538,13.26,100,1,13.73,15,1,13.04,2,1,13.74,100,1,13.03,100,1,13.75,15,1,12.73,100,1,13.77,100,1,12.71,100,1,14.07,2,1,12.50,700,1,14.28,100,1,12.46,200,1,14.40,100,1,12.43,700,1,14.56,800,1,12.42,700,1,14.60,700,1,12.37,700,1,14.64,200,1,ARL,306784853
1298,2025-07-17T15:48:46.773555566Z,2025-07-17T15:48:46.773555566Z,10,2,1108,A,A,0,14.010000000,100,130,165160,258261539,13.26,100,1,13.73,15,1,13.04,2,1,13.74,100,1,13.03,100,1,13.75,15,1,12.73,100,1,13.77,100,1,12.71,100,1,14.01,100,1,12.50,700,1,14.07,2,1,12.46,200,1,14.28,100,1,12.43,700,1,14.40,100,1,12.42,700,1,14.56,800,1,12.37,700,1,14.60,700,1,ARL,308375185
1299,2025-07-17T15:49:02.010329052Z,2025-07-17T15:49:02.010329052Z,10,2,1108,A,A,0,13.750000000,100,130,165428,258502869,13.26,100,1,13.73,15,1,13.04,2,1,13.74,100,1,13.03,100,1,13.75,115,1,12.73,100,1,13.77,100,1,12.71,100,1,14.01,100,1,12.50,700,1,14.07,2,1,12.46,200,1,14.28,100,1,12.43,700,1,14.40,100,1,12.42,700,1,14.56,800,1,12.37,700,1,14.60,700,1,ARL,308705489
1300,2025-07-17T15:49:02.019824230Z,2025-07-17T15:49:02.019824230Z,10,2,1108,C,A,0,13.770000000,100,130,165337,258502929,13.26,100,1,13.73,15,1,13.04,2,1,13.74,100,1,13.03,100,1,13.75,115,1,12.73,100,1,14.01,100,1,12.71,100,1,14.07,2,1,12.50,700,1,14.28,100,1,12.46,200,1,14.40,100,1,12.43,700,1,14.56,800,1,12.42,700,1,14.60,700,1,12.37,700,1,14.64,200,1,ARL,308296741
1301,2025-07-17T15:49:03.405840358Z,2025-07-17T15:49:03.405840358Z,10,2,1108,C,A,0,13.750000000,15,130,165232,258527308,13.26,100,1,13.73,15,1,13.04,2,1,13.74,100,1,13.03,100,1,13.75,100,1,12.73,100,1,14.01,100,1,12.71,100,1,14.07,2,1,12.50,700,1,14.28,100,1,12.46,200,1,14.40,100,1,12.43,700,1,14.56,800,1,12.42,700,1,14.60,700,1,12.37,700,1,14.64,200,1,ARL,307964605
1302,2025-07-17T15:49:04.713831675Z,2025-07-17T15:49:04.713831675Z,10,2,1108,A,A,0,13.710000000,15,128,166250,258547335,13.26,100,1,13.71,15,1,13.04,2,1,13.73,15,1,13.03,100,1,13.74,100,1,12.73,100,1,13.75,100,1,12.71,100,1,14.01,100,1,12.50,700,1,14.07,2,1,12.46,200,1,14.28,100,1,12.43,700,1,14.40,100,1,12.42,700,1,14.56,800,1,12.37,700,1,14.60,700,1,ARL,308763065
1303,2025-07-17T15:49:06.012946379Z,2025-07-17T15:49:06.012946379Z,10,2,1108,A,A,0,13.730000000,100,130,165562,258567259,13.26,100,1,13.71,15,1,13.04,2,1,13.73,115,1,13.03,100,1,13.74,100,1,12.73,100,1,13.75,100,1,12.71,100,1,14.01,100,1,12.50,700,1,14.07,2,1,12.46,200,1,14.28,100,1,12.43,700,1,14.40,100,1,12.42,700,1,14.56,800,1,12.37,700,1,14.60,700,1,ARL,308786185
1304,2025-07-17T15:49:06.023126600Z,2025-07-17T15:49:06.023126600Z,10,2,1108,C,A,0,13.750000000,100,130,165547,258567405,13.26,100,1,13.71,15,1,13.04,2,1,13.73,115,1,13.03,100,1,13.74,100,1,12.73,100,1,14.01,100,1,12.71,100,1,14.07,2,1,12.50,700,1,14.28,100,1,12.46,200,1,14.40,100,1,12.43,700,1,14.56,800,1,12.42,700,1,14.60,700,1,12.37,700,1,14.64,200,1,ARL,308705489
1305,2025-07-17T15:49:06.344191321Z,2025-07-17T15:49:06.344191321Z,10,2,1108,C,A,0,13.740000000,100,0,165569,258574949,13.26,100,1,13.71,15,1,13.04,2,1,13.73,115,1,13.03,100,1,14.01,100,1,12.73,100,1,14.07,2,1,12.71,100,1,14.28,100,1,12.50,700,1,14.40,100,1,12.46,200,1,14.56,800,1,12.43,700,1,14.60,700,1,12.42,700,1,14.64,200,1,12.37,700,1,14.65,100,1,ARL,308374881
1306,2025-07-17T15:49:06.344191321Z,2025-07-17T15:49:06.344191321Z,10,2,1108,A,A,0,13.720000000,100,130,165569,258574949,13.26,100,1,13.71,15,1,13.04,2,1,13.72,100,1,13.03,100,1,13.73,115,1,12.73,100,1,14.01,100,1,12.71,100,1,14.07,2,1,12.50,700,1,14.28,100,1,12.46,200,1,14.40,100,1,12.43,700,1,14.56,800,1,12.42,700,1,14.60,700,1,12.37,700,1,14.64,200,1,ARL,308797069
1307,2025-07-17T15:49:06.344938975Z,2025-07-17T15:49:06.344938975Z,10,2,1108,C,A,0,14.830000000,100,0,165516,258575013,13.26,100,1,13.71,15,1,13.04,2,1,13.72,100,1,13.03,100,1,13.73,115,1,12.73,100,1,14.01,100,1,12.71,100,1,14.07,2,1,12.50,700,1,14.28,100,1,12.46,200,1,14.40,100,1,12.43,700,1,14.56,800,1,12.42,700,1,14.60,700,1,12.37,700,1,14.64,200,1,ARL,307964665
1308,2025-07-17T15:49:06.344938975Z,2025-07-17T15:49:06.344938975Z,10,2,1108,A,A,0,14.780000000,100,130,165516,258575013,13.26,100,1,13.71,15,1,13.04,2,1,13.72,100,1,13.03,100,1,13.73,115,1,12.73,100,1,14.01,100,1,12.71,100,1,14.07,2,1,12.50,700,1,14.28,100,1,12.46,200,1,14.40,100,1,12.43,700,1,14.56,800,1,12.42,700,1,14.60,700,1,12.37,700,1,14.64,200,1,ARL,308797245
1309,2025-07-17T15:49:06.362779870Z,2025-07-17T15:49:06.362779870Z,10,2,1108,C,A,0,17.580000000,100,0,165540,258575963,13.26,100,1,13.71,15,1,13.04,2,1,13.72,100,1,13.03,100,1,13.73,115,1,12.73,100,1,14.01,100,1,12.71,100,1,14.07,2,1,12.50,700,1,14.28,100,1,12.46,200,1,14.40,100,1,12.43,700,1,14.56,800,1,12.42,700,1,14.60,700,1,12.37,700,1,14.64,200,1,ARL,306652017
1310,2025-07-17T15:49:06.362779870Z,2025-07-17T15:49:06.362779870Z,10,2,1108,A,A,0,17.430000000,100,130,165540,258575963,13.26,100,1,13.71,15,1,13.04,2,1,13.72,100,1,13.03,100,1,13.73,115,1,12.73,100,1,14.01,100,1,12.71,100,1,14.07,2,1,12.50,700,1,14.28,100,1,12.46,200,1,14.40,100,1,12.43,700,1,14.56,800,1,12.42,700,1,14.60,700,1,12.37,700,1,14.64,200,1,ARL,308799373
1311,2025-07-17T15:49:10.459152457Z,2025-07-17T15:49:10.459152457Z,10,2,1108,C,A,0,13.730000000,15,130,165428,258636400,13.26,100,1,13.71,15,1,13.04,2,1,13.72,100,1,13.03,100,1,13.73,100,1,12.73,100,1,14.01,100,1,12.71,100,1,14.07,2,1,12.50,700,1,14.28,100,1,12.46,200,1,14.40,100,1,12.43,700,1,14.56,800,1,12.42,700,1,14.60,700,1,12.37,700,1,14.64,200,1,ARL,308374537
1312,2025-07-17T15:49:11.460432218Z,2025-07-17T15:49:11.460432218Z,10,2,1108,A,A,0,13.690000000,15,130,165382,258650544,13.26,100,1,13.69,15,1,13.04,2,1,13.71,15,1,13.03,100,1,13.72,100,1,12.73,100,1,13.73,100,1,12.71,100,1,14.01,100,1,12.50,700,1,14.07,2,1,12.46,200,1,14.28,100,1,12.43,700,1,14.40,100,1,12.42,700,1,14.56,800,1,12.37,700,1,14.60,700,1,ARL,308893737
1313,2025-07-17T15:49:11.891477604Z,2025-07-17T15:49:11.891477604Z,10,2,1108,C,A,0,13.720000000,100,0,165495,258658721,13.26,100,1,13.69,15,1,13.04,2,1,13.71,15,1,13.03,100,1,13.73,100,1,12.73,100,1,14.01,100,1,12.71,100,1,14.07,2,1,12.50,700,1,14.28,100,1,12.46,200,1,14.40,100,1,12.43,700,1,14.56,800,1,12.42,700,1,14.60,700,1,12.37,700,1,14.64,200,1,ARL,308797069
1314,2025-07-17T15:49:11.891477604Z,2025-07-17T15:49:11.891477604Z,10,2,1108,A,A,0,13.700000000,100,130,165495,258658721,13.26,100,1,13.69,15,1,13.04,2,1,13.70,100,1,13.03,100,1,13.71,15,1,12.73,100,1,13.73,100,1,12.71,100,1,14.01,100,1,12.50,700,1,14.07,2,1,12.46,200,1,14.28,100,1,12.43,700,1,14.40,100,1,12.42,700,1,14.56,800,1,12.37,700,1,14.60,700,1,ARL,308901793
1315,2025-07-17T15:49:11.893823458Z,2025-07-17T15:49:11.893823458Z,10,2,1108,C,A,0,14.810000000,100,0,165613,258658835,13.26,100,1,13.69,15,1,13.04,2,1,13.70,100,1,13.03,100,1,13.71,15,1,12.73,100,1,13.73,100,1,12.71,100,1,14.01,100,1,12.50,700,1,14.07,2,1,12.46,200,1,14.28,100,1,12.43,700,1,14.40,100,1,12.42,700,1,14.56,800,1,12.37,700,1,14.60,700,1,ARL,306649913
1316,2025-07-17T15:49:11.893823458Z,2025-07-17T15:49:11.893823458Z,10,2,1108,A,A,0,14.660000000,100,130,165613,258658835,13.26,100,1,13.69,15,1,13.04,2,1,13.70,100,1,13.03,100,1,13.71,15,1,12.73,100,1,13.73,100,1,12.71,100,1,14.01,100,1,12.50,700,1,14.07,2,1,12.46,200,1,14.28,100,1,12.43,700,1,14.40,100,1,12.42,700,1,14.56,800,1,12.37,700,1,14.60,700,1,ARL,308901981
1317,2025-07-17T15:49:11.904065674Z,2025-07-17T15:49:11.904065674Z,10,2,1108,C,A,0,15.920000000,100,0,165475,258659039,13.26,100,1,13.69,15,1,13.04,2,1,13.70,100,1,13.03,100,1,13.71,15,1,12.73,100,1,13.73,100,1,12.71,100,1,14.01,100,1,12.50,700,1,14.07,2,1,12.46,200,1,14.28,100,1,12.43,700,1,14.40,100,1,12.42,700,1,14.56,800,1,12.37,700,1,14.60,700,1,ARL,306652001
1318,2025-07-17T15:49:11.904065674Z,2025-07-17T15:49:11.904065674Z,10,2,1108,A,A,0,15.760000000,100,130,165475,258659039,13.26,100,1,13.69,15,1,13.04,2,1,13.70,100,1,13.03,100,1,13.71,15,1,12.73,100,1,13.73,100,1,12.71,100,1,14.01,100,1,12.50,700,1,14.07,2,1,12.46,200,1,14.28,100,1,12.43,700,1,14.40,100,1,12.42,700,1,14.56,800,1,12.37,700,1,14.60,700,1,ARL,308902229
1319,2025-07-17T15:49:11.935356090Z,2025-07-17T15:49:11.935356090Z,10,2,1108,C,A,0,14.810000000,100,0,165597,258659320,13.26,100,1,13.69,15,1,13.04,2,1,13.70,100,1,13.03,100,1,13.71,15,1,12.73,100,1,13.73,100,1,12.71,100,1,14.01,100,1,12.50,700,1,14.07,2,1,12.46,200,1,14.28,100,1,12.43,700,1,14.40,100,1,12.42,700,1,14.56,800,1,12.37,700,1,14.60,700,1,ARL,306653713
1320,2025-07-17T15:49:11.935356090Z,2025-07-17T15:49:11.935356090Z,10,2,1108,A,A,0,14.660000000,100,130,165597,258659320,13.26,100,1,13.69,15,1,13.04,2,1,13.70,100,1,13.03,100,1,13.71,15,1,12.73,100,1,13.73,100,1,12.71,100,1,14.01,100,1,12.50,700,1,14.07,2,1,12.46,200,1,14.28,100,1,12.43,700,1,14.40,100,1,12.42,700,1,14.56,800,1,12.37,700,1,14.60,700,1,ARL,308903001
1321,2025-07-17T15:49:11.948535655Z,2025-07-17T15:49:11.948535655Z,10,2,1108,C,A,0,14.640000000,100,130,165394,258659496,13.26,100,1,13.69,15,1,13.04,2,1,13.70,100,1,13.03,100,1,13.71,15,1,12.73,100,1,13.73,100,1,12.71,100,1,14.01,100,1,12.50,700,1,14.07,2,1,12.46,200,1,14.28,100,1,12.43,700,1,14.40,100,1,12.42,700,1,14.56,800,1,12.37,700,1,14.60,700,1,ARL,306647521
1322,2025-07-17T15:49:11.948663655Z,2025-07-17T15:49:11.948663655Z,10,2,1108,A,A,0,14.500000000,100,130,165457,258659499,13.26,100,1,13.69,15,1,13.04,2,1,13.70,100,1,13.03,100,1,13.71,15,1,12.73,100,1,13.73,100,1,12.71,100,1,14.01,100,1,12.50,700,1,14.07,2,1,12.46,200,1,14.28,100,1,12.43,700,1,14.40,100,1,12.42,700,1,14.50,100,1,12.37,700,1,14.56,800,1,ARL,308903349
1323,2025-07-17T15:49:12.221056085Z,2025-07-17T15:49:12.221056085Z,10,2,1108,A,A,0,13.710000000,100,130,165282,258663292,13.26,100,1,13.69,15,1,13.04,2,1,13.70,100,1,13.03,100,1,13.71,115,1,12.73,100,1,13.73,100,1,12.71,100,1,14.01,100,1,12.50,700,1,14.07,2,1,12.46,200,1,14.28,100,1,12.43,700,1,14.40,100,1,12.42,700,1,14.50,100,1,12.37,700,1,14.56,800,1,ARL,308909249
1324,2025-07-17T15:49:12.227821500Z,2025-07-17T15:49:12.227821500Z,10,2,1108,C,A,0,13.730000000,100,130,165405,258663378,13.26,100,1,13.69,15,1,13.04,2,1,13.70,100,1,13.03,100,1,13.71,115,1,12.73,100,1,14.01,100,1,12.71,100,1,14.07,2,1,12.50,700,1,14.28,100,1,12.46,200,1,14.40,100,1,12.43,700,1,14.50,100,1,12.42,700,1,14.56,800,1,12.37,700,1,14.60,700,1,ARL,308786185
1325,2025-07-17T15:49:14.463063539Z,2025-07-17T15:49:14.463063539Z,10,2,1108,C,A,0,13.710000000,15,130,165582,258702625,13.26,100,1,13.69,15,1,13.04,2,1,13.70,100,1,13.03,100,1,13.71,100,1,12.73,100,1,14.01,100,1,12.71,100,1,14.07,2,1,12.50,700,1,14.28,100,1,12.46,200,1,14.40,100,1,12.43,700,1,14.50,100,1,12.42,700,1,14.56,800,1,12.37,700,1,14.60,700,1,ARL,308763065
1326,2025-07-17T15:49:15.466199239Z,2025-07-17T15:49:15.466199239Z,10,2,1108,A,A,0,13.670000000,15,130,165883,258716863,13.26,100,1,13.67,15,1,13.04,2,1,13.69,15,1,13.03,100,1,13.70,100,1,12.73,100,1,13.71,100,1,12.71,100,1,14.01,100,1,12.50,700,1,14.07,2,1,12.46,200,1,14.28,100,1,12.43,700,1,14.40,100,1,12.42,700,1,14.50,100,1,12.37,700,1,14.56,800,1,ARL,308980305
1327,2025-07-17T15:49:16.350859152Z,2025-07-17T15:49:16.350859152Z,10,2,1108,C,A,0,13.700000000,100,0,165436,258727929,13.26,100,1,13.67,15,1,13.04,2,1,13.69,15,1,13.03,100,1,13.71,100,1,12.73,100,1,14.01,100,1,12.71,100,1,14.07,2,1,12.50,700,1,14.28,100,1,12.46,200,1,14.40,100,1,12.43,700,1,14.50,100,1,12.42,700,1,14.56,800,1,12.37,700,1,14.60,700,1,ARL,308901793
1328,2025-07-17T15:49:16.350859152Z,2025-07-17T15:49:16.350859152Z,10,2,1108,A,A,0,13.680000000,100,130,165436,258727929,13.26,100,1,13.67,15,1,13.04,2,1,13.68,100,1,13.03,100,1,13.69,15,1,12.73,100,1,13.71,100,1,12.71,100,1,14.01,100,1,12.50,700,1,14.07,2,1,12.46,200,1,14.28,100,1,12.43,700,1,14.40,100,1,12.42,700,1,14.50,100,1,12.37,700,1,14.56,800,1,ARL,308998225
1329,2025-07-17T15:49:16.351594042Z,2025-07-17T15:49:16.351594042Z,10,2,1108,C,A,0,14.780000000,100,0,165576,258727956,13.26,100,1,13.67,15,1,13.04,2,1,13.68,100,1,13.03,100,1,13.69,15,1,12.73,100,1,13.71,100,1,12.71,100,1,14.01,100,1,12.50,700,1,14.07,2,1,12.46,200,1,14.28,100,1,12.43,700,1,14.40,100,1,12.42,700,1,14.50,100,1,12.37,700,1,14.56,800,1,ARL,308797245
1330,2025-07-17T15:49:16.351594042Z,2025-07-17T15:49:16.351594042Z,10,2,1108,A,A,0,14.740000000,100,130,165576,258727956,13.26,100,1,13.67,15,1,13.04,2,1,13.68,100,1,13.03,100,1,13.69,15,1,12.73,100,1,13.71,100,1,12.71,100,1,14.01,100,1,12.50,700,1,14.07,2,1,12.46,200,1,14.28,100,1,12.43,700,1,14.40,100,1,12.42,700,1,14.50,100,1,12.37,700,1,14.56,800,1,ARL,308998341
1331,2025-07-17T15:49:16.493946243Z,2025-07-17T15:49:16.493946243Z,10,2,1108,A,A,0,13.690000000,100,130,165247,258729266,13.26,100,1,13.67,15,1,13.04,2,1,13.68,100,1,13.03,100,1,13.69,115,1,12.73,100,1,13.71,100,1,12.71,100,1,14.01,100,1,12.50,700,1,14.07,2,1,12.46,200,1,14.28,100,1,12.43,700,1,14.40,100,1,12.42,700,1,14.50,100,1,12.37,700,1,14.56,800,1,ARL,309001525
1332,2025-07-17T15:49:16.557759633Z,2025-07-17T15:49:16.557759633Z,10,2,1108,C,A,0,13.710000000,100,130,165230,258730034,13.26,100,1,13.67,15,1,13.04,2,1,13.68,100,1,13.03,100,1,13.69,115,1,12.73,100,1,14.01,100,1,12.71,100,1,14.07,2,1,12.50,700,1,14.28,100,1,12.46,200,1,14.40,100,1,12.43,700,1,14.50,100,1,12.42,700,1,14.56,800,1,12.37,700,1,14.60,700,1,ARL,308909249
1333,2025-07-17T15:49:21.185984774Z,2025-07-17T15:49:21.185984774Z,10,2,1108,C,A,0,14.070000000,2,0,165713,258786552,13.26,100,1,13.67,15,1,13.04,2,1,13.68,100,1,13.03,100,1,13.69,115,1,12.73,100,1,14.01,100,1,12.71,100,1,14.28,100,1,12.50,700,1,14.40,100,1,12.46,200,1,14.50,100,1,12.43,700,1,14.56,800,1,12.42,700,1,14.60,700,1,12.37,700,1,14.64,100,1,ARL,296478973
1334,2025-07-17T15:49:21.185984774Z,2025-07-17T15:49:21.185984774Z,10,2,1108,A,A,0,13.980000000,2,130,165713,258786552,13.26,100,1,13.67,15,1,13.04,2,1,13.68,100,1,13.03,100,1,13.69,115,1,12.73,100,1,13.98,2,1,12.71,100,1,14.01,100,1,12.50,700,1,14.28,100,1,12.46,200,1,14.40,100,1,12.43,700,1,14.50,100,1,12.42,700,1,14.56,800,1,12.37,700,1,14.60,700,1,ARL,309091513
1335,2025-07-17T15:49:24.282985894Z,2025-07-17T15:49:24.282985894Z,10,2,1108,C,A,0,13.690000000,15,130,166218,258838460,13.26,100,1,13.67,15,1,13.04,2,1,13.68,100,1,13.03,100,1,13.69,100,1,12.73,100,1,13.98,2,1,12.71,100,1,14.01,100,1,12.50,700,1,14.28,100,1,12.46,200,1,14.40,100,1,12.43,700,1,14.50,100,1,12.42,700,1,14.56,800,1,12.37,700,1,14.60,700,1,ARL,308893737
1336,2025-07-17T15:49:34.570031718Z,2025-07-17T15:49:34.570031718Z,10,2,1108,C,A,0,13.670000000,15,130,165416,258980876,13.26,100,1,13.68,100,1,13.04,2,1,13.69,100,1,13.03,100,1,13.98,2,1,12.73,100,1,14.01,100,1,12.71,100,1,14.28,100,1,12.50,700,1,14.40,100,1,12.46,200,1,14.50,100,1,12.43,700,1,14.56,800,1,12.42,700,1,14.60,700,1,12.37,700,1,14.64,100,1,ARL,308980305
1337,2025-07-17T15:49:34.591347169Z,2025-07-17T15:49:34.591347169Z,10,2,1108,C,A,0,13.690000000,100,130,165746,258983321,13.26,100,1,13.68,100,1,13.04,2,1,13.98,2,1,13.03,100,1,14.01,100,1,12.73,100,1,14.28,100,1,12.71,100,1,14.40,100,1,12.50,700,1,14.50,100,1,12.46,200,1,14.56,800,1,12.43,700,1,14.60,700,1,12.42,700,1,14.64,100,1,12.37,700,1,14.65,100,1,ARL,309001525
1338,2025-07-17T15:49:38.609851985Z,2025-07-17T15:49:38.609851985Z,10,2,1108,A,A,0,13.720000000,100,130,165409,259031220,13.26,100,1,13.68,100,1,13.04,2,1,13.72,100,1,13.03,100,1,13.98,2,1,12.73,100,1,14.01,100,1,12.71,100,1,14.28,100,1,12.50,700,1,14.40,100,1,12.46,200,1,14.50,100,1,12.43,700,1,14.56,800,1,12.42,700,1,14.60,700,1,12.37,700,1,14.64,100,1,ARL,309410565
1339,2025-07-17T15:49:38.609907720Z,2025-07-17T15:49:38.609907720Z,10,2,1108,C,B,0,13.260000000,100,130,165614,259031221,13.04,2,1,13.68,100,1,13.03,100,1,13.72,100,1,12.73,100,1,13.98,2,1,12.71,100,1,14.01,100,1,12.50,700,1,14.28,100,1,12.46,200,1,14.40,100,1,12.43,700,1,14.50,100,1,12.42,700,1,14.56,800,1,12.37,700,1,14.60,700,1,12.36,200,1,14.64,100,1,ARL,291975017
1340,2025-07-17T15:49:39.068349660Z,2025-07-17T15:49:39.068349660Z,10,2,1108,A,B,0,13.020000000,100,130,165345,259035032,13.04,2,1,13.68,100,1,13.03,100,1,13.72,100,1,13.02,100,1,13.98,2,1,12.73,100,1,14.01,100,1,12.71,100,1,14.28,100,1,12.50,700,1,14.40,100,1,12.46,200,1,14.50,100,1,12.43,700,1,14.56,800,1,12.42,700,1,14.60,700,1,12.37,700,1,14.64,100,1,ARL,309415429
1341,2025-07-17T15:49:44.788249210Z,2025-07-17T15:49:44.788249210Z,10,2,1108,A,A,0,13.670000000,15,130,165191,259105347,13.04,2,1,13.67,15,1,13.03,100,1,13.68,100,1,13.02,100,1,13.72,100,1,12.73,100,1,13.98,2,1,12.71,100,1,14.01,100,1,12.50,700,1,14.28,100,1,12.46,200,1,14.40,100,1,12.43,700,1,14.50,100,1,12.42,700,1,14.56,800,1,12.37,700,1,14.60,700,1,ARL,309524921
1342,2025-07-17T15:49:44.788855587Z,2025-07-17T15:49:44.788855587Z,10,2,1108,A,A,0,13.700000000,100,130,165170,259105361,13.04,2,1,13.67,15,1,13.03,100,1,13.68,100,1,13.02,100,1,13.70,100,1,12.73,100,1,13.72,100,1,12.71,100,1,13.98,2,1,12.50,700,1,14.01,100,1,12.46,200,1,14.28,100,1,12.43,700,1,14.40,100,1,12.42,700,1,14.50,100,1,12.37,700,1,14.56,800,1,ARL,309524933
1343,2025-07-17T15:49:44.789537536Z,2025-07-17T15:49:44.789537536Z,10,2,1108,C,A,0,13.720000000,100,130,165380,259105380,13.04,2,1,13.67,15,1,13.03,100,1,13.68,100,1,13.02,100,1,13.70,100,1,12.73,100,1,13.98,2,1,12.71,100,1,14.01,100,1,12.50,700,1,14.28,100,1,12.46,200,1,14.40,100,1,12.43,700,1,14.50,100,1,12.42,700,1,14.56,800,1,12.37,700,1,14.60,700,1,ARL,309410565
1344,2025-07-17T15:49:54.788493605Z,2025-07-17T15:49:54.788493605Z,10,2,1108,A,A,0,13.650000000,15,130,165236,259253294,13.04,2,1,13.65,15,1,13.03,100,1,13.67,15,1,13.02,100,1,13.68,100,1,12.73,100,1,13.70,100,1,12.71,100,1,13.98,2,1,12.50,700,1,14.01,100,1,12.46,200,1,14.28,100,1,12.43,700,1,14.40,100,1,12.42,700,1,14.50,100,1,12.37,700,1,14.56,800,1,ARL,309707269
1345,2025-07-17T15:49:54.799370442Z,2025-07-17T15:49:54.799370442Z,10,2,1108,A,A,0,13.680000000,100,130,165302,259253527,13.04,2,1,13.65,15,1,13.03,100,1,13.67,15,1,13.02,100,1,13.68,200,1,12.73,100,1,13.70,100,1,12.71,100,1,13.98,2,1,12.50,700,1,14.01,100,1,12.46,200,1,14.28,100,1,12.43,700,1,14.40,100,1,12.42,700,1,14.50,100,1,12.37,700,1,14.56,800,1,ARL,309707413
1346,2025-07-17T15:49:54.820469390Z,2025-07-17T15:49:54.820469390Z,10,2,1108,C,A,0,13.700000000,100,130,165527,259253732,13.04,2,1,13.65,15,1,13.03,100,1,13.67,15,1,13.02,100,1,13.68,200,1,12.73,100,1,13.98,2,1,12.71,100,1,14.01,100,1,12.50,700,1,14.28,100,1,12.46,200,1,14.40,100,1,12.43,700,1,14.50,100,1,12.42,700,1,14.56,800,1,12.37,700,1,14.60,700,1,ARL,309524933
1347,2025-07-17T15:49:59.511938438Z,2025-07-17T15:49:59.511938438Z,10,2,1108,C,A,0,13.680000000,100,0,165626,259313537,13.04,2,1,13.65,15,1,13.03,100,1,13.67,15,1,13.02,100,1,13.68,100,1,12.73,100,1,13.98,2,1,12.71,100,1,14.01,100,1,12.50,700,1,14.28,100,1,12.46,200,1,14.40,100,1,12.43,700,1,14.50,100,1,12.42,700,1,14.56,800,1,12.37,700,1,14.60,700,1,ARL,308998225
1348,2025-07-17T15:49:59.511938438Z,2025-07-17T15:49:59.511938438Z,10,2,1108,A,A,0,13.660000000,100,130,165626,259313537,13.04,2,1,13.65,15,1,13.03,100,1,13.66,100,1,13.02,100,1,13.67,15,1,12.73,100,1,13.68,100,1,12.71,100,1,13.98,2,1,12.50,700,1,14.01,100,1,12.46,200,1,14.28,100,1,12.43,700,1,14.40,100,1,12.42,700,1,14.50,100,1,12.37,700,1,14.56,800,1,ARL,309782481
1349,2025-07-17T15:49:59.533897369Z,2025-07-17T15:49:59.533897369Z,10,2,1108,C,A,0,14.010000000,100,130,165265,259314032,13.04,2,1,13.65,15,1,13.03,100,1,13.66,100,1,13.02,100,1,13.67,15,1,12.73,100,1,13.68,100,1,12.71,100,1,13.98,2,1,12.50,700,1,14.28,100,1,12.46,200,1,14.40,100,1,12.43,700,1,14.50,100,1,12.42,700,1,14.56,800,1,12.37,700,1,14.60,700,1,ARL,308375185
1350,2025-07-17T15:49:59.533948952Z,2025-07-17T15:49:59.533948952Z,10,2,1108,A,A,0,13.930000000,100,130,166323,259314033,13.04,2,1,13.65,15,1,13.03,100,1,13.66,100,1,13.02,100,1,13.67,15,1,12.73,100,1,13.68,100,1,12.71,100,1,13.93,100,1,12.50,700,1,13.98,2,1,12.46,200,1,14.28,100,1,12.43,700,1,14.40,100,1,12.42,700,1,14.50,100,1,12.37,700,1,14.56,800,1,ARL,309782973
1351,2025-07-17T15:50:00.547239401Z,2025-07-17T15:50:00.547239401Z,10,2,1108,C,A,0,13.670000000,15,130,165571,259349868,13.04,2,1,13.65,15,1,13.03,100,1,13.66,100,1,13.02,100,1,13.68,100,1,12.73,100,1,13.93,100,1,12.71,100,1,13.98,2,1,12.50,700,1,14.28,100,1,12.46,200,1,14.40,100,1,12.43,700,1,14.50,100,1,12.42,700,1,14.56,800,1,12.37,700,1,14.60,700,1,ARL,309524921
1352,2025-07-17T15:50:00.555363249Z,2025-07-17T15:50:00.555363249Z,10,2,1108,C,A,0,14.650000000,100,0,173439,259353226,13.04,2,1,13.65,15,1,13.03,100,1,13.66,100,1,13.02,100,1,13.68,100,1,12.73,100,1,13.93,100,1,12.71,100,1,13.98,2,1,12.50,700,1,14.28,100,1,12.46,200,1,14.40,100,1,12.43,700,1,14.50,100,1,12.42,700,1,14.56,800,1,12.37,700,1,14.60,700,1,ARL,307964661
1353,2025-07-17T15:50:00.555363249Z,2025-07-17T15:50:00.555363249Z,10,2,1108,A,A,0,14.540000000,100,128,173439,259353226,13.04,2,1,13.65,15,1,13.03,100,1,13.66,100,1,13.02,100,1,13.68,100,1,12.73,100,1,13.93,100,1,12.71,100,1,13.98,2,1,12.50,700,1,14.28,100,1,12.46,200,1,14.40,100,1,12.43,700,1,14.50,100,1,12.42,700,1,14.54,100,1,12.37,700,1,14.56,800,1,ARL,309823025
1354,2025-07-17T15:50:03.412257475Z,2025-07-17T15:50:03.412257475Z,10,2,1108,A,A,0,13.630000000,15,130,165405,259413272,13.04,2,1,13.63,15,1,13.03,100,1,13.65,15,1,13.02,100,1,13.66,100,1,12.73,100,1,13.68,100,1,12.71,100,1,13.93,100,1,12.50,700,1,13.98,2,1,12.46,200,1,14.28,100,1,12.43,700,1,14.40,100,1,12.42,700,1,14.50,100,1,12.37,700,1,14.54,100,1,ARL,309899025
1355,2025-07-17T15:50:03.415361851Z,2025-07-17T15:50:03.415361851Z,10,2,1108,C,A,0,14.640000000,100,0,165521,259413427,13.04,2,1,13.63,15,1,13.03,100,1,13.65,15,1,13.02,100,1,13.66,100,1,12.73,100,1,13.68,100,1,12.71,100,1,13.93,100,1,12.50,700,1,13.98,2,1,12.46,200,1,14.28,100,1,12.43,700,1,14.40,100,1,12.42,700,1,14.50,100,1,12.37,700,1,14.54,100,1,ARL,308296381
1356,2025-07-17T15:50:03.415361851Z,2025-07-17T15:50:03.415361851Z,10,2,1108,A,A,0,14.530000000,100,130,165521,259413427,13.04,2,1,13.63,15,1,13.03,100,1,13.65,15,1,13.02,100,1,13.66,100,1,12.73,100,1,13.68,100,1,12.71,100,1,13.93,100,1,12.50,700,1,13.98,2,1,12.46,200,1,14.28,100,1,12.43,700,1,14.40,100,1,12.42,700,1,14.50,100,1,12.37,700,1,14.53,100,1,ARL,309899141
1357,2025-07-17T15:50:03.824126753Z,2025-07-17T15:50:03.824126753Z,10,2,1108,C,A,0,13.660000000,100,0,165399,259418661,13.04,2,1,13.63,15,1,13.03,100,1,13.65,15,1,13.02,100,1,13.68,100,1,12.73,100,1,13.93,100,1,12.71,100,1,13.98,2,1,12.50,700,1,14.28,100,1,12.46,200,1,14.40,100,1,12.43,700,1,14.50,100,1,12.42,700,1,14.53,100,1,12.37,700,1,14.54,100,1,ARL,309782481
1358,2025-07-17T15:50:03.824126753Z,2025-07-17T15:50:03.824126753Z,10,2,1108,A,A,0,13.640000000,100,130,165399,259418661,13.04,2,1,13.63,15,1,13.03,100,1,13.64,100,1,13.02,100,1,13.65,15,1,12.73,100,1,13.68,100,1,12.71,100,1,13.93,100,1,12.50,700,1,13.98,2,1,12.46,200,1,14.28,100,1,12.43,700,1,14.40,100,1,12.42,700,1,14.50,100,1,12.37,700,1,14.53,100,1,ARL,309903973
1359,2025-07-17T15:50:03.824863026Z,2025-07-17T15:50:03.824863026Z,10,2,1108,C,A,0,14.740000000,100,0,165434,259418664,13.04,2,1,13.63,15,1,13.03,100,1,13.64,100,1,13.02,100,1,13.65,15,1,12.73,100,1,13.68,100,1,12.71,100,1,13.93,100,1,12.50,700,1,13.98,2,1,12.46,200,1,14.28,100,1,12.43,700,1,14.40,100,1,12.42,700,1,14.50,100,1,12.37,700,1,14.53,100,1,ARL,308998341
1360,2025-07-17T15:50:03.824863026Z,2025-07-17T15:50:03.824863026Z,10,2,1108,A,A,0,14.700000000,100,130,165434,259418664,13.04,2,1,13.63,15,1,13.03,100,1,13.64,100,1,13.02,100,1,13.65,15,1,12.73,100,1,13.68,100,1,12.71,100,1,13.93,100,1,12.50,700,1,13.98,2,1,12.46,200,1,14.28,100,1,12.43,700,1,14.40,100,1,12.42,700,1,14.50,100,1,12.37,700,1,14.53,100,1,ARL,309903993
1361,2025-07-17T15:50:04.484733438Z,2025-07-17T15:50:04.484733438Z,10,2,1108,A,A,0,13.660000000,100,130,165321,259433904,13.04,2,1,13.63,15,1,13.03,100,1,13.64,100,1,13.02,100,1,13.65,15,1,12.73,100,1,13.66,100,1,12.71,100,1,13.68,100,1,12.50,700,1,13.93,100,1,12.46,200,1,13.98,2,1,12.43,700,1,14.28,100,1,12.42,700,1,14.40,100,1,12.37,700,1,14.50,100,1,ARL,309922345
1362,2025-07-17T15:50:04.524563568Z,2025-07-17T15:50:04.524563568Z,10,2,1108,C,A,0,13.680000000,100,130,165471,259434652,13.04,2,1,13.63,15,1,13.03,100,1,13.64,100,1,13.02,100,1,13.65,15,1,12.73,100,1,13.66,100,1,12.71,100,1,13.93,100,1,12.50,700,1,13.98,2,1,12.46,200,1,14.28,100,1,12.43,700,1,14.40,100,1,12.42,700,1,14.50,100,1,12.37,700,1,14.53,100,1,ARL,309707413
1363,2025-07-17T15:50:06.787661846Z,2025-07-17T15:50:06.787661846Z,10,2,1108,C,A,0,13.630000000,15,130,165129,259472951,13.04,2,1,13.64,100,1,13.03,100,1,13.65,15,1,13.02,100,1,13.66,100,1,12.73,100,1,13.93,100,1,12.71,100,1,13.98,2,1,12.50,700,1,14.28,100,1,12.46,200,1,14.40,100,1,12.43,700,1,14.50,100,1,12.42,700,1,14.53,100,1,12.37,700,1,14.54,100,1,ARL,309899025
1364,2025-07-17T15:50:09.185334126Z,2025-07-17T15:50:09.185334126Z,10,2,1108,A,A,0,13.610000000,15,130,165241,259516855,13.04,2,1,13.61,15,1,13.03,100,1,13.64,100,1,13.02,100,1,13.65,15,1,12.73,100,1,13.66,100,1,12.71,100,1,13.93,100,1,12.50,700,1,13.98,2,1,12.46,200,1,14.28,100,1,12.43,700,1,14.40,100,1,12.42,700,1,14.50,100,1,12.37,700,1,14.53,100,1,ARL,310030465
1365,2025-07-17T15:50:09.198311198Z,2025-07-17T15:50:09.198311198Z,10,2,1108,A,A,0,13.640000000,100,130,165239,259517754,13.04,2,1,13.61,15,1,13.03,100,1,13.64,200,1,13.02,100,1,13.65,15,1,12.73,100,1,13.66,100,1,12.71,100,1,13.93,100,1,12.50,700,1,13.98,2,1,12.46,200,1,14.28,100,1,12.43,700,1,14.40,100,1,12.42,700,1,14.50,100,1,12.37,700,1,14.53,100,1,ARL,310031625
1366,2025-07-17T15:50:09.205322092Z,2025-07-17T15:50:09.205322092Z,10,2,1108,C,A,0,13.660000000,100,130,165324,259517973,13.04,2,1,13.61,15,1,13.03,100,1,13.64,200,1,13.02,100,1,13.65,15,1,12.73,100,1,13.93,100,1,12.71,100,1,13.98,2,1,12.50,700,1,14.28,100,1,12.46,200,1,14.40,100,1,12.43,700,1,14.50,100,1,12.42,700,1,14.53,100,1,12.37,700,1,14.54,100,1,ARL,309922345
1367,2025-07-17T15:50:09.330572653Z,2025-07-17T15:50:09.330572653Z,10,2,1108,C,A,0,13.640000000,100,0,165500,259522708,13.04,2,1,13.61,15,1,13.03,100,1,13.64,100,1,13.02,100,1,13.65,15,1,12.73,100,1,13.93,100,1,12.71,100,1,13.98,2,1,12.50,700,1,14.28,100,1,12.46,200,1,14.40,100,1,12.43,700,1,14.50,100,1,12.42,700,1,14.53,100,1,12.37,700,1,14.54,100,1,ARL,309903973
1368,2025-07-17T15:50:09.330572653Z,2025-07-17T15:50:09.330572653Z,10,2,1108,A,A,0,13.620000000,100,130,165500,259522708,13.04,2,1,13.61,15,1,13.03,100,1,13.62,100,1,13.02,100,1,13.64,100,1,12.73,100,1,13.65,15,1,12.71,100,1,13.93,100,1,12.50,700,1,13.98,2,1,12.46,200,1,14.28,100,1,12.43,700,1,14.40,100,1,12.42,700,1,14.50,100,1,12.37,700,1,14.53,100,1,ARL,310037965
1369,2025-07-17T15:50:20.204373858Z,2025-07-17T15:50:20.204373858Z,10,2,1108,C,A,0,13.650000000,15,130,165327,259737768,13.04,2,1,13.61,15,1,13.03,100,1,13.62,100,1,13.02,100,1,13.64,100,1,12.73,100,1,13.93,100,1,12.71,100,1,13.98,2,1,12.50,700,1,14.28,100,1,12.46,200,1,14.40,100,1,12.43,700,1,14.50,100,1,12.42,700,1,14.53,100,1,12.37,700,1,14.54,100,1,ARL,309707269
1370,2025-07-17T15:50:25.935412900Z,2025-07-17T15:50:25.935412900Z,10,2,1108,A,A,0,13.590000000,15,128,166134,259828644,13.04,2,1,13.59,15,1,13.03,100,1,13.61,15,1,13.02,100,1,13.62,100,1,12.73,100,1,13.64,100,1,12.71,100,1,13.93,100,1,12.50,700,1,13.98,2,1,12.46,200,1,14.28,100,1,12.43,700,1,14.40,100,1,12.42,700,1,14.50,100,1,12.37,700,1,14.53,100,1,ARL,310424077
1371,2025-07-17T15:50:26.954662143Z,2025-07-17T15:50:26.954662143Z,10,2,1108,C,A,0,13.620000000,100,0,166007,259847181,13.04,2,1,13.59,15,1,13.03,100,1,13.61,15,1,13.02,100,1,13.64,100,1,12.73,100,1,13.93,100,1,12.71,100,1,13.98,2,1,12.50,700,1,14.28,100,1,12.46,200,1,14.40,100,1,12.43,700,1,14.50,100,1,12.42,700,1,14.53,100,1,12.37,700,1,14.54,100,1,ARL,310037965
1372,2025-07-17T15:50:26.954662143Z,2025-07-17T15:50:26.954662143Z,10,2,1108,A,A,0,13.600000000,100,130,166007,259847181,13.04,2,1,13.59,15,1,13.03,100,1,13.60,100,1,13.02,100,1,13.61,15,1,12.73,100,1,13.64,100,1,12.71,100,1,13.93,100,1,12.50,700,1,13.98,2,1,12.46,200,1,14.28,100,1,12.43,700,1,14.40,100,1,12.42,700,1,14.50,100,1,12.37,700,1,14.53,100,1,ARL,310446249
1373,2025-07-17T15:50:26.955400327Z,2025-07-17T15:50:26.955400327Z,10,2,1108,C,A,0,14.700000000,100,0,165577,259847190,13.04,2,1,13.59,15,1,13.03,100,1,13.60,100,1,13.02,100,1,13.61,15,1,12.73,100,1,13.64,100,1,12.71,100,1,13.93,100,1,12.50,700,1,13.98,2,1,12.46,200,1,14.28,100,1,12.43,700,1,14.40,100,1,12.42,700,1,14.50,100,1,12.37,700,1,14.53,100,1,ARL,309903993
1374,2025-07-17T15:50:26.955400327Z,2025-07-17T15:50:26.955400327Z,10,2,1108,A,A,0,14.650000000,100,130,165577,259847190,13.04,2,1,13.59,15,1,13.03,100,1,13.60,100,1,13.02,100,1,13.61,15,1,12.73,100,1,13.64,100,1,12.71,100,1,13.93,100,1,12.50,700,1,13.98,2,1,12.46,200,1,14.28,100,1,12.43,700,1,14.40,100,1,12.42,700,1,14.50,100,1,12.37,700,1,14.53,100,1,ARL,310446269
1375,2025-07-17T15:50:26.956094101Z,2025-07-17T15:50:26.956094101Z,10,2,1108,C,A,0,17.430000000,100,0,165407,259847199,13.04,2,1,13.59,15,1,13.03,100,1,13.60,100,1,13.02,100,1,13.61,15,1,12.73,100,1,13.64,100,1,12.71,100,1,13.93,100,1,12.50,700,1,13.98,2,1,12.46,200,1,14.28,100,1,12.43,700,1,14.40,100,1,12.42,700,1,14.50,100,1,12.37,700,1,14.53,100,1,ARL,308799373
1376,2025-07-17T15:50:26.956094101Z,2025-07-17T15:50:26.956094101Z,10,2,1108,A,A,0,17.280000000,100,130,165407,259847199,13.04,2,1,13.59,15,1,13.03,100,1,13.60,100,1,13.02,100,1,13.61,15,1,12.73,100,1,13.64,100,1,12.71,100,1,13.93,100,1,12.50,700,1,13.98,2,1,12.46,200,1,14.28,100,1,12.43,700,1,14.40,100,1,12.42,700,1,14.50,100,1,12.37,700,1,14.53,100,1,ARL,310446293
1377,2025-07-17T15:50:26.982879448Z,2025-07-17T15:50:26.982879448Z,10,2,1108,A,A,0,15.510000000,100,130,165288,259847556,13.04,2,1,13.59,15,1,13.03,100,1,13.60,100,1,13.02,100,1,13.61,15,1,12.73,100,1,13.64,100,1,12.71,100,1,13.93,100,1,12.50,700,1,13.98,2,1,12.46,200,1,14.28,100,1,12.43,700,1,14.40,100,1,12.42,700,1,14.50,100,1,12.37,700,1,14.53,100,1,ARL,310447441
1378,2025-07-17T15:50:26.982892468Z,2025-07-17T15:50:26.982892468Z,10,2,1108,C,A,0,15.780000000,100,130,165207,259847557,13.04,2,1,13.59,15,1,13.03,100,1,13.60,100,1,13.02,100,1,13.61,15,1,12.73,100,1,13.64,100,1,12.71,100,1,13.93,100,1,12.50,700,1,13.98,2,1,12.46,200,1,14.28,100,1,12.43,700,1,14.40,100,1,12.42,700,1,14.50,100,1,12.37,700,1,14.53,100,1,ARL,282776733
1379,2025-07-17T15:50:30.046714265Z,2025-07-17T15:50:30.046714265Z,10,2,1108,C,A,0,13.590000000,15,130,165304,259916670,13.04,2,1,13.60,100,1,13.03,100,1,13.61,15,1,13.02,100,1,13.64,100,1,12.73,100,1,13.93,100,1,12.71,100,1,13.98,2,1,12.50,700,1,14.28,100,1,12.46,200,1,14.40,100,1,12.43,700,1,14.50,100,1,12.42,700,1,14.53,100,1,12.37,700,1,14.54,100,1,ARL,310424077
1380,2025-07-17T15:50:30.046849726Z,2025-07-17T15:50:30.046849726Z,10,2,1108,C,A,0,13.610000000,15,130,165388,259916674,13.04,2,1,13.60,100,1,13.03,100,1,13.64,100,1,13.02,100,1,13.93,100,1,12.73,100,1,13.98,2,1,12.71,100,1,14.28,100,1,12.50,700,1,14.40,100,1,12.46,200,1,14.50,100,1,12.43,700,1,14.53,100,1,12.42,700,1,14.54,100,1,12.37,700,1,14.56,800,1,ARL,310030465
1381,2025-07-17T15:51:37.985992174Z,2025-07-17T15:51:37.985992174Z,10,2,1108,C,A,0,13.980000000,2,0,166156,261130345,13.04,2,1,13.60,100,1,13.03,100,1,13.64,100,1,13.02,100,1,13.93,100,1,12.73,100,1,14.28,100,1,12.71,100,1,14.40,100,1,12.50,700,1,14.50,100,1,12.46,200,1,14.53,100,1,12.43,700,1,14.54,100,1,12.42,700,1,14.56,800,1,12.37,700,1,14.60,700,1,ARL,309091513
1382,2025-07-17T15:51:37.985992174Z,2025-07-17T15:51:37.985992174Z,10,2,1108,A,A,0,13.890000000,2,130,166156,261130345,13.04,2,1,13.60,100,1,13.03,100,1,13.64,100,1,13.02,100,1,13.89,2,1,12.73,100,1,13.93,100,1,12.71,100,1,14.28,100,1,12.50,700,1,14.40,100,1,12.46,200,1,14.50,100,1,12.43,700,1,14.53,100,1,12.42,700,1,14.54,100,1,12.37,700,1,14.56,800,1,ARL,311979125
1383,2025-07-17T15:52:16.371351021Z,2025-07-17T15:52:16.371351021Z,10,2,1108,T,N,0,13.410000000,58,0,166818,261713745,13.04,2,1,13.60,100,1,13.03,100,1,13.64,100,1,13.02,100,1,13.89,2,1,12.73,100,1,13.93,100,1,12.71,100,1,14.28,100,1,12.50,700,1,14.40,100,1,12.46,200,1,14.50,100,1,12.43,700,1,14.53,100,1,12.42,700,1,14.54,100,1,12.37,700,1,14.56,800,1,ARL,0
1384,2025-07-17T15:52:16.371351021Z,2025-07-17T15:52:16.371351021Z,10,2,1108,T,N,0,13.280000000,12,130,166818,261713746,13.04,2,1,13.60,100,1,13.03,100,1,13.64,100,1,13.02,100,1,13.89,2,1,12.73,100,1,13.93,100,1,12.71,100,1,14.28,100,1,12.50,700,1,14.40,100,1,12.46,200,1,14.50,100,1,12.43,700,1,14.53,100,1,12.42,700,1,14.54,100,1,12.37,700,1,14.56,800,1,ARL,0
1385,2025-07-17T15:52:16.372269170Z,2025-07-17T15:52:16.372269170Z,10,2,1108,C,A,0,13.600000000,100,130,165455,261713790,13.04,2,1,13.64,100,1,13.03,100,1,13.89,2,1,13.02,100,1,13.93,100,1,12.73,100,1,14.28,100,1,12.71,100,1,14.40,100,1,12.50,700,1,14.50,100,1,12.46,200,1,14.53,100,1,12.43,700,1,14.54,100,1,12.42,700,1,14.56,800,1,12.37,700,1,14.60,700,1,ARL,310446249
1386,2025-07-17T15:52:16.373023186Z,2025-07-17T15:52:16.373023186Z,10,2,1108,C,A,0,14.650000000,100,0,165605,261713830,13.04,2,1,13.64,100,1,13.03,100,1,13.89,2,1,13.02,100,1,13.93,100,1,12.73,100,1,14.28,100,1,12.71,100,1,14.40,100,1,12.50,700,1,14.50,100,1,12.46,200,1,14.53,100,1,12.43,700,1,14.54,100,1,12.42,700,1,14.56,800,1,12.37,700,1,14.60,700,1,ARL,310446269
1387,2025-07-17T15:52:16.373023186Z,2025-07-17T15:52:16.373023186Z,10,2,1108,A,A,0,14.700000000,100,130,165605,261713830,13.04,2,1,13.64,100,1,13.03,100,1,13.89,2,1,13.02,100,1,13.93,100,1,12.73,100,1,14.28,100,1,12.71,100,1,14.40,100,1,12.50,700,1,14.50,100,1,12.46,200,1,14.53,100,1,12.43,700,1,14.54,100,1,12.42,700,1,14.56,800,1,12.37,700,1,14.60,700,1,ARL,312771573
1388,2025-07-17T15:52:16.374186508Z,2025-07-17T15:52:16.374186508Z,10,2,1108,C,A,0,13.640000000,100,130,166651,261713870,13.04,2,1,13.89,2,1,13.03,100,1,13.93,100,1,13.02,100,1,14.28,100,1,12.73,100,1,14.40,100,1,12.71,100,1,14.50,100,1,12.50,700,1,14.53,100,1,12.46,200,1,14.54,100,1,12.43,700,1,14.56,800,1,12.42,700,1,14.60,700,1,12.37,700,1,14.66,200,1,ARL,310031625
1389,2025-07-17T15:52:16.374312976Z,2025-07-17T15:52:16.374312976Z,10,2,1108,A,A,0,15.860000000,100,128,167207,261713880,13.04,2,1,13.89,2,1,13.03,100,1,13.93,100,1,13.02,100,1,14.28,100,1,12.73,100,1,14.40,100,1,12.71,100,1,14.50,100,1,12.50,700,1,14.53,100,1,12.46,200,1,14.54,100,1,12.43,700,1,14.56,800,1,12.42,700,1,14.60,700,1,12.37,700,1,14.66,200,1,ARL,312771645
1390,2025-07-17T15:52:16.374327668Z,2025-07-17T15:52:16.374327668Z,10,2,1108,C,A,0,15.510000000,100,130,165982,261713884,13.04,2,1,13.89,2,1,13.03,100,1,13.93,100,1,13.02,100,1,14.28,100,1,12.73,100,1,14.40,100,1,12.71,100,1,14.50,100,1,12.50,700,1,14.53,100,1,12.46,200,1,14.54,100,1,12.43,700,1,14.56,800,1,12.42,700,1,14.60,700,1,12.37,700,1,14.66,200,1,ARL,310447441
1391,2025-07-17T15:52:16.375222836Z,2025-07-17T15:52:16.375222836Z,10,2,1108,C,A,0,14.540000000,100,0,165449,261713944,13.04,2,1,13.89,2,1,13.03,100,1,13.93,100,1,13.02,100,1,14.28,100,1,12.73,100,1,14.40,100,1,12.71,100,1,14.50,100,1,12.50,700,1,14.53,100,1,12.46,200,1,14.56,800,1,12.43,700,1,14.60,700,1,12.42,700,1,14.66,200,1,12.37,700,1,14.68,1400,1,ARL,309823025
1392,2025-07-17T15:52:16.375222836Z,2025-07-17T15:52:16.375222836Z,10,2,1108,A,A,0,14.810000000,100,130,165449,261713944,13.04,2,1,13.89,2,1,13.03,100,1,13.93,100,1,13.02,100,1,14.28,100,1,12.73,100,1,14.40,100,1,12.71,100,1,14.50,100,1,12.50,700,1,14.53,100,1,12.46,200,1,14.56,800,1,12.43,700,1,14.60,700,1,12.42,700,1,14.66,200,1,12.37,700,1,14.68,1400,1,ARL,312771781
1393,2025-07-17T15:52:16.375248654Z,2025-07-17T15:52:16.375248654Z,10,2,1108,C,A,0,14.660000000,100,0,165593,261713945,13.04,2,1,13.89,2,1,13.03,100,1,13.93,100,1,13.02,100,1,14.28,100,1,12.73,100,1,14.40,100,1,12.71,100,1,14.50,100,1,12.50,700,1,14.53,100,1,12.46,200,1,14.56,800,1,12.43,700,1,14.60,700,1,12.42,700,1,14.66,100,1,12.37,700,1,14.68,1400,1,ARL,308901981
1394,2025-07-17T15:52:16.375248654Z,2025-07-17T15:52:16.375248654Z,10,2,1108,A,A,0,14.890000000,100,130,165593,261713945,13.04,2,1,13.89,2,1,13.03,100,1,13.93,100,1,13.02,100,1,14.28,100,1,12.73,100,1,14.40,100,1,12.71,100,1,14.50,100,1,12.50,700,1,14.53,100,1,12.46,200,1,14.56,800,1,12.43,700,1,14.60,700,1,12.42,700,1,14.66,100,1,12.37,700,1,14.68,1400,1,ARL,312771785
1395,2025-07-17T15:52:16.375662552Z,2025-07-17T15:52:16.375662552Z,10,2,1108,C,A,0,14.530000000,100,0,165602,261713959,13.04,2,1,13.89,2,1,13.03,100,1,13.93,100,1,13.02,100,1,14.28,100,1,12.73,100,1,14.40,100,1,12.71,100,1,14.50,100,1,12.50,700,1,14.56,800,1,12.46,200,1,14.60,700,1,12.43,700,1,14.66,100,1,12.42,700,1,14.68,1400,1,12.37,700,1,14.70,100,1,ARL,309899141
1396,2025-07-17T15:52:16.375662552Z,2025-07-17T15:52:16.375662552Z,10,2,1108,A,A,0,14.760000000,100,130,165602,261713959,13.04,2,1,13.89,2,1,13.03,100,1,13.93,100,1,13.02,100,1,14.28,100,1,12.73,100,1,14.40,100,1,12.71,100,1,14.50,100,1,12.50,700,1,14.56,800,1,12.46,200,1,14.60,700,1,12.43,700,1,14.66,100,1,12.42,700,1,14.68,1400,1,12.37,700,1,14.70,100,1,ARL,312771829
1397,2025-07-17T15:52:16.377179230Z,2025-07-17T15:52:16.377179230Z,10,2,1108,C,A,0,17.280000000,100,0,165823,261714104,13.04,2,1,13.89,2,1,13.03,100,1,13.93,100,1,13.02,100,1,14.28,100,1,12.73,100,1,14.40,100,1,12.71,100,1,14.50,100,1,12.50,700,1,14.56,800,1,12.46,200,1,14.60,700,1,12.43,700,1,14.66,100,1,12.42,700,1,14.68,1400,1,12.37,700,1,14.70,100,1,ARL,310446293
1398,2025-07-17T15:52:16.377179230Z,2025-07-17T15:52:16.377179230Z,10,2,1108,A,A,0,17.700000000,100,130,165823,261714104,13.04,2,1,13.89,2,1,13.03,100,1,13.93,100,1,13.02,100,1,14.28,100,1,12.73,100,1,14.40,100,1,12.71,100,1,14.50,100,1,12.50,700,1,14.56,800,1,12.46,200,1,14.60,700,1,12.43,700,1,14.66,100,1,12.42,700,1,14.68,1400,1,12.37,700,1,14.70,100,1,ARL,312772009
1399,2025-07-17T15:52:16.378073674Z,2025-07-17T15:52:16.378073674Z,10,2,1108,C,A,0,15.760000000,100,0,165440,261714140,13.04,2,1,13.89,2,1,13.03,100,1,13.93,100,1,13.02,100,1,14.28,100,1,12.73,100,1,14.40,100,1,12.71,100,1,14.50,100,1,12.50,700,1,14.56,800,1,12.46,200,1,14.60,700,1,12.43,700,1,14.66,100,1,12.42,700,1,14.68,1400,1,12.37,700,1,14.70,100,1,ARL,308902229
1400,2025-07-17T15:52:16.378073674Z,2025-07-17T15:52:16.378073674Z,10,2,1108,A,A,0,16.020000000,100,130,165440,261714140,13.04,2,1,13.89,2,1,13.03,100,1,13.93,100,1,13.02,100,1,14.28,100,1,12.73,100,1,14.40,100,1,12.71,100,1,14.50,100,1,12.50,700,1,14.56,800,1,12.46,200,1,14.60,700,1,12.43,700,1,14.66,100,1,12.42,700,1,14.68,1400,1,12.37,700,1,14.70,100,1,ARL,312772057
1401,2025-07-17T15:52:16.378220434Z,2025-07-17T15:52:16.378220434Z,10,2,1108,C,A,0,14.500000000,100,0,165509,261714145,13.04,2,1,13.89,2,1,13.03,100,1,13.93,100,1,13.02,100,1,14.28,100,1,12.73,100,1,14.40,100,1,12.71,100,1,14.56,800,1,12.50,700,1,14.60,700,1,12.46,200,1,14.66,100,1,12.43,700,1,14.68,1400,1,12.42,700,1,14.70,100,1,12.37,700,1,14.76,100,1,ARL,308903349
1402,2025-07-17T15:52:16.378220434Z,2025-07-17T15:52:16.378220434Z,10,2,1108,A,A,0,14.720000000,100,130,165509,261714145,13.04,2,1,13.89,2,1,13.03,100,1,13.93,100,1,13.02,100,1,14.28,100,1,12.73,100,1,14.40,100,1,12.71,100,1,14.56,800,1,12.50,700,1,14.60,700,1,12.46,200,1,14.66,100,1,12.43,700,1,14.68,1400,1,12.42,700,1,14.70,100,1,12.37,700,1,14.72,100,1,ARL,312772061
1403,2025-07-17T15:52:16.378705201Z,2025-07-17T15:52:16.378705201Z,10,2,1108,A,B,0,13.270000000,10,130,165437,261714171,13.27,10,1,13.89,2,1,13.04,2,1,13.93,100,1,13.03,100,1,14.28,100,1,13.02,100,1,14.40,100,1,12.73,100,1,14.56,800,1,12.71,100,1,14.60,700,1,12.50,700,1,14.66,100,1,12.46,200,1,14.68,1400,1,12.43,700,1,14.70,100,1,12.42,700,1,14.72,100,1,ARL,312772069
1404,2025-07-17T15:52:16.378707041Z,2025-07-17T15:52:16.378707041Z,10,2,1108,A,A,0,13.860000000,15,130,165344,261714172,13.27,10,1,13.86,15,1,13.04,2,1,13.89,2,1,13.03,100,1,13.93,100,1,13.02,100,1,14.28,100,1,12.73,100,1,14.40,100,1,12.71,100,1,14.56,800,1,12.50,700,1,14.60,700,1,12.46,200,1,14.66,100,1,12.43,700,1,14.68,1400,1,12.42,700,1,14.70,100,1,ARL,312772073
1405,2025-07-17T15:52:16.378962330Z,2025-07-17T15:52:16.378962330Z,10,2,1108,C,B,0,13.020000000,100,0,165452,261714185,13.27,10,1,13.86,15,1,13.04,2,1,13.89,2,1,13.03,100,1,13.93,100,1,12.73,100,1,14.28,100,1,12.71,100,1,14.40,100,1,12.50,700,1,14.56,800,1,12.46,200,1,14.60,700,1,12.43,700,1,14.66,100,1,12.42,700,1,14.68,1400,1,12.37,700,1,14.70,100,1,ARL,309415429
1406,2025-07-17T15:52:16.378962330Z,2025-07-17T15:52:16.378962330Z,10,2,1108,A,B,0,13.260000000,100,130,165452,261714185,13.27,10,1,13.86,15,1,13.26,100,1,13.89,2,1,13.04,2,1,13.93,100,1,13.03,100,1,14.28,100,1,12.73,100,1,14.40,100,1,12.71,100,1,14.56,800,1,12.50,700,1,14.60,700,1,12.46,200,1,14.66,100,1,12.43,700,1,14.68,1400,1,12.42,700,1,14.70,100,1,ARL,312772077
1407,2025-07-17T15:52:16.388859982Z,2025-07-17T15:52:16.388859982Z,10,2,1108,C,A,0,13.930000000,100,130,165487,261714477,13.27,10,1,13.86,15,1,13.26,100,1,13.89,2,1,13.04,2,1,14.28,100,1,13.03,100,1,14.40,100,1,12.73,100,1,14.56,800,1,12.71,100,1,14.60,700,1,12.50,700,1,14.66,100,1,12.46,200,1,14.68,1400,1,12.43,700,1,14.70,100,1,12.42,700,1,14.72,100,1,ARL,309782973
1408,2025-07-17T15:52:16.388917108Z,2025-07-17T15:52:16.388917108Z,10,2,1108,A,A,0,14.190000000,100,130,165343,261714481,13.27,10,1,13.86,15,1,13.26,100,1,13.89,2,1,13.04,2,1,14.19,100,1,13.03,100,1,14.28,100,1,12.73,100,1,14.40,100,1,12.71,100,1,14.56,800,1,12.50,700,1,14.60,700,1,12.46,200,1,14.66,100,1,12.43,700,1,14.68,1400,1,12.42,700,1,14.70,100,1,ARL,312772501
1409,2025-07-17T15:52:16.396008715Z,2025-07-17T15:52:16.396008715Z,10,2,1108,C,A,0,14.660000000,100,0,165787,261714603,13.27,10,1,13.86,15,1,13.26,100,1,13.89,2,1,13.04,2,1,14.19,100,1,13.03,100,1,14.28,100,1,12.73,100,1,14.40,100,1,12.71,100,1,14.56,800,1,12.50,700,1,14.60,700,1,12.46,200,1,14.68,1400,1,12.43,700,1,14.70,100,1,12.42,700,1,14.72,100,1,ARL,308903001
1410,2025-07-17T15:52:16.396008715Z,2025-07-17T15:52:16.396008715Z,10,2,1108,A,A,0,14.960000000,100,130,165787,261714603,13.27,10,1,13.86,15,1,13.26,100,1,13.89,2,1,13.04,2,1,14.19,100,1,13.03,100,1,14.28,100,1,12.73,100,1,14.40,100,1,12.71,100,1,14.56,800,1,12.50,700,1,14.60,700,1,12.46,200,1,14.68,1400,1,12.43,700,1,14.70,100,1,12.42,700,1,14.72,100,1,ARL,312772869
1411,2025-07-17T15:52:16.397512710Z,2025-07-17T15:52:16.397512710Z,10,2,1108,C,A,0,14.190000000,100,130,164971,261714619,13.27,10,1,13.86,15,1,13.26,100,1,13.89,2,1,13.04,2,1,14.28,100,1,13.03,100,1,14.40,100,1,12.73,100,1,14.56,800,1,12.71,100,1,14.60,700,1,12.50,700,1,14.68,1400,1,12.46,200,1,14.70,100,1,12.43,700,1,14.72,100,1,12.42,700,1,14.76,100,1,ARL,312772501
1412,2025-07-17T15:52:16.397561691Z,2025-07-17T15:52:16.397561691Z,10,2,1108,A,A,0,14.260000000,100,130,165351,261714620,13.27,10,1,13.86,15,1,13.26,100,1,13.89,2,1,13.04,2,1,14.26,100,1,13.03,100,1,14.28,100,1,12.73,100,1,14.40,100,1,12.71,100,1,14.56,800,1,12.50,700,1,14.60,700,1,12.46,200,1,14.68,1400,1,12.43,700,1,14.70,100,1,12.42,700,1,14.72,100,1,ARL,312772901
1413,2025-07-17T15:52:16.423972000Z,2025-07-17T15:52:16.423972000Z,10,2,1108,C,A,0,14.700000000,100,0,165423,261714976,13.27,10,1,13.86,15,1,13.26,100,1,13.89,2,1,13.04,2,1,14.26,100,1,13.03,100,1,14.28,100,1,12.73,100,1,14.40,100,1,12.71,100,1,14.56,800,1,12.50,700,1,14.60,700,1,12.46,200,1,14.68,1400,1,12.43,700,1,14.72,100,1,12.42,700,1,14.76,100,1,ARL,312771573
1414,2025-07-17T15:52:16.423972000Z,2025-07-17T15:52:16.423972000Z,10,2,1108,A,A,0,15.060000000,100,130,165423,261714976,13.27,10,1,13.86,15,1,13.26,100,1,13.89,2,1,13.04,2,1,14.26,100,1,13.03,100,1,14.28,100,1,12.73,100,1,14.40,100,1,12.71,100,1,14.56,800,1,12.50,700,1,14.60,700,1,12.46,200,1,14.68,1400,1,12.43,700,1,14.72,100,1,12.42,700,1,14.76,100,1,ARL,312773353
1415,2025-07-17T15:52:16.464616142Z,2025-07-17T15:52:16.464616142Z,10,2,1108,A,A,0,13.870000000,100,130,165201,261715303,13.27,10,1,13.86,15,1,13.26,100,1,13.87,100,1,13.04,2,1,13.89,2,1,13.03,100,1,14.26,100,1,12.73,100,1,14.28,100,1,12.71,100,1,14.40,100,1,12.50,700,1,14.56,800,1,12.46,200,1,14.60,700,1,12.43,700,1,14.68,1400,1,12.42,700,1,14.72,100,1,ARL,312773881
1416,2025-07-17T15:52:16.473391480Z,2025-07-17T15:52:16.473391480Z,10,2,1108,C,A,0,15.060000000,100,0,165468,261715409,13.27,10,1,13.86,15,1,13.26,100,1,13.87,100,1,13.04,2,1,13.89,2,1,13.03,100,1,14.26,100,1,12.73,100,1,14.28,100,1,12.71,100,1,14.40,100,1,12.50,700,1,14.56,800,1,12.46,200,1,14.60,700,1,12.43,700,1,14.68,1400,1,12.42,700,1,14.72,100,1,ARL,312773353
1417,2025-07-17T15:52:16.473391480Z,2025-07-17T15:52:16.473391480Z,10,2,1108,A,A,0,14.950000000,100,130,165468,261715409,13.27,10,1,13.86,15,1,13.26,100,1,13.87,100,1,13.04,2,1,13.89,2,1,13.03,100,1,14.26,100,1,12.73,100,1,14.28,100,1,12.71,100,1,14.40,100,1,12.50,700,1,14.56,800,1,12.46,200,1,14.60,700,1,12.43,700,1,14.68,1400,1,12.42,700,1,14.72,100,1,ARL,312774001
1418,2025-07-17T15:52:16.479925781Z,2025-07-17T15:52:16.479925781Z,10,2,1108,C,A,0,14.260000000,100,130,165113,261715467,13.27,10,1,13.86,15,1,13.26,100,1,13.87,100,1,13.04,2,1,13.89,2,1,13.03,100,1,14.28,100,1,12.73,100,1,14.40,100,1,12.71,100,1,14.56,800,1,12.50,700,1,14.60,700,1,12.46,200,1,14.68,1400,1,12.43,700,1,14.72,100,1,12.42,700,1,14.76,100,1,ARL,312772901
1419,2025-07-17T15:52:16.479974840Z,2025-07-17T15:52:16.479974840Z,10,2,1108,A,A,0,14.150000000,100,130,165291,261715468,13.27,10,1,13.86,15,1,13.26,100,1,13.87,100,1,13.04,2,1,13.89,2,1,13.03,100,1,14.15,100,1,12.73,100,1,14.28,100,1,12.71,100,1,14.40,100,1,12.50,700,1,14.56,800,1,12.46,200,1,14.60,700,1,12.43,700,1,14.68,1400,1,12.42,700,1,14.72,100,1,ARL,312774033
1420,2025-07-17T15:52:28.787151494Z,2025-07-17T15:52:28.787151494Z,10,2,1108,C,B,0,13.270000000,10,130,165371,261883294,13.26,100,1,13.86,15,1,13.04,2,1,13.87,100,1,13.03,100,1,13.89,2,1,12.73,100,1,14.15,100,1,12.71,100,1,14.28,100,1,12.50,700,1,14.40,100,1,12.46,200,1,14.56,800,1,12.43,700,1,14.60,700,1,12.42,700,1,14.68,1400,1,12.37,700,1,14.72,100,1,ARL,312772069
1421,2025-07-17T15:52:28.787152437Z,2025-07-17T15:52:28.787152437Z,10,2,1108,C,A,0,13.860000000,15,130,165390,261883295,13.26,100,1,13.87,100,1,13.04,2,1,13.89,2,1,13.03,100,1,14.15,100,1,12.73,100,1,14.28,100,1,12.71,100,1,14.40,100,1,12.50,700,1,14.56,800,1,12.46,200,1,14.60,700,1,12.43,700,1,14.68,1400,1,12.42,700,1,14.72,100,1,12.37,700,1,14.76,100,1,ARL,312772073
1422,2025-07-17T15:52:43.128203357Z,2025-07-17T15:52:43.128203357Z,10,2,1108,C,A,0,13.890000000,2,0,167676,262115170,13.26,100,1,13.87,100,1,13.04,2,1,14.15,100,1,13.03,100,1,14.28,100,1,12.73,100,1,14.40,100,1,12.71,100,1,14.56,800,1,12.50,700,1,14.60,700,1,12.46,200,1,14.68,1400,1,12.43,700,1,14.72,100,1,12.42,700,1,14.76,100,1,12.37,700,1,14.81,100,1,ARL,311979125
1423,2025-07-17T15:52:43.128203357Z,2025-07-17T15:52:43.128203357Z,10,2,1108,A,A,0,13.990000000,2,128,167676,262115170,13.26,100,1,13.87,100,1,13.04,2,1,13.99,2,1,13.03,100,1,14.15,100,1,12.73,100,1,14.28,100,1,12.71,100,1,14.40,100,1,12.50,700,1,14.56,800,1,12.46,200,1,14.60,700,1,12.43,700,1,14.68,1400,1,12.42,700,1,14.72,100,1,12.37,700,1,14.76,100,1,ARL,313336713
1424,2025-07-17T15:54:24.908318259Z,2025-07-17T15:54:24.908318259Z,10,2,1108,A,B,0,13.290000000,10,130,165523,263863872,13.29,10,1,13.87,100,1,13.26,100,1,13.99,2,1,13.04,2,1,14.15,100,1,13.03,100,1,14.28,100,1,12.73,100,1,14.40,100,1,12.71,100,1,14.56,800,1,12.50,700,1,14.60,700,1,12.46,200,1,14.68,1400,1,12.43,700,1,14.72,100,1,12.42,700,1,14.76,100,1,ARL,315581981
1425,2025-07-17T15:54:26.792313320Z,2025-07-17T15:54:26.792313320Z,10,2,1108,C,B,0,13.290000000,10,130,165136,263895481,13.26,100,1,13.87,100,1,13.04,2,1,13.99,2,1,13.03,100,1,14.15,100,1,12.73,100,1,14.28,100,1,12.71,100,1,14.40,100,1,12.50,700,1,14.56,800,1,12.46,200,1,14.60,700,1,12.43,700,1,14.68,1400,1,12.42,700,1,14.72,100,1,12.37,700,1,14.76,100,1,ARL,315581981
1426,2025-07-17T15:54:52.985950259Z,2025-07-17T15:54:52.985950259Z,10,2,1108,C,A,0,13.990000000,2,0,165824,264262615,13.26,100,1,13.87,100,1,13.04,2,1,14.15,100,1,13.03,100,1,14.28,100,1,12.73,100,1,14.40,100,1,12.71,100,1,14.56,800,1,12.50,700,1,14.60,700,1,12.46,200,1,14.68,1400,1,12.43,700,1,14.72,100,1,12.42,700,1,14.76,100,1,12.37,700,1,14.81,100,1,ARL,313336713
1427,2025-07-17T15:54:52.985950259Z,2025-07-17T15:54:52.985950259Z,10,2,1108,A,A,0,14.100000000,2,130,165824,264262615,13.26,100,1,13.87,100,1,13.04,2,1,14.10,2,1,13.03,100,1,14.15,100,1,12.73,100,1,14.28,100,1,12.71,100,1,14.40,100,1,12.50,700,1,14.56,800,1,12.46,200,1,14.60,700,1,12.43,700,1,14.68,1400,1,12.42,700,1,14.72,100,1,12.37,700,1,14.76,100,1,ARL,316098525
1428,2025-07-17T15:55:33.673432762Z,2025-07-17T15:55:33.673432762Z,10,2,1108,A,B,0,13.290000000,10,130,165490,264905534,13.29,10,1,13.87,100,1,13.26,100,1,14.10,2,1,13.04,2,1,14.15,100,1,13.03,100,1,14.28,100,1,12.73,100,1,14.40,100,1,12.71,100,1,14.56,800,1,12.50,700,1,14.60,700,1,12.46,200,1,14.68,1400,1,12.43,700,1,14.72,100,1,12.42,700,1,14.76,100,1,ARL,316911465
1429,2025-07-17T15:55:34.257251787Z,2025-07-17T15:55:34.257251787Z,10,2,1108,C,B,0,13.260000000,100,0,165417,264919835,13.29,10,1,13.87,100,1,13.04,2,1,14.10,2,1,13.03,100,1,14.15,100,1,12.73,100,1,14.28,100,1,12.71,100,1,14.40,100,1,12.50,700,1,14.56,800,1,12.46,200,1,14.60,700,1,12.43,700,1,14.68,1400,1,12.42,700,1,14.72,100,1,12.37,700,1,14.76,100,1,ARL,312772077
1430,2025-07-17T15:55:34.257251787Z,2025-07-17T15:55:34.257251787Z,10,2,1108,A,B,0,13.280000000,100,130,165417,264919835,13.29,10,1,13.87,100,1,13.28,100,1,14.10,2,1,13.04,2,1,14.15,100,1,13.03,100,1,14.28,100,1,12.73,100,1,14.40,100,1,12.71,100,1,14.56,800,1,12.50,700,1,14.60,700,1,12.46,200,1,14.68,1400,1,12.43,700,1,14.72,100,1,12.42,700,1,14.76,100,1,ARL,316924721
1431,2025-07-17T15:55:40.197584524Z,2025-07-17T15:55:40.197584524Z,10,2,1108,C,B,0,13.290000000,10,130,165876,265015966,13.28,100,1,13.87,100,1,13.04,2,1,14.10,2,1,13.03,100,1,14.15,100,1,12.73,100,1,14.28,100,1,12.71,100,1,14.40,100,1,12.50,700,1,14.56,800,1,12.46,200,1,14.60,700,1,12.43,700,1,14.68,1400,1,12.42,700,1,14.72,100,1,12.37,700,1,14.76,100,1,ARL,316911465
1432,2025-07-17T15:57:51.111121910Z,2025-07-17T15:57:51.111121910Z,10,2,1108,T,N,0,13.600000000,1,0,167045,267268162,13.28,100,1,13.87,100,1,13.04,2,1,14.10,2,1,13.03,100,1,14.15,100,1,12.73,100,1,14.28,100,1,12.71,100,1,14.40,100,1,12.50,700,1,14.56,800,1,12.46,200,1,14.60,700,1,12.43,700,1,14.68,1400,1,12.42,700,1,14.72,100,1,12.37,700,1,14.76,100,1,ARL,0
1433,2025-07-17T15:57:51.111121910Z,2025-07-17T15:57:51.111121910Z,10,2,1108,T,N,0,13.575000000,99,130,167045,267268163,13.28,100,1,13.87,100,1,13.04,2,1,14.10,2,1,13.03,100,1,14.15,100,1,12.73,100,1,14.28,100,1,12.71,100,1,14.40,100,1,12.50,700,1,14.56,800,1,12.46,200,1,14.60,700,1,12.43,700,1,14.68,1400,1,12.42,700,1,14.72,100,1,12.37,700,1,14.76,100,1,ARL,0
1434,2025-07-17T15:57:51.111527963Z,2025-07-17T15:57:51.111527963Z,10,2,1108,T,N,0,13.575000000,100,130,165792,267268168,13.28,100,1,13.87,100,1,13.04,2,1,14.10,2,1,13.03,100,1,14.15,100,1,12.73,100,1,14.28,100,1,12.71,100,1,14.40,100,1,12.50,700,1,14.56,800,1,12.46,200,1,14.60,700,1,12.43,700,1,14.68,1400,1,12.42,700,1,14.72,100,1,12.37,700,1,14.76,100,1,ARL,0
1435,2025-07-17T15:57:51.111911476Z,2025-07-17T15:57:51.111911476Z,10,2,1108,T,N,0,13.575000000,1,130,166056,267268183,13.28,100,1,13.87,100,1,13.04,2,1,14.10,2,1,13.03,100,1,14.15,100,1,12.73,100,1,14.28,100,1,12.71,100,1,14.40,100,1,12.50,700,1,14.56,800,1,12.46,200,1,14.60,700,1,12.43,700,1,14.68,1400,1,12.42,700,1,14.72,100,1,12.37,700,1,14.76,100,1,ARL,0
1436,2025-07-17T15:57:51.328698198Z,2025-07-17T15:57:51.328698198Z,10,2,1108,C,A,0,13.870000000,100,130,165362,267272430,13.28,100,1,14.10,2,1,13.04,2,1,14.15,100,1,13.03,100,1,14.28,100,1,12.73,100,1,14.40,100,1,12.71,100,1,14.56,800,1,12.50,700,1,14.60,700,1,12.46,200,1,14.68,1400,1,12.43,700,1,14.72,100,1,12.42,700,1,14.76,100,1,12.37,700,1,14.81,100,1,ARL,312773881
1437,2025-07-17T15:57:51.329447325Z,2025-07-17T15:57:51.329447325Z,10,2,1108,C,A,0,14.950000000,100,0,166259,267272438,13.28,100,1,14.10,2,1,13.04,2,1,14.15,100,1,13.03,100,1,14.28,100,1,12.73,100,1,14.40,100,1,12.71,100,1,14.56,800,1,12.50,700,1,14.60,700,1,12.46,200,1,14.68,1400,1,12.43,700,1,14.72,100,1,12.42,700,1,14.76,100,1,12.37,700,1,14.81,100,1,ARL,312774001
1438,2025-07-17T15:57:51.329447325Z,2025-07-17T15:57:51.329447325Z,10,2,1108,A,A,0,15.000000000,100,130,166259,267272438,13.28,100,1,14.10,2,1,13.04,2,1,14.15,100,1,13.03,100,1,14.28,100,1,12.73,100,1,14.40,100,1,12.71,100,1,14.56,800,1,12.50,700,1,14.60,700,1,12.46,200,1,14.68,1400,1,12.43,700,1,14.72,100,1,12.42,700,1,14.76,100,1,12.37,700,1,14.81,100,1,ARL,319985021
1439,2025-07-17T15:57:51.329692071Z,2025-07-17T15:57:51.329692071Z,10,2,1108,C,A,0,14.760000000,100,0,165601,267272442,13.28,100,1,14.10,2,1,13.04,2,1,14.15,100,1,13.03,100,1,14.28,100,1,12.73,100,1,14.40,100,1,12.71,100,1,14.56,800,1,12.50,700,1,14.60,700,1,12.46,200,1,14.68,1400,1,12.43,700,1,14.72,100,1,12.42,700,1,14.81,100,1,12.37,700,1,14.89,100,1,ARL,312771829
1440,2025-07-17T15:57:51.329692071Z,2025-07-17T15:57:51.329692071Z,10,2,1108,A,A,0,14.890000000,100,130,165601,267272442,13.28,100,1,14.10,2,1,13.04,2,1,14.15,100,1,13.03,100,1,14.28,100,1,12.73,100,1,14.40,100,1,12.71,100,1,14.56,800,1,12.50,700,1,14.60,700,1,12.46,200,1,14.68,1400,1,12.43,700,1,14.72,100,1,12.42,700,1,14.81,100,1,12.37,700,1,14.89,200,1,ARL,319985025
1441,2025-07-17T15:57:51.339162512Z,2025-07-17T15:57:51.339162512Z,10,2,1108,C,A,0,14.150000000,100,130,165707,267272660,13.28,100,1,14.10,2,1,13.04,2,1,14.28,100,1,13.03,100,1,14.40,100,1,12.73,100,1,14.56,800,1,12.71,100,1,14.60,700,1,12.50,700,1,14.68,1400,1,12.46,200,1,14.72,100,1,12.43,700,1,14.81,100,1,12.42,700,1,14.89,200,1,12.37,700,1,14.96,100,1,ARL,312774033
1442,2025-07-17T15:57:51.339216923Z,2025-07-17T15:57:51.339216923Z,10,2,1108,A,A,0,14.260000000,100,130,165175,267272665,13.28,100,1,14.10,2,1,13.04,2,1,14.26,100,1,13.03,100,1,14.28,100,1,12.73,100,1,14.40,100,1,12.71,100,1,14.56,800,1,12.50,700,1,14.60,700,1,12.46,200,1,14.68,1400,1,12.43,700,1,14.72,100,1,12.42,700,1,14.81,100,1,12.37,700,1,14.89,200,1,ARL,319985165
1443,2025-07-17T15:57:51.379570470Z,2025-07-17T15:57:51.379570470Z,10,2,1108,C,A,0,15.000000000,100,0,166382,267273071,13.28,100,1,14.10,2,1,13.04,2,1,14.26,100,1,13.03,100,1,14.28,100,1,12.73,100,1,14.40,100,1,12.71,100,1,14.56,800,1,12.50,700,1,14.60,700,1,12.46,200,1,14.68,1400,1,12.43,700,1,14.72,100,1,12.42,700,1,14.81,100,1,12.37,700,1,14.89,200,1,ARL,319985021
1444,2025-07-17T15:57:51.379570470Z,2025-07-17T15:57:51.379570470Z,10,2,1108,A,A,0,15.060000000,100,128,166382,267273071,13.28,100,1,14.10,2,1,13.04,2,1,14.26,100,1,13.03,100,1,14.28,100,1,12.73,100,1,14.40,100,1,12.71,100,1,14.56,800,1,12.50,700,1,14.60,700,1,12.46,200,1,14.68,1400,1,12.43,700,1,14.72,100,1,12.42,700,1,14.81,100,1,12.37,700,1,14.89,200,1,ARL,319985497
1445,2025-07-17T15:57:52.378204338Z,2025-07-17T15:57:52.378204338Z,10,2,1108,A,A,0,14.110000000,100,130,165186,267283873,13.28,100,1,14.10,2,1,13.04,2,1,14.11,100,1,13.03,100,1,14.26,100,1,12.73,100,1,14.28,100,1,12.71,100,1,14.40,100,1,12.50,700,1,14.56,800,1,12.46,200,1,14.60,700,1,12.43,700,1,14.68,1400,1,12.42,700,1,14.72,100,1,12.37,700,1,14.81,100,1,ARL,320000233
1446,2025-07-17T15:58:14.483712278Z,2025-07-17T15:58:14.483712278Z,10,2,1108,T,N,0,13.410000000,44,130,166801,267657010,13.28,100,1,14.10,2,1,13.04,2,1,14.11,100,1,13.03,100,1,14.26,100,1,12.73,100,1,14.28,100,1,12.71,100,1,14.40,100,1,12.50,700,1,14.56,800,1,12.46,200,1,14.60,700,1,12.43,700,1,14.68,1400,1,12.42,700,1,14.72,100,1,12.37,700,1,14.81,100,1,ARL,0
1447,2025-07-17T15:58:14.483743947Z,2025-07-17T15:58:14.483743947Z,10,2,1108,A,A,0,13.760000000,4,130,165407,267657011,13.28,100,1,13.76,4,1,13.04,2,1,14.10,2,1,13.03,100,1,14.11,100,1,12.73,100,1,14.26,100,1,12.71,100,1,14.28,100,1,12.50,700,1,14.40,100,1,12.46,200,1,14.56,800,1,12.43,700,1,14.60,700,1,12.42,700,1,14.68,1400,1,12.37,700,1,14.72,100,1,ARL,320484625
1448,2025-07-17T15:58:14.483999049Z,2025-07-17T15:58:14.483999049Z,10,2,1108,C,A,0,14.110000000,100,0,165502,267657013,13.28,100,1,13.76,4,1,13.04,2,1,14.10,2,1,13.03,100,1,14.26,100,1,12.73,100,1,14.28,100,1,12.71,100,1,14.40,100,1,12.50,700,1,14.56,800,1,12.46,200,1,14.60,700,1,12.43,700,1,14.68,1400,1,12.42,700,1,14.72,100,1,12.37,700,1,14.81,100,1,ARL,320000233
1449,2025-07-17T15:58:14.483999049Z,2025-07-17T15:58:14.483999049Z,10,2,1108,A,A,0,13.770000000,100,130,165502,267657013,13.28,100,1,13.76,4,1,13.04,2,1,13.77,100,1,13.03,100,1,14.10,2,1,12.73,100,1,14.26,100,1,12.71,100,1,14.28,100,1,12.50,700,1,14.40,100,1,12.46,200,1,14.56,800,1,12.43,700,1,14.60,700,1,12.42,700,1,14.68,1400,1,12.37,700,1,14.72,100,1,ARL,320484637
1450,2025-07-17T15:58:14.484017806Z,2025-07-17T15:58:14.484017806Z,10,2,1108,C,B,0,13.280000000,100,130,165607,267657014,13.04,2,1,13.76,4,1,13.03,100,1,13.77,100,1,12.73,100,1,14.10,2,1,12.71,100,1,14.26,100,1,12.50,700,1,14.28,100,1,12.46,200,1,14.40,100,1,12.43,700,1,14.56,800,1,12.42,700,1,14.60,700,1,12.37,700,1,14.68,1400,1,12.36,200,1,14.72,100,1,ARL,316924721
1451,2025-07-17T15:58:14.484133730Z,2025-07-17T15:58:14.484133730Z,10,2,1108,T,N,0,13.410000000,8,130,165720,267657017,13.04,2,1,13.76,4,1,13.03,100,1,13.77,100,1,12.73,100,1,14.10,2,1,12.71,100,1,14.26,100,1,12.50,700,1,14.28,100,1,12.46,200,1,14.40,100,1,12.43,700,1,14.56,800,1,12.42,700,1,14.60,700,1,12.37,700,1,14.68,1400,1,12.36,200,1,14.72,100,1,ARL,0
1452,2025-07-17T15:58:14.484147359Z,2025-07-17T15:58:14.484147359Z,10,2,1108,A,A,0,13.790000000,100,130,165173,267657020,13.04,2,1,13.76,4,1,13.03,100,1,13.77,100,1,12.73,100,1,13.79,100,1,12.71,100,1,14.10,2,1,12.50,700,1,14.26,100,1,12.46,200,1,14.28,100,1,12.43,700,1,14.40,100,1,12.42,700,1,14.56,800,1,12.37,700,1,14.60,700,1,12.36,200,1,14.68,1400,1,ARL,320484661
1453,2025-07-17T15:58:14.484736787Z,2025-07-17T15:58:14.484736787Z,10,2,1108,C,A,0,15.060000000,100,0,165388,267657063,13.04,2,1,13.76,4,1,13.03,100,1,13.77,100,1,12.73,100,1,13.79,100,1,12.71,100,1,14.10,2,1,12.50,700,1,14.26,100,1,12.46,200,1,14.28,100,1,12.43,700,1,14.40,100,1,12.42,700,1,14.56,800,1,12.37,700,1,14.60,700,1,12.36,200,1,14.68,1400,1,ARL,319985497
1454,2025-07-17T15:58:14.484736787Z,2025-07-17T15:58:14.484736787Z,10,2,1108,A,A,0,14.840000000,100,130,165388,267657063,13.04,2,1,13.76,4,1,13.03,100,1,13.77,100,1,12.73,100,1,13.79,100,1,12.71,100,1,14.10,2,1,12.50,700,1,14.26,100,1,12.46,200,1,14.28,100,1,12.43,700,1,14.40,100,1,12.42,700,1,14.56,800,1,12.37,700,1,14.60,700,1,12.36,200,1,14.68,1400,1,ARL,320484709
1455,2025-07-17T15:58:14.484761664Z,2025-07-17T15:58:14.484761664Z,10,2,1108,C,A,0,13.760000000,4,128,166184,267657070,13.04,2,1,13.77,100,1,13.03,100,1,13.79,100,1,12.73,100,1,14.10,2,1,12.71,100,1,14.26,100,1,12.50,700,1,14.28,100,1,12.46,200,1,14.40,100,1,12.43,700,1,14.56,800,1,12.42,700,1,14.60,700,1,12.37,700,1,14.68,1400,1,12.36,200,1,14.72,100,1,ARL,320484625
1456,2025-07-17T15:58:14.484798779Z,2025-07-17T15:58:14.484798779Z,10,2,1108,C,A,0,13.770000000,100,130,165091,267657073,13.04,2,1,13.79,100,1,13.03,100,1,14.10,2,1,12.73,100,1,14.26,100,1,12.71,100,1,14.28,100,1,12.50,700,1,14.40,100,1,12.46,200,1,14.56,800,1,12.43,700,1,14.60,700,1,12.42,700,1,14.68,1400,1,12.37,700,1,14.72,100,1,12.36,200,1,14.81,100,1,ARL,320484637
1457,2025-07-17T15:58:14.485227487Z,2025-07-17T15:58:14.485227487Z,10,2,1108,C,A,0,14.810000000,100,0,165416,267657092,13.04,2,1,13.79,100,1,13.03,100,1,14.10,2,1,12.73,100,1,14.26,100,1,12.71,100,1,14.28,100,1,12.50,700,1,14.40,100,1,12.46,200,1,14.56,800,1,12.43,700,1,14.60,700,1,12.42,700,1,14.68,1400,1,12.37,700,1,14.72,100,1,12.36,200,1,14.84,100,1,ARL,312771781
1458,2025-07-17T15:58:14.485227487Z,2025-07-17T15:58:14.485227487Z,10,2,1108,A,A,0,14.680000000,100,130,165416,267657092,13.04,2,1,13.79,100,1,13.03,100,1,14.10,2,1,12.73,100,1,14.26,100,1,12.71,100,1,14.28,100,1,12.50,700,1,14.40,100,1,12.46,200,1,14.56,800,1,12.43,700,1,14.60,700,1,12.42,700,1,14.68,1500,1,12.37,700,1,14.72,100,1,12.36,200,1,14.84,100,1,ARL,320484781
1459,2025-07-17T15:58:14.485666254Z,2025-07-17T15:58:14.485666254Z,10,2,1108,C,A,0,16.020000000,100,0,165348,267657097,13.04,2,1,13.79,100,1,13.03,100,1,14.10,2,1,12.73,100,1,14.26,100,1,12.71,100,1,14.28,100,1,12.50,700,1,14.40,100,1,12.46,200,1,14.56,800,1,12.43,700,1,14.60,700,1,12.42,700,1,14.68,1500,1,12.37,700,1,14.72,100,1,12.36,200,1,14.84,100,1,ARL,312772057
1460,2025-07-17T15:58:14.485666254Z,2025-07-17T15:58:14.485666254Z,10,2,1108,A,A,0,15.860000000,100,130,165348,267657097,13.04,2,1,13.79,100,1,13.03,100,1,14.10,2,1,12.73,100,1,14.26,100,1,12.71,100,1,14.28,100,1,12.50,700,1,14.40,100,1,12.46,200,1,14.56,800,1,12.43,700,1,14.60,700,1,12.42,700,1,14.68,1500,1,12.37,700,1,14.72,100,1,12.36,200,1,14.84,100,1,ARL,320484817
1461,2025-07-17T15:58:14.485685308Z,2025-07-17T15:58:14.485685308Z,10,2,1108,C,A,0,14.960000000,100,0,165566,267657098,13.04,2,1,13.79,100,1,13.03,100,1,14.10,2,1,12.73,100,1,14.26,100,1,12.71,100,1,14.28,100,1,12.50,700,1,14.40,100,1,12.46,200,1,14.56,800,1,12.43,700,1,14.60,700,1,12.42,700,1,14.68,1500,1,12.37,700,1,14.72,100,1,12.36,200,1,14.84,100,1,ARL,312772869
1462,2025-07-17T15:58:14.485685308Z,2025-07-17T15:58:14.485685308Z,10,2,1108,A,A,0,14.760000000,100,130,165566,267657098,13.04,2,1,13.79,100,1,13.03,100,1,14.10,2,1,12.73,100,1,14.26,100,1,12.71,100,1,14.28,100,1,12.50,700,1,14.40,100,1,12.46,200,1,14.56,800,1,12.43,700,1,14.60,700,1,12.42,700,1,14.68,1500,1,12.37,700,1,14.72,100,1,12.36,200,1,14.76,100,1,ARL,320484821
1463,2025-07-17T15:58:14.485824228Z,2025-07-17T15:58:14.485824228Z,10,2,1108,C,A,0,14.890000000,100,0,165415,267657101,13.04,2,1,13.79,100,1,13.03,100,1,14.10,2,1,12.73,100,1,14.26,100,1,12.71,100,1,14.28,100,1,12.50,700,1,14.40,100,1,12.46,200,1,14.56,800,1,12.43,700,1,14.60,700,1,12.42,700,1,14.68,1500,1,12.37,700,1,14.72,100,1,12.36,200,1,14.76,100,1,ARL,319985025
1464,2025-07-17T15:58:14.485824228Z,2025-07-17T15:58:14.485824228Z,10,2,1108,A,A,0,14.690000000,100,130,165415,267657101,13.04,2,1,13.79,100,1,13.03,100,1,14.10,2,1,12.73,100,1,14.26,100,1,12.71,100,1,14.28,100,1,12.50,700,1,14.40,100,1,12.46,200,1,14.56,800,1,12.43,700,1,14.60,700,1,12.42,700,1,14.68,1500,1,12.37,700,1,14.69,100,1,12.36,200,1,14.72,100,1,ARL,320484825
1465,2025-07-17T15:58:14.486240860Z,2025-07-17T15:58:14.486240860Z,10,2,1108,C,A,0,17.700000000,100,0,165495,267657116,13.04,2,1,13.79,100,1,13.03,100,1,14.10,2,1,12.73,100,1,14.26,100,1,12.71,100,1,14.28,100,1,12.50,700,1,14.40,100,1,12.46,200,1,14.56,800,1,12.43,700,1,14.60,700,1,12.42,700,1,14.68,1500,1,12.37,700,1,14.69,100,1,12.36,200,1,14.72,100,1,ARL,312772009
1466,2025-07-17T15:58:14.486240860Z,2025-07-17T15:58:14.486240860Z,10,2,1108,A,A,0,17.520000000,100,130,165495,267657116,13.04,2,1,13.79,100,1,13.03,100,1,14.10,2,1,12.73,100,1,14.26,100,1,12.71,100,1,14.28,100,1,12.50,700,1,14.40,100,1,12.46,200,1,14.56,800,1,12.43,700,1,14.60,700,1,12.42,700,1,14.68,1500,1,12.37,700,1,14.69,100,1,12.36,200,1,14.72,100,1,ARL,320484837
1467,2025-07-17T15:58:14.508012098Z,2025-07-17T15:58:14.508012098Z,10,2,1108,C,A,0,14.260000000,100,130,165158,267657330,13.04,2,1,13.79,100,1,13.03,100,1,14.10,2,1,12.73,100,1,14.28,100,1,12.71,100,1,14.40,100,1,12.50,700,1,14.56,800,1,12.46,200,1,14.60,700,1,12.43,700,1,14.68,1500,1,12.42,700,1,14.69,100,1,12.37,700,1,14.72,100,1,12.36,200,1,14.76,100,1,ARL,319985165
1468,2025-07-17T15:58:14.508062605Z,2025-07-17T15:58:14.508062605Z,10,2,1108,A,A,0,14.050000000,100,130,165285,267657333,13.04,2,1,13.79,100,1,13.03,100,1,14.05,100,1,12.73,100,1,14.10,2,1,12.71,100,1,14.28,100,1,12.50,700,1,14.40,100,1,12.46,200,1,14.56,800,1,12.43,700,1,14.60,700,1,12.42,700,1,14.68,1500,1,12.37,700,1,14.69,100,1,12.36,200,1,14.72,100,1,ARL,320484985
1469,2025-07-17T15:58:14.529391743Z,2025-07-17T15:58:14.529391743Z,10,2,1108,A,B,0,13.020000000,100,130,165365,267657561,13.04,2,1,13.79,100,1,13.03,100,1,14.05,100,1,13.02,100,1,14.10,2,1,12.73,100,1,14.28,100,1,12.71,100,1,14.40,100,1,12.50,700,1,14.56,800,1,12.46,200,1,14.60,700,1,12.43,700,1,14.68,1500,1,12.42,700,1,14.69,100,1,12.37,700,1,14.72,100,1,ARL,320485385
1470,2025-07-17T15:58:14.529413184Z,2025-07-17T15:58:14.529413184Z,10,2,1108,A,A,0,13.800000000,100,130,165107,267657562,13.04,2,1,13.79,100,1,13.03,100,1,13.80,100,1,13.02,100,1,14.05,100,1,12.73,100,1,14.10,2,1,12.71,100,1,14.28,100,1,12.50,700,1,14.40,100,1,12.46,200,1,14.56,800,1,12.43,700,1,14.60,700,1,12.42,700,1,14.68,1500,1,12.37,700,1,14.69,100,1,ARL,320485389
1471,2025-07-17T15:58:14.659734381Z,2025-07-17T15:58:14.659734381Z,10,2,1108,C,A,0,13.790000000,100,130,165045,267658873,13.04,2,1,13.80,100,1,13.03,100,1,14.05,100,1,13.02,100,1,14.10,2,1,12.73,100,1,14.28,100,1,12.71,100,1,14.40,100,1,12.50,700,1,14.56,800,1,12.46,200,1,14.60,700,1,12.43,700,1,14.68,1500,1,12.42,700,1,14.69,100,1,12.37,700,1,14.72,100,1,ARL,320484661
1472,2025-07-17T15:58:14.659773896Z,2025-07-17T15:58:14.659773896Z,10,2,1108,C,A,0,13.800000000,100,130,165334,267658879,13.04,2,1,14.05,100,1,13.03,100,1,14.10,2,1,13.02,100,1,14.28,100,1,12.73,100,1,14.40,100,1,12.71,100,1,14.56,800,1,12.50,700,1,14.60,700,1,12.46,200,1,14.68,1500,1,12.43,700,1,14.69,100,1,12.42,700,1,14.72,100,1,12.37,700,1,14.76,100,1,ARL,320485389
1473,2025-07-17T15:58:14.660502341Z,2025-07-17T15:58:14.660502341Z,10,2,1108,C,A,0,14.840000000,100,0,165295,267658892,13.04,2,1,14.05,100,1,13.03,100,1,14.10,2,1,13.02,100,1,14.28,100,1,12.73,100,1,14.40,100,1,12.71,100,1,14.56,800,1,12.50,700,1,14.60,700,1,12.46,200,1,14.68,1500,1,12.43,700,1,14.69,100,1,12.42,700,1,14.72,100,1,12.37,700,1,14.76,100,1,ARL,320484709
1474,2025-07-17T15:58:14.660502341Z,2025-07-17T15:58:14.660502341Z,10,2,1108,A,A,0,14.910000000,100,130,165295,267658892,13.04,2,1,14.05,100,1,13.03,100,1,14.10,2,1,13.02,100,1,14.28,100,1,12.73,100,1,14.40,100,1,12.71,100,1,14.56,800,1,12.50,700,1,14.60,700,1,12.46,200,1,14.68,1500,1,12.43,700,1,14.69,100,1,12.42,700,1,14.72,100,1,12.37,700,1,14.76,100,1,ARL,320486925
1475,2025-07-17T15:58:14.664213722Z,2025-07-17T15:58:14.664213722Z,10,2,1108,C,A,0,17.520000000,100,0,165240,267658928,13.04,2,1,14.05,100,1,13.03,100,1,14.10,2,1,13.02,100,1,14.28,100,1,12.73,100,1,14.40,100,1,12.71,100,1,14.56,800,1,12.50,700,1,14.60,700,1,12.46,200,1,14.68,1500,1,12.43,700,1,14.69,100,1,12.42,700,1,14.72,100,1,12.37,700,1,14.76,100,1,ARL,320484837
1476,2025-07-17T15:58:14.664213722Z,2025-07-17T15:58:14.664213722Z,10,2,1108,A,A,0,17.760000000,100,130,165240,267658928,13.04,2,1,14.05,100,1,13.03,100,1,14.10,2,1,13.02,100,1,14.28,100,1,12.73,100,1,14.40,100,1,12.71,100,1,14.56,800,1,12.50,700,1,14.60,700,1,12.46,200,1,14.68,1500,1,12.43,700,1,14.69,100,1,12.42,700,1,14.72,100,1,12.37,700,1,14.76,100,1,ARL,320486937
1477,2025-07-17T15:58:14.664774078Z,2025-07-17T15:58:14.664774078Z,10,2,1108,C,A,0,15.860000000,100,0,165232,267658931,13.04,2,1,14.05,100,1,13.03,100,1,14.10,2,1,13.02,100,1,14.28,100,1,12.73,100,1,14.40,100,1,12.71,100,1,14.56,800,1,12.50,700,1,14.60,700,1,12.46,200,1,14.68,1500,1,12.43,700,1,14.69,100,1,12.42,700,1,14.72,100,1,12.37,700,1,14.76,100,1,ARL,320484817
1478,2025-07-17T15:58:14.664774078Z,2025-07-17T15:58:14.664774078Z,10,2,1108,A,A,0,16.080000000,100,130,165232,267658931,13.04,2,1,14.05,100,1,13.03,100,1,14.10,2,1,13.02,100,1,14.28,100,1,12.73,100,1,14.40,100,1,12.71,100,1,14.56,800,1,12.50,700,1,14.60,700,1,12.46,200,1,14.68,1500,1,12.43,700,1,14.69,100,1,12.42,700,1,14.72,100,1,12.37,700,1,14.76,100,1,ARL,320486945
1479,2025-07-17T15:58:14.672150755Z,2025-07-17T15:58:14.672150755Z,10,2,1108,C,A,0,14.050000000,100,130,165051,267658982,13.04,2,1,14.10,2,1,13.03,100,1,14.28,100,1,13.02,100,1,14.40,100,1,12.73,100,1,14.56,800,1,12.71,100,1,14.60,700,1,12.50,700,1,14.68,1500,1,12.46,200,1,14.69,100,1,12.43,700,1,14.72,100,1,12.42,700,1,14.76,100,1,12.37,700,1,14.89,100,1,ARL,320484985
1480,2025-07-17T15:58:14.672200872Z,2025-07-17T15:58:14.672200872Z,10,2,1108,A,A,0,14.120000000,100,130,165102,267658983,13.04,2,1,14.10,2,1,13.03,100,1,14.12,100,1,13.02,100,1,14.28,100,1,12.73,100,1,14.40,100,1,12.71,100,1,14.56,800,1,12.50,700,1,14.60,700,1,12.46,200,1,14.68,1500,1,12.43,700,1,14.69,100,1,12.42,700,1,14.72,100,1,12.37,700,1,14.76,100,1,ARL,320487017
1481,2025-07-17T15:58:14.673019194Z,2025-07-17T15:58:14.673019194Z,10,2,1108,C,A,0,14.120000000,100,130,164922,267658989,13.04,2,1,14.10,2,1,13.03,100,1,14.28,100,1,13.02,100,1,14.40,100,1,12.73,100,1,14.56,800,1,12.71,100,1,14.60,700,1,12.50,700,1,14.68,1500,1,12.46,200,1,14.69,100,1,12.43,700,1,14.72,100,1,12.42,700,1,14.76,100,1,12.37,700,1,14.89,100,1,ARL,320487017
1482,2025-07-17T15:58:14.673065320Z,2025-07-17T15:58:14.673065320Z,10,2,1108,A,A,0,14.260000000,100,130,165160,267658990,13.04,2,1,14.10,2,1,13.03,100,1,14.26,100,1,13.02,100,1,14.28,100,1,12.73,100,1,14.40,100,1,12.71,100,1,14.56,800,1,12.50,700,1,14.60,700,1,12.46,200,1,14.68,1500,1,12.43,700,1,14.69,100,1,12.42,700,1,14.72,100,1,12.37,700,1,14.76,100,1,ARL,320487025
1483,2025-07-17T15:58:14.682780396Z,2025-07-17T15:58:14.682780396Z,10,2,1108,C,A,0,14.760000000,100,0,165145,267659018,13.04,2,1,14.10,2,1,13.03,100,1,14.26,100,1,13.02,100,1,14.28,100,1,12.73,100,1,14.40,100,1,12.71,100,1,14.56,800,1,12.50,700,1,14.60,700,1,12.46,200,1,14.68,1500,1,12.43,700,1,14.69,100,1,12.42,700,1,14.72,100,1,12.37,700,1,14.89,100,1,ARL,320484821
1484,2025-07-17T15:58:14.682780396Z,2025-07-17T15:58:14.682780396Z,10,2,1108,A,A,0,14.960000000,100,130,165145,267659018,13.04,2,1,14.10,2,1,13.03,100,1,14.26,100,1,13.02,100,1,14.28,100,1,12.73,100,1,14.40,100,1,12.71,100,1,14.56,800,1,12.50,700,1,14.60,700,1,12.46,200,1,14.68,1500,1,12.43,700,1,14.69,100,1,12.42,700,1,14.72,100,1,12.37,700,1,14.89,100,1,ARL,320487105
1485,2025-07-17T15:58:14.710622495Z,2025-07-17T15:58:14.710622495Z,10,2,1108,C,A,0,14.910000000,100,0,165396,267659178,13.04,2,1,14.10,2,1,13.03,100,1,14.26,100,1,13.02,100,1,14.28,100,1,12.73,100,1,14.40,100,1,12.71,100,1,14.56,800,1,12.50,700,1,14.60,700,1,12.46,200,1,14.68,1500,1,12.43,700,1,14.69,100,1,12.42,700,1,14.72,100,1,12.37,700,1,14.89,100,1,ARL,320486925
1486,2025-07-17T15:58:14.710622495Z,2025-07-17T15:58:14.710622495Z,10,2,1108,A,A,0,15.060000000,100,130,165396,267659178,13.04,2,1,14.10,2,1,13.03,100,1,14.26,100,1,13.02,100,1,14.28,100,1,12.73,100,1,14.40,100,1,12.71,100,1,14.56,800,1,12.50,700,1,14.60,700,1,12.46,200,1,14.68,1500,1,12.43,700,1,14.69,100,1,12.42,700,1,14.72,100,1,12.37,700,1,14.89,100,1,ARL,320487357
1487,2025-07-17T15:58:15.563904700Z,2025-07-17T15:58:15.563904700Z,10,2,1108,C,A,0,14.680000000,100,0,165556,267672469,13.04,2,1,14.10,2,1,13.03,100,1,14.26,100,1,13.02,100,1,14.28,100,1,12.73,100,1,14.40,100,1,12.71,100,1,14.56,800,1,12.50,700,1,14.60,700,1,12.46,200,1,14.68,1400,1,12.43,700,1,14.69,100,1,12.42,700,1,14.72,100,1,12.37,700,1,14.89,100,1,ARL,320484781
1488,2025-07-17T15:58:15.563904700Z,2025-07-17T15:58:15.563904700Z,10,2,1108,A,A,0,14.870000000,100,130,165556,267672469,13.04,2,1,14.10,2,1,13.03,100,1,14.26,100,1,13.02,100,1,14.28,100,1,12.73,100,1,14.40,100,1,12.71,100,1,14.56,800,1,12.50,700,1,14.60,700,1,12.46,200,1,14.68,1400,1,12.43,700,1,14.69,100,1,12.42,700,1,14.72,100,1,12.37,700,1,14.87,100,1,ARL,320504473
1489,2025-07-17T15:58:15.577554368Z,2025-07-17T15:58:15.577554368Z,10,2,1108,C,A,0,14.690000000,100,0,165428,267672549,13.04,2,1,14.10,2,1,13.03,100,1,14.26,100,1,13.02,100,1,14.28,100,1,12.73,100,1,14.40,100,1,12.71,100,1,14.56,800,1,12.50,700,1,14.60,700,1,12.46,200,1,14.68,1400,1,12.43,700,1,14.72,100,1,12.42,700,1,14.87,100,1,12.37,700,1,14.89,100,1,ARL,320484825
1490,2025-07-17T15:58:15.577554368Z,2025-07-17T15:58:15.577554368Z,10,2,1108,A,A,0,14.880000000,100,130,165428,267672549,13.04,2,1,14.10,2,1,13.03,100,1,14.26,100,1,13.02,100,1,14.28,100,1,12.73,100,1,14.40,100,1,12.71,100,1,14.56,800,1,12.50,700,1,14.60,700,1,12.46,200,1,14.68,1400,1,12.43,700,1,14.72,100,1,12.42,700,1,14.87,100,1,12.37,700,1,14.88,100,1,ARL,320504609
1491,2025-07-17T15:58:16.501915292Z,2025-07-17T15:58:16.501915292Z,10,2,1108,A,A,0,14.110000000,100,130,165223,267685252,13.04,2,1,14.10,2,1,13.03,100,1,14.11,100,1,13.02,100,1,14.26,100,1,12.73,100,1,14.28,100,1,12.71,100,1,14.40,100,1,12.50,700,1,14.56,800,1,12.46,200,1,14.60,700,1,12.43,700,1,14.68,1400,1,12.42,700,1,14.72,100,1,12.37,700,1,14.87,100,1,ARL,320519893
1492,2025-07-17T15:58:19.965034325Z,2025-07-17T15:58:19.965034325Z,10,2,1108,A,A,0,13.940000000,15,130,166655,267738403,13.04,2,1,13.94,15,1,13.03,100,1,14.10,2,1,13.02,100,1,14.11,100,1,12.73,100,1,14.26,100,1,12.71,100,1,14.28,100,1,12.50,700,1,14.40,100,1,12.46,200,1,14.56,800,1,12.43,700,1,14.60,700,1,12.42,700,1,14.68,1400,1,12.37,700,1,14.72,100,1,ARL,320588689
1493,2025-07-17T15:58:20.237668047Z,2025-07-17T15:58:20.237668047Z,10,2,1108,C,A,0,14.110000000,100,0,165355,267745213,13.04,2,1,13.94,15,1,13.03,100,1,14.10,2,1,13.02,100,1,14.26,100,1,12.73,100,1,14.28,100,1,12.71,100,1,14.40,100,1,12.50,700,1,14.56,800,1,12.46,200,1,14.60,700,1,12.43,700,1,14.68,1400,1,12.42,700,1,14.72,100,1,12.37,700,1,14.87,100,1,ARL,320519893
1494,2025-07-17T15:58:20.237668047Z,2025-07-17T15:58:20.237668047Z,10,2,1108,A,A,0,13.950000000,100,130,165355,267745213,13.04,2,1,13.94,15,1,13.03,100,1,13.95,100,1,13.02,100,1,14.10,2,1,12.73,100,1,14.26,100,1,12.71,100,1,14.28,100,1,12.50,700,1,14.40,100,1,12.46,200,1,14.56,800,1,12.43,700,1,14.60,700,1,12.42,700,1,14.68,1400,1,12.37,700,1,14.72,100,1,ARL,320595817
1495,2025-07-17T15:58:20.705344578Z,2025-07-17T15:58:20.705344578Z,10,2,1108,C,A,0,13.940000000,15,128,167593,267754327,13.04,2,1,13.95,100,1,13.03,100,1,14.10,2,1,13.02,100,1,14.26,100,1,12.73,100,1,14.28,100,1,12.71,100,1,14.40,100,1,12.50,700,1,14.56,800,1,12.46,200,1,14.60,700,1,12.43,700,1,14.68,1400,1,12.42,700,1,14.72,100,1,12.37,700,1,14.87,100,1,ARL,320588689
1496,2025-07-17T15:58:30.799887713Z,2025-07-17T15:58:30.799887713Z,10,2,1108,A,A,0,13.890000000,15,130,165349,267913947,13.04,2,1,13.89,15,1,13.03,100,1,13.95,100,1,13.02,100,1,14.10,2,1,12.73,100,1,14.26,100,1,12.71,100,1,14.28,100,1,12.50,700,1,14.40,100,1,12.46,200,1,14.56,800,1,12.43,700,1,14.60,700,1,12.42,700,1,14.68,1400,1,12.37,700,1,14.72,100,1,ARL,320833897
1497,2025-07-17T15:58:30.905491759Z,2025-07-17T15:58:30.905491759Z,10,2,1108,C,A,0,13.950000000,100,0,165560,267919515,13.04,2,1,13.89,15,1,13.03,100,1,14.10,2,1,13.02,100,1,14.26,100,1,12.73,100,1,14.28,100,1,12.71,100,1,14.40,100,1,12.50,700,1,14.56,800,1,12.46,200,1,14.60,700,1,12.43,700,1,14.68,1400,1,12.42,700,1,14.72,100,1,12.37,700,1,14.87,100,1,ARL,320595817
1498,2025-07-17T15:58:30.905491759Z,2025-07-17T15:58:30.905491759Z,10,2,1108,A,A,0,13.900000000,100,130,165560,267919515,13.04,2,1,13.89,15,1,13.03,100,1,13.90,100,1,13.02,100,1,14.10,2,1,12.73,100,1,14.26,100,1,12.71,100,1,14.28,100,1,12.50,700,1,14.40,100,1,12.46,200,1,14.56,800,1,12.43,700,1,14.60,700,1,12.42,700,1,14.68,1400,1,12.37,700,1,14.72,100,1,ARL,320839125
1499,2025-07-17T15:58:30.906246950Z,2025-07-17T15:58:30.906246950Z,10,2,1108,C,A,0,15.060000000,100,0,165336,267919540,13.04,2,1,13.89,15,1,13.03,100,1,13.90,100,1,13.02,100,1,14.10,2,1,12.73,100,1,14.26,100,1,12.71,100,1,14.28,100,1,12.50,700,1,14.40,100,1,12.46,200,1,14.56,800,1,12.43,700,1,14.60,700,1,12.42,700,1,14.68,1400,1,12.37,700,1,14.72,100,1,ARL,320487357
1500,2025-07-17T15:58:30.906246950Z,2025-07-17T15:58:30.906246950Z,10,2,1108,A,A,0,14.980000000,100,130,165336,267919540,13.04,2,1,13.89,15,1,13.03,100,1,13.90,100,1,13.02,100,1,14.10,2,1,12.73,100,1,14.26,100,1,12.71,100,1,14.28,100,1,12.50,700,1,14.40,100,1,12.46,200,1,14.56,800,1,12.43,700,1,14.60,700,1,12.42,700,1,14.68,1400,1,12.37,700,1,14.72,100,1,ARL,320839149
1501,2025-07-17T15:58:30.916561264Z,2025-07-17T15:58:30.916561264Z,10,2,1108,C,A,0,14.260000000,100,130,165089,267919917,13.04,2,1,13.89,15,1,13.03,100,1,13.90,100,1,13.02,100,1,14.10,2,1,12.73,100,1,14.28,100,1,12.71,100,1,14.40,100,1,12.50,700,1,14.56,800,1,12.46,200,1,14.60,700,1,12.43,700,1,14.68,1400,1,12.42,700,1,14.72,100,1,12.37,700,1,14.87,100,1,ARL,320487025
1502,2025-07-17T15:58:30.916619122Z,2025-07-17T15:58:30.916619122Z,10,2,1108,A,A,0,14.180000000,100,130,165156,267919919,13.04,2,1,13.89,15,1,13.03,100,1,13.90,100,1,13.02,100,1,14.10,2,1,12.73,100,1,14.18,100,1,12.71,100,1,14.28,100,1,12.50,700,1,14.40,100,1,12.46,200,1,14.56,800,1,12.43,700,1,14.60,700,1,12.42,700,1,14.68,1400,1,12.37,700,1,14.72,100,1,ARL,320839577
1503,2025-07-17T15:58:31.124222733Z,2025-07-17T15:58:31.124222733Z,10,2,1108,C,A,0,14.870000000,100,0,165984,267925564,13.04,2,1,13.89,15,1,13.03,100,1,13.90,100,1,13.02,100,1,14.10,2,1,12.73,100,1,14.18,100,1,12.71,100,1,14.28,100,1,12.50,700,1,14.40,100,1,12.46,200,1,14.56,800,1,12.43,700,1,14.60,700,1,12.42,700,1,14.68,1400,1,12.37,700,1,14.72,100,1,ARL,320504473
1504,2025-07-17T15:58:31.124222733Z,2025-07-17T15:58:31.124222733Z,10,2,1108,A,A,0,14.760000000,100,130,165984,267925564,13.04,2,1,13.89,15,1,13.03,100,1,13.90,100,1,13.02,100,1,14.10,2,1,12.73,100,1,14.18,100,1,12.71,100,1,14.28,100,1,12.50,700,1,14.40,100,1,12.46,200,1,14.56,800,1,12.43,700,1,14.60,700,1,12.42,700,1,14.68,1400,1,12.37,700,1,14.72,100,1,ARL,320845893
1505,2025-07-17T15:58:31.136273403Z,2025-07-17T15:58:31.136273403Z,10,2,1108,C,A,0,14.880000000,100,0,165845,267925951,13.04,2,1,13.89,15,1,13.03,100,1,13.90,100,1,13.02,100,1,14.10,2,1,12.73,100,1,14.18,100,1,12.71,100,1,14.28,100,1,12.50,700,1,14.40,100,1,12.46,200,1,14.56,800,1,12.43,700,1,14.60,700,1,12.42,700,1,14.68,1400,1,12.37,700,1,14.72,100,1,ARL,320504609
1506,2025-07-17T15:58:31.136273403Z,2025-07-17T15:58:31.136273403Z,10,2,1108,A,A,0,14.770000000,100,130,165845,267925951,13.04,2,1,13.89,15,1,13.03,100,1,13.90,100,1,13.02,100,1,14.10,2,1,12.73,100,1,14.18,100,1,12.71,100,1,14.28,100,1,12.50,700,1,14.40,100,1,12.46,200,1,14.56,800,1,12.43,700,1,14.60,700,1,12.42,700,1,14.68,1400,1,12.37,700,1,14.72,100,1,ARL,320846429
1507,2025-07-17T15:58:40.799787018Z,2025-07-17T15:58:40.799787018Z,10,2,1108,A,A,0,13.830000000,15,130,165225,268074431,13.04,2,1,13.83,15,1,13.03,100,1,13.89,15,1,13.02,100,1,13.90,100,1,12.73,100,1,14.10,2,1,12.71,100,1,14.18,100,1,12.50,700,1,14.28,100,1,12.46,200,1,14.40,100,1,12.43,700,1,14.56,800,1,12.42,700,1,14.60,700,1,12.37,700,1,14.68,1400,1,ARL,321038033
1508,2025-07-17T15:58:43.690078924Z,2025-07-17T15:58:43.690078924Z,10,2,1108,C,A,0,13.900000000,100,0,165549,268115228,13.04,2,1,13.83,15,1,13.03,100,1,13.89,15,1,13.02,100,1,14.10,2,1,12.73,100,1,14.18,100,1,12.71,100,1,14.28,100,1,12.50,700,1,14.40,100,1,12.46,200,1,14.56,800,1,12.43,700,1,14.60,700,1,12.42,700,1,14.68,1400,1,12.37,700,1,14.72,100,1,ARL,320839125
1509,2025-07-17T15:58:43.690078924Z,2025-07-17T15:58:43.690078924Z,10,2,1108,A,A,0,13.840000000,100,130,165549,268115228,13.04,2,1,13.83,15,1,13.03,100,1,13.84,100,1,13.02,100,1,13.89,15,1,12.73,100,1,14.10,2,1,12.71,100,1,14.18,100,1,12.50,700,1,14.28,100,1,12.46,200,1,14.40,100,1,12.43,700,1,14.56,800,1,12.42,700,1,14.60,700,1,12.37,700,1,14.68,1400,1,ARL,321096769
1510,2025-07-17T15:58:43.690823184Z,2025-07-17T15:58:43.690823184Z,10,2,1108,C,A,0,14.980000000,100,0,165737,268115235,13.04,2,1,13.83,15,1,13.03,100,1,13.84,100,1,13.02,100,1,13.89,15,1,12.73,100,1,14.10,2,1,12.71,100,1,14.18,100,1,12.50,700,1,14.28,100,1,12.46,200,1,14.40,100,1,12.43,700,1,14.56,800,1,12.42,700,1,14.60,700,1,12.37,700,1,14.68,1400,1,ARL,320839149
1511,2025-07-17T15:58:43.690823184Z,2025-07-17T15:58:43.690823184Z,10,2,1108,A,A,0,14.910000000,100,130,165737,268115235,13.04,2,1,13.83,15,1,13.03,100,1,13.84,100,1,13.02,100,1,13.89,15,1,12.73,100,1,14.10,2,1,12.71,100,1,14.18,100,1,12.50,700,1,14.28,100,1,12.46,200,1,14.40,100,1,12.43,700,1,14.56,800,1,12.42,700,1,14.60,700,1,12.37,700,1,14.68,1400,1,ARL,321096793
1512,2025-07-17T15:58:43.693228946Z,2025-07-17T15:58:43.693228946Z,10,2,1108,C,A,0,17.760000000,100,0,165554,268115265,13.04,2,1,13.83,15,1,13.03,100,1,13.84,100,1,13.02,100,1,13.89,15,1,12.73,100,1,14.10,2,1,12.71,100,1,14.18,100,1,12.50,700,1,14.28,100,1,12.46,200,1,14.40,100,1,12.43,700,1,14.56,800,1,12.42,700,1,14.60,700,1,12.37,700,1,14.68,1400,1,ARL,320486937
1513,2025-07-17T15:58:43.693228946Z,2025-07-17T15:58:43.693228946Z,10,2,1108,A,A,0,17.580000000,100,130,165554,268115265,13.04,2,1,13.83,15,1,13.03,100,1,13.84,100,1,13.02,100,1,13.89,15,1,12.73,100,1,14.10,2,1,12.71,100,1,14.18,100,1,12.50,700,1,14.28,100,1,12.46,200,1,14.40,100,1,12.43,700,1,14.56,800,1,12.42,700,1,14.60,700,1,12.37,700,1,14.68,1400,1,ARL,321096825
1514,2025-07-17T15:58:43.694890264Z,2025-07-17T15:58:43.694890264Z,10,2,1108,C,A,0,16.080000000,100,0,165521,268115287,13.04,2,1,13.83,15,1,13.03,100,1,13.84,100,1,13.02,100,1,13.89,15,1,12.73,100,1,14.10,2,1,12.71,100,1,14.18,100,1,12.50,700,1,14.28,100,1,12.46,200,1,14.40,100,1,12.43,700,1,14.56,800,1,12.42,700,1,14.60,700,1,12.37,700,1,14.68,1400,1,ARL,320486945
1515,2025-07-17T15:58:43.694890264Z,2025-07-17T15:58:43.694890264Z,10,2,1108,A,A,0,15.920000000,100,130,165521,268115287,13.04,2,1,13.83,15,1,13.03,100,1,13.84,100,1,13.02,100,1,13.89,15,1,12.73,100,1,14.10,2,1,12.71,100,1,14.18,100,1,12.50,700,1,14.28,100,1,12.46,200,1,14.40,100,1,12.43,700,1,14.56,800,1,12.42,700,1,14.60,700,1,12.37,700,1,14.68,1400,1,ARL,321096889
1516,2025-07-17T15:58:43.716271172Z,2025-07-17T15:58:43.716271172Z,10,2,1108,C,A,0,14.960000000,100,0,165952,268115456,13.04,2,1,13.83,15,1,13.03,100,1,13.84,100,1,13.02,100,1,13.89,15,1,12.73,100,1,14.10,2,1,12.71,100,1,14.18,100,1,12.50,700,1,14.28,100,1,12.46,200,1,14.40,100,1,12.43,700,1,14.56,800,1,12.42,700,1,14.60,700,1,12.37,700,1,14.68,1400,1,ARL,320487105
1517,2025-07-17T15:58:43.716271172Z,2025-07-17T15:58:43.716271172Z,10,2,1108,A,A,0,14.810000000,100,130,165952,268115456,13.04,2,1,13.83,15,1,13.03,100,1,13.84,100,1,13.02,100,1,13.89,15,1,12.73,100,1,14.10,2,1,12.71,100,1,14.18,100,1,12.50,700,1,14.28,100,1,12.46,200,1,14.40,100,1,12.43,700,1,14.56,800,1,12.42,700,1,14.60,700,1,12.37,700,1,14.68,1400,1,ARL,321097197
1518,2025-07-17T15:58:44.903574654Z,2025-07-17T15:58:44.903574654Z,10,2,1108,A,A,0,13.830000000,100,130,165455,268129040,13.04,2,1,13.83,115,1,13.03,100,1,13.84,100,1,13.02,100,1,13.89,15,1,12.73,100,1,14.10,2,1,12.71,100,1,14.18,100,1,12.50,700,1,14.28,100,1,12.46,200,1,14.40,100,1,12.43,700,1,14.56,800,1,12.42,700,1,14.60,700,1,12.37,700,1,14.68,1400,1,ARL,321114473
1519,2025-07-17T15:58:44.923948853Z,2025-07-17T15:58:44.923948853Z,10,2,1108,C,A,0,14.180000000,100,130,165415,268129217,13.04,2,1,13.83,115,1,13.03,100,1,13.84,100,1,13.02,100,1,13.89,15,1,12.73,100,1,14.10,2,1,12.71,100,1,14.28,100,1,12.50,700,1,14.40,100,1,12.46,200,1,14.56,800,1,12.43,700,1,14.60,700,1,12.42,700,1,14.68,1400,1,12.37,700,1,14.72,100,1,ARL,320839577
1520,2025-07-17T15:58:44.924000519Z,2025-07-17T15:58:44.924000519Z,10,2,1108,A,A,0,14.110000000,100,130,165356,268129218,13.04,2,1,13.83,115,1,13.03,100,1,13.84,100,1,13.02,100,1,13.89,15,1,12.73,100,1,14.10,2,1,12.71,100,1,14.11,100,1,12.50,700,1,14.28,100,1,12.46,200,1,14.40,100,1,12.43,700,1,14.56,800,1,12.42,700,1,14.60,700,1,12.37,700,1,14.68,1400,1,ARL,321114729
1521,2025-07-17T15:58:51.241176997Z,2025-07-17T15:58:51.241176997Z,10,2,1108,C,A,0,13.890000000,15,130,165268,268212338,13.04,2,1,13.83,115,1,13.03,100,1,13.84,100,1,13.02,100,1,14.10,2,1,12.73,100,1,14.11,100,1,12.71,100,1,14.28,100,1,12.50,700,1,14.40,100,1,12.46,200,1,14.56,800,1,12.43,700,1,14.60,700,1,12.42,700,1,14.68,1400,1,12.37,700,1,14.72,100,1,ARL,320833897
1522,2025-07-17T15:58:51.253961905Z,2025-07-17T15:58:51.253961905Z,10,2,1108,A,A,0,13.800000000,100,130,165434,268212497,13.04,2,1,13.80,100,1,13.03,100,1,13.83,115,1,13.02,100,1,13.84,100,1,12.73,100,1,14.10,2,1,12.71,100,1,14.11,100,1,12.50,700,1,14.28,100,1,12.46,200,1,14.40,100,1,12.43,700,1,14.56,800,1,12.42,700,1,14.60,700,1,12.37,700,1,14.68,1400,1,ARL,321225725
1523,2025-07-17T15:58:51.254706004Z,2025-07-17T15:58:51.254706004Z,10,2,1108,C,A,0,14.910000000,100,0,165886,268212499,13.04,2,1,13.80,100,1,13.03,100,1,13.83,115,1,13.02,100,1,13.84,100,1,12.73,100,1,14.10,2,1,12.71,100,1,14.11,100,1,12.50,700,1,14.28,100,1,12.46,200,1,14.40,100,1,12.43,700,1,14.56,800,1,12.42,700,1,14.60,700,1,12.37,700,1,14.68,1400,1,ARL,321096793
1524,2025-07-17T15:58:51.254706004Z,2025-07-17T15:58:51.254706004Z,10,2,1108,A,A,0,14.870000000,100,130,165886,268212499,13.04,2,1,13.80,100,1,13.03,100,1,13.83,115,1,13.02,100,1,13.84,100,1,12.73,100,1,14.10,2,1,12.71,100,1,14.11,100,1,12.50,700,1,14.28,100,1,12.46,200,1,14.40,100,1,12.43,700,1,14.56,800,1,12.42,700,1,14.60,700,1,12.37,700,1,14.68,1400,1,ARL,321225745
1525,2025-07-17T15:58:51.260587778Z,2025-07-17T15:58:51.260587778Z,10,2,1108,C,A,0,13.830000000,100,130,165401,268212534,13.04,2,1,13.80,100,1,13.03,100,1,13.83,15,1,13.02,100,1,13.84,100,1,12.73,100,1,14.10,2,1,12.71,100,1,14.11,100,1,12.50,700,1,14.28,100,1,12.46,200,1,14.40,100,1,12.43,700,1,14.56,800,1,12.42,700,1,14.60,700,1,12.37,700,1,14.68,1400,1,ARL,321114473
1526,2025-07-17T15:58:53.579462029Z,2025-07-17T15:58:53.579462029Z,10,2,1108,C,A,0,13.830000000,15,130,166259,268250290,13.04,2,1,13.80,100,1,13.03,100,1,13.84,100,1,13.02,100,1,14.10,2,1,12.73,100,1,14.11,100,1,12.71,100,1,14.28,100,1,12.50,700,1,14.40,100,1,12.46,200,1,14.56,800,1,12.43,700,1,14.60,700,1,12.42,700,1,14.68,1400,1,12.37,700,1,14.72,100,1,ARL,321038033
1527,2025-07-17T15:58:53.580052014Z,2025-07-17T15:58:53.580052014Z,10,2,1108,C,A,0,13.840000000,100,0,165431,268250346,13.04,2,1,13.80,100,1,13.03,100,1,14.10,2,1,13.02,100,1,14.11,100,1,12.73,100,1,14.28,100,1,12.71,100,1,14.40,100,1,12.50,700,1,14.56,800,1,12.46,200,1,14.60,700,1,12.43,700,1,14.68,1400,1,12.42,700,1,14.72,100,1,12.37,700,1,14.76,100,1,ARL,321096769
1528,2025-07-17T15:58:53.580052014Z,2025-07-17T15:58:53.580052014Z,10,2,1108,A,A,0,13.810000000,100,130,165431,268250346,13.04,2,1,13.80,100,1,13.03,100,1,13.81,100,1,13.02,100,1,14.10,2,1,12.73,100,1,14.11,100,1,12.71,100,1,14.28,100,1,12.50,700,1,14.40,100,1,12.46,200,1,14.56,800,1,12.43,700,1,14.60,700,1,12.42,700,1,14.68,1400,1,12.37,700,1,14.72,100,1,ARL,321272581
1529,2025-07-17T15:58:54.583958582Z,2025-07-17T15:58:54.583958582Z,10,2,1108,C,A,0,14.770000000,100,0,165633,268265585,13.04,2,1,13.80,100,1,13.03,100,1,13.81,100,1,13.02,100,1,14.10,2,1,12.73,100,1,14.11,100,1,12.71,100,1,14.28,100,1,12.50,700,1,14.40,100,1,12.46,200,1,14.56,800,1,12.43,700,1,14.60,700,1,12.42,700,1,14.68,1400,1,12.37,700,1,14.72,100,1,ARL,320846429
1530,2025-07-17T15:58:54.583958582Z,2025-07-17T15:58:54.583958582Z,10,2,1108,A,A,0,14.650000000,100,130,165633,268265585,13.04,2,1,13.80,100,1,13.03,100,1,13.81,100,1,13.02,100,1,14.10,2,1,12.73,100,1,14.11,100,1,12.71,100,1,14.28,100,1,12.50,700,1,14.40,100,1,12.46,200,1,14.56,800,1,12.43,700,1,14.60,700,1,12.42,700,1,14.65,100,1,12.37,700,1,14.68,1400,1,ARL,321293737
1531,2025-07-17T15:58:54.584094980Z,2025-07-17T15:58:54.584094980Z,10,2,1108,C,A,0,14.760000000,100,0,165732,268265586,13.04,2,1,13.80,100,1,13.03,100,1,13.81,100,1,13.02,100,1,14.10,2,1,12.73,100,1,14.11,100,1,12.71,100,1,14.28,100,1,12.50,700,1,14.40,100,1,12.46,200,1,14.56,800,1,12.43,700,1,14.60,700,1,12.42,700,1,14.65,100,1,12.37,700,1,14.68,1400,1,ARL,320845893
1532,2025-07-17T15:58:54.584094980Z,2025-07-17T15:58:54.584094980Z,10,2,1108,A,A,0,14.640000000,100,130,165732,268265586,13.04,2,1,13.80,100,1,13.03,100,1,13.81,100,1,13.02,100,1,14.10,2,1,12.73,100,1,14.11,100,1,12.71,100,1,14.28,100,1,12.50,700,1,14.40,100,1,12.46,200,1,14.56,800,1,12.43,700,1,14.60,700,1,12.42,700,1,14.64,100,1,12.37,700,1,14.65,100,1,ARL,321293741
1533,2025-07-17T15:58:55.304938318Z,2025-07-17T15:58:55.304938318Z,10,2,1108,A,A,0,13.780000000,100,130,165711,268277940,13.04,2,1,13.78,100,1,13.03,100,1,13.80,100,1,13.02,100,1,13.81,100,1,12.73,100,1,14.10,2,1,12.71,100,1,14.11,100,1,12.50,700,1,14.28,100,1,12.46,200,1,14.40,100,1,12.43,700,1,14.56,800,1,12.42,700,1,14.60,700,1,12.37,700,1,14.64,100,1,ARL,321309865
1534,2025-07-17T15:58:55.307342971Z,2025-07-17T15:58:55.307342971Z,10,2,1108,C,A,0,14.720000000,100,130,165334,268277999,13.04,2,1,13.78,100,1,13.03,100,1,13.80,100,1,13.02,100,1,13.81,100,1,12.73,100,1,14.10,2,1,12.71,100,1,14.11,100,1,12.50,700,1,14.28,100,1,12.46,200,1,14.40,100,1,12.43,700,1,14.56,800,1,12.42,700,1,14.60,700,1,12.37,700,1,14.64,100,1,ARL,312772061
1535,2025-07-17T15:58:55.307472032Z,2025-07-17T15:58:55.307472032Z,10,2,1108,A,A,0,14.580000000,100,130,165177,268278004,13.04,2,1,13.78,100,1,13.03,100,1,13.80,100,1,13.02,100,1,13.81,100,1,12.73,100,1,14.10,2,1,12.71,100,1,14.11,100,1,12.50,700,1,14.28,100,1,12.46,200,1,14.40,100,1,12.43,700,1,14.56,800,1,12.42,700,1,14.58,100,1,12.37,700,1,14.60,700,1,ARL,321309941
1536,2025-07-17T15:58:55.311734700Z,2025-07-17T15:58:55.311734700Z,10,2,1108,C,A,0,13.800000000,100,130,165265,268278030,13.04,2,1,13.78,100,1,13.03,100,1,13.81,100,1,13.02,100,1,14.10,2,1,12.73,100,1,14.11,100,1,12.71,100,1,14.28,100,1,12.50,700,1,14.40,100,1,12.46,200,1,14.56,800,1,12.43,700,1,14.58,100,1,12.42,700,1,14.60,700,1,12.37,700,1,14.64,100,1,ARL,321225725
1537,2025-07-17T15:58:58.668086788Z,2025-07-17T15:58:58.668086788Z,10,2,1108,C,A,0,13.810000000,100,0,165518,268321684,13.04,2,1,13.78,100,1,13.03,100,1,14.10,2,1,13.02,100,1,14.11,100,1,12.73,100,1,14.28,100,1,12.71,100,1,14.40,100,1,12.50,700,1,14.56,800,1,12.46,200,1,14.58,100,1,12.43,700,1,14.60,700,1,12.42,700,1,14.64,100,1,12.37,700,1,14.65,100,1,ARL,321272581
1538,2025-07-17T15:58:58.668086788Z,2025-07-17T15:58:58.668086788Z,10,2,1108,A,A,0,13.790000000,100,130,165518,268321684,13.04,2,1,13.78,100,1,13.03,100,1,13.79,100,1,13.02,100,1,14.10,2,1,12.73,100,1,14.11,100,1,12.71,100,1,14.28,100,1,12.50,700,1,14.40,100,1,12.46,200,1,14.56,800,1,12.43,700,1,14.58,100,1,12.42,700,1,14.60,700,1,12.37,700,1,14.64,100,1,ARL,321364281
1539,2025-07-17T15:59:03.613527621Z,2025-07-17T15:59:03.613527621Z,10,2,1108,A,A,0,13.720000000,15,130,165292,268437919,13.04,2,1,13.72,15,1,13.03,100,1,13.78,100,1,13.02,100,1,13.79,100,1,12.73,100,1,14.10,2,1,12.71,100,1,14.11,100,1,12.50,700,1,14.28,100,1,12.46,200,1,14.40,100,1,12.43,700,1,14.56,800,1,12.42,700,1,14.58,100,1,12.37,700,1,14.60,700,1,ARL,321500117
1540,2025-07-17T15:59:03.626181384Z,2025-07-17T15:59:03.626181384Z,10,2,1108,A,A,0,13.760000000,100,130,165232,268438110,13.04,2,1,13.72,15,1,13.03,100,1,13.76,100,1,13.02,100,1,13.78,100,1,12.73,100,1,13.79,100,1,12.71,100,1,14.10,2,1,12.50,700,1,14.11,100,1,12.46,200,1,14.28,100,1,12.43,700,1,14.40,100,1,12.42,700,1,14.56,800,1,12.37,700,1,14.58,100,1,ARL,321500317
1541,2025-07-17T15:59:03.626920954Z,2025-07-17T15:59:03.626920954Z,10,2,1108,C,A,0,14.870000000,100,0,165934,268438112,13.04,2,1,13.72,15,1,13.03,100,1,13.76,100,1,13.02,100,1,13.78,100,1,12.73,100,1,13.79,100,1,12.71,100,1,14.10,2,1,12.50,700,1,14.11,100,1,12.46,200,1,14.28,100,1,12.43,700,1,14.40,100,1,12.42,700,1,14.56,800,1,12.37,700,1,14.58,100,1,ARL,321225745
1542,2025-07-17T15:59:03.626920954Z,2025-07-17T15:59:03.626920954Z,10,2,1108,A,A,0,14.830000000,100,130,165934,268438112,13.04,2,1,13.72,15,1,13.03,100,1,13.76,100,1,13.02,100,1,13.78,100,1,12.73,100,1,13.79,100,1,12.71,100,1,14.10,2,1,12.50,700,1,14.11,100,1,12.46,200,1,14.28,100,1,12.43,700,1,14.40,100,1,12.42,700,1,14.56,800,1,12.37,700,1,14.58,100,1,ARL,321500333
1543,2025-07-17T15:59:03.628779364Z,2025-07-17T15:59:03.628779364Z,10,2,1108,C,A,0,14.890000000,100,0,165914,268438129,13.04,2,1,13.72,15,1,13.03,100,1,13.76,100,1,13.02,100,1,13.78,100,1,12.73,100,1,13.79,100,1,12.71,100,1,14.10,2,1,12.50,700,1,14.11,100,1,12.46,200,1,14.28,100,1,12.43,700,1,14.40,100,1,12.42,700,1,14.56,800,1,12.37,700,1,14.58,100,1,ARL,312771785
1544,2025-07-17T15:59:03.628779364Z,2025-07-17T15:59:03.628779364Z,10,2,1108,A,A,0,14.730000000,100,130,165914,268438129,13.04,2,1,13.72,15,1,13.03,100,1,13.76,100,1,13.02,100,1,13.78,100,1,12.73,100,1,13.79,100,1,12.71,100,1,14.10,2,1,12.50,700,1,14.11,100,1,12.46,200,1,14.28,100,1,12.43,700,1,14.40,100,1,12.42,700,1,14.56,800,1,12.37,700,1,14.58,100,1,ARL,321500349
1545,2025-07-17T15:59:03.632928023Z,2025-07-17T15:59:03.632928023Z,10,2,1108,C,A,0,13.780000000,100,130,165235,268438149,13.04,2,1,13.72,15,1,13.03,100,1,13.76,100,1,13.02,100,1,13.79,100,1,12.73,100,1,14.10,2,1,12.71,100,1,14.11,100,1,12.50,700,1,14.28,100,1,12.46,200,1,14.40,100,1,12.43,700,1,14.56,800,1,12.42,700,1,14.58,100,1,12.37,700,1,14.60,700,1,ARL,321309865
1546,2025-07-17T15:59:03.649116452Z,2025-07-17T15:59:03.649116452Z,10,2,1108,C,A,0,14.110000000,100,130,165611,268438330,13.04,2,1,13.72,15,1,13.03,100,1,13.76,100,1,13.02,100,1,13.79,100,1,12.73,100,1,14.10,2,1,12.71,100,1,14.28,100,1,12.50,700,1,14.40,100,1,12.46,200,1,14.56,800,1,12.43,700,1,14.58,100,1,12.42,700,1,14.60,700,1,12.37,700,1,14.64,100,1,ARL,321114729
1547,2025-07-17T15:59:03.649167617Z,2025-07-17T15:59:03.649167617Z,10,2,1108,A,A,0,14.040000000,100,130,165256,268438331,13.04,2,1,13.72,15,1,13.03,100,1,13.76,100,1,13.02,100,1,13.79,100,1,12.73,100,1,14.04,100,1,12.71,100,1,14.10,2,1,12.50,700,1,14.28,100,1,12.46,200,1,14.40,100,1,12.43,700,1,14.56,800,1,12.42,700,1,14.58,100,1,12.37,700,1,14.60,700,1,ARL,321500957
1548,2025-07-17T15:59:04.223835151Z,2025-07-17T15:59:04.223835151Z,10,2,1108,C,A,0,13.790000000,100,0,165654,268447989,13.04,2,1,13.72,15,1,13.03,100,1,13.76,100,1,13.02,100,1,14.04,100,1,12.73,100,1,14.10,2,1,12.71,100,1,14.28,100,1,12.50,700,1,14.40,100,1,12.46,200,1,14.56,800,1,12.43,700,1,14.58,100,1,12.42,700,1,14.60,700,1,12.37,700,1,14.64,100,1,ARL,321364281
1549,2025-07-17T15:59:04.223835151Z,2025-07-17T15:59:04.223835151Z,10,2,1108,A,A,0,13.730000000,100,130,165654,268447989,13.04,2,1,13.72,15,1,13.03,100,1,13.73,100,1,13.02,100,1,13.76,100,1,12.73,100,1,14.04,100,1,12.71,100,1,14.10,2,1,12.50,700,1,14.28,100,1,12.46,200,1,14.40,100,1,12.43,700,1,14.56,800,1,12.42,700,1,14.58,100,1,12.37,700,1,14.60,700,1,ARL,321511377
1550,2025-07-17T15:59:04.224583946Z,2025-07-17T15:59:04.224583946Z,10,2,1108,C,A,0,14.830000000,100,0,165387,268448014,13.04,2,1,13.72,15,1,13.03,100,1,13.73,100,1,13.02,100,1,13.76,100,1,12.73,100,1,14.04,100,1,12.71,100,1,14.10,2,1,12.50,700,1,14.28,100,1,12.46,200,1,14.40,100,1,12.43,700,1,14.56,800,1,12.42,700,1,14.58,100,1,12.37,700,1,14.60,700,1,ARL,321500333
1551,2025-07-17T15:59:04.224583946Z,2025-07-17T15:59:04.224583946Z,10,2,1108,A,A,0,14.790000000,100,130,165387,268448014,13.04,2,1,13.72,15,1,13.03,100,1,13.73,100,1,13.02,100,1,13.76,100,1,12.73,100,1,14.04,100,1,12.71,100,1,14.10,2,1,12.50,700,1,14.28,100,1,12.46,200,1,14.40,100,1,12.43,700,1,14.56,800,1,12.42,700,1,14.58,100,1,12.37,700,1,14.60,700,1,ARL,321511477
1552,2025-07-17T15:59:04.799833206Z,2025-07-17T15:59:04.799833206Z,10,2,1108,C,A,0,13.720000000,15,130,165436,268457531,13.04,2,1,13.73,100,1,13.03,100,1,13.76,100,1,13.02,100,1,14.04,100,1,12.73,100,1,14.10,2,1,12.71,100,1,14.28,100,1,12.50,700,1,14.40,100,1,12.46,200,1,14.56,800,1,12.43,700,1,14.58,100,1,12.42,700,1,14.60,700,1,12.37,700,1,14.64,100,1,ARL,321500117
1553,2025-07-17T16:00:13.989771852Z,2025-07-17T16:00:13.989771852Z,10,2,1108,C,A,0,14.100000000,2,0,165562,269514876,13.04,2,1,13.73,100,1,13.03,100,1,13.76,100,1,13.02,100,1,14.04,100,1,12.73,100,1,14.28,100,1,12.71,100,1,14.40,100,1,12.50,700,1,14.56,800,1,12.46,200,1,14.58,100,1,12.43,700,1,14.60,700,1,12.42,700,1,14.64,100,1,12.37,700,1,14.65,100,1,ARL,316098525
1554,2025-07-17T16:00:13.989771852Z,2025-07-17T16:00:13.989771852Z,10,2,1108,A,A,0,14.010000000,2,130,165562,269514876,13.04,2,1,13.73,100,1,13.03,100,1,13.76,100,1,13.02,100,1,14.01,2,1,12.73,100,1,14.04,100,1,12.71,100,1,14.28,100,1,12.50,700,1,14.40,100,1,12.46,200,1,14.56,800,1,12.43,700,1,14.58,100,1,12.42,700,1,14.60,700,1,12.37,700,1,14.64,100,1,ARL,322898193
1555,2025-07-17T16:00:28.802849928Z,2025-07-17T16:00:28.802849928Z,10,2,1108,A,A,0,13.720000000,15,130,166002,269765653,13.04,2,1,13.72,15,1,13.03,100,1,13.73,100,1,13.02,100,1,13.76,100,1,12.73,100,1,14.01,2,1,12.71,100,1,14.04,100,1,12.50,700,1,14.28,100,1,12.46,200,1,14.40,100,1,12.43,700,1,14.56,800,1,12.42,700,1,14.58,100,1,12.37,700,1,14.60,700,1,ARL,323238809
1556,2025-07-17T16:00:32.549247168Z,2025-07-17T16:00:32.549247168Z,10,2,1108,A,A,0,13.740000000,100,130,165448,269878282,13.04,2,1,13.72,15,1,13.03,100,1,13.73,100,1,13.02,100,1,13.74,100,1,12.73,100,1,13.76,100,1,12.71,100,1,14.01,2,1,12.50,700,1,14.04,100,1,12.46,200,1,14.28,100,1,12.43,700,1,14.40,100,1,12.42,700,1,14.56,800,1,12.37,700,1,14.58,100,1,ARL,323370569
1557,2025-07-17T16:00:32.560823786Z,2025-07-17T16:00:32.560823786Z,10,2,1108,C,A,0,13.760000000,100,130,165307,269878639,13.04,2,1,13.72,15,1,13.03,100,1,13.73,100,1,13.02,100,1,13.74,100,1,12.73,100,1,14.01,2,1,12.71,100,1,14.04,100,1,12.50,700,1,14.28,100,1,12.46,200,1,14.40,100,1,12.43,700,1,14.56,800,1,12.42,700,1,14.58,100,1,12.37,700,1,14.60,700,1,ARL,321500317
1558,2025-07-17T16:00:35.512999155Z,2025-07-17T16:00:35.512999155Z,10,2,1108,A,A,0,13.690000000,15,130,165303,269940539,13.04,2,1,13.69,15,1,13.03,100,1,13.72,15,1,13.02,100,1,13.73,100,1,12.73,100,1,13.74,100,1,12.71,100,1,14.01,2,1,12.50,700,1,14.04,100,1,12.46,200,1,14.28,100,1,12.43,700,1,14.40,100,1,12.42,700,1,14.56,800,1,12.37,700,1,14.58,100,1,ARL,323455221
1559,2025-07-17T16:00:42.614063415Z,2025-07-17T16:00:42.614063415Z,10,2,1108,C,A,0,13.730000000,100,0,165769,270051089,13.04,2,1,13.69,15,1,13.03,100,1,13.72,15,1,13.02,100,1,13.74,100,1,12.73,100,1,14.01,2,1,12.71,100,1,14.04,100,1,12.50,700,1,14.28,100,1,12.46,200,1,14.40,100,1,12.43,700,1,14.56,800,1,12.42,700,1,14.58,100,1,12.37,700,1,14.60,700,1,ARL,321511377
1560,2025-07-17T16:00:42.614063415Z,2025-07-17T16:00:42.614063415Z,10,2,1108,A,A,0,13.700000000,100,130,165769,270051089,13.04,2,1,13.69,15,1,13.03,100,1,13.70,100,1,13.02,100,1,13.72,15,1,12.73,100,1,13.74,100,1,12.71,100,1,14.01,2,1,12.50,700,1,14.04,100,1,12.46,200,1,14.28,100,1,12.43,700,1,14.40,100,1,12.42,700,1,14.56,800,1,12.37,700,1,14.58,100,1,ARL,323599605
1561,2025-07-17T16:00:42.614088947Z,2025-07-17T16:00:42.614088947Z,10,2,1108,A,A,0,13.720000000,100,130,165252,270051090,13.04,2,1,13.69,15,1,13.03,100,1,13.70,100,1,13.02,100,1,13.72,115,1,12.73,100,1,13.74,100,1,12.71,100,1,14.01,2,1,12.50,700,1,14.04,100,1,12.46,200,1,14.28,100,1,12.43,700,1,14.40,100,1,12.42,700,1,14.56,800,1,12.37,700,1,14.58,100,1,ARL,323599609
1562,2025-07-17T16:00:42.614231125Z,2025-07-17T16:00:42.614231125Z,10,2,1108,C,A,0,13.740000000,100,130,165089,270051092,13.04,2,1,13.69,15,1,13.03,100,1,13.70,100,1,13.02,100,1,13.72,115,1,12.73,100,1,14.01,2,1,12.71,100,1,14.04,100,1,12.50,700,1,14.28,100,1,12.46,200,1,14.40,100,1,12.43,700,1,14.56,800,1,12.42,700,1,14.58,100,1,12.37,700,1,14.60,700,1,ARL,323370569
1563,2025-07-17T16:00:42.616013371Z,2025-07-17T16:00:42.616013371Z,10,2,1108,C,A,0,14.810000000,100,0,165591,270051093,13.04,2,1,13.69,15,1,13.03,100,1,13.70,100,1,13.02,100,1,13.72,115,1,12.73,100,1,14.01,2,1,12.71,100,1,14.04,100,1,12.50,700,1,14.28,100,1,12.46,200,1,14.40,100,1,12.43,700,1,14.56,800,1,12.42,700,1,14.58,100,1,12.37,700,1,14.60,700,1,ARL,321097197
1564,2025-07-17T16:00:42.616013371Z,2025-07-17T16:00:42.616013371Z,10,2,1108,A,A,0,14.660000000,100,130,165591,270051093,13.04,2,1,13.69,15,1,13.03,100,1,13.70,100,1,13.02,100,1,13.72,115,1,12.73,100,1,14.01,2,1,12.71,100,1,14.04,100,1,12.50,700,1,14.28,100,1,12.46,200,1,14.40,100,1,12.43,700,1,14.56,800,1,12.42,700,1,14.58,100,1,12.37,700,1,14.60,700,1,ARL,323599625
1565,2025-07-17T16:00:42.616156310Z,2025-07-17T16:00:42.616156310Z,10,2,1108,C,A,0,15.920000000,100,0,165569,270051094,13.04,2,1,13.69,15,1,13.03,100,1,13.70,100,1,13.02,100,1,13.72,115,1,12.73,100,1,14.01,2,1,12.71,100,1,14.04,100,1,12.50,700,1,14.28,100,1,12.46,200,1,14.40,100,1,12.43,700,1,14.56,800,1,12.42,700,1,14.58,100,1,12.37,700,1,14.60,700,1,ARL,321096889
1566,2025-07-17T16:00:42.616156310Z,2025-07-17T16:00:42.616156310Z,10,2,1108,A,A,0,15.760000000,100,130,165569,270051094,13.04,2,1,13.69,15,1,13.03,100,1,13.70,100,1,13.02,100,1,13.72,115,1,12.73,100,1,14.01,2,1,12.71,100,1,14.04,100,1,12.50,700,1,14.28,100,1,12.46,200,1,14.40,100,1,12.43,700,1,14.56,800,1,12.42,700,1,14.58,100,1,12.37,700,1,14.60,700,1,ARL,323599629
1567,2025-07-17T16:00:42.616186901Z,2025-07-17T16:00:42.616186901Z,10,2,1108,C,A,0,17.580000000,100,0,165346,270051095,13.04,2,1,13.69,15,1,13.03,100,1,13.70,100,1,13.02,100,1,13.72,115,1,12.73,100,1,14.01,2,1,12.71,100,1,14.04,100,1,12.50,700,1,14.28,100,1,12.46,200,1,14.40,100,1,12.43,700,1,14.56,800,1,12.42,700,1,14.58,100,1,12.37,700,1,14.60,700,1,ARL,321096825
1568,2025-07-17T16:00:42.616186901Z,2025-07-17T16:00:42.616186901Z,10,2,1108,A,A,0,17.400000000,100,130,165346,270051095,13.04,2,1,13.69,15,1,13.03,100,1,13.70,100,1,13.02,100,1,13.72,115,1,12.73,100,1,14.01,2,1,12.71,100,1,14.04,100,1,12.50,700,1,14.28,100,1,12.46,200,1,14.40,100,1,12.43,700,1,14.56,800,1,12.42,700,1,14.58,100,1,12.37,700,1,14.60,700,1,ARL,323599633
1569,2025-07-17T16:00:42.636595817Z,2025-07-17T16:00:42.636595817Z,10,2,1108,C,A,0,14.040000000,100,130,165359,270051179,13.04,2,1,13.69,15,1,13.03,100,1,13.70,100,1,13.02,100,1,13.72,115,1,12.73,100,1,14.01,2,1,12.71,100,1,14.28,100,1,12.50,700,1,14.40,100,1,12.46,200,1,14.56,800,1,12.43,700,1,14.58,100,1,12.42,700,1,14.60,700,1,12.37,700,1,14.64,100,1,ARL,321500957
1570,2025-07-17T16:00:42.636649389Z,2025-07-17T16:00:42.636649389Z,10,2,1108,A,A,0,13.970000000,100,130,165315,270051181,13.04,2,1,13.69,15,1,13.03,100,1,13.70,100,1,13.02,100,1,13.72,115,1,12.73,100,1,13.97,100,1,12.71,100,1,14.01,2,1,12.50,700,1,14.28,100,1,12.46,200,1,14.40,100,1,12.43,700,1,14.56,800,1,12.42,700,1,14.58,100,1,12.37,700,1,14.60,700,1,ARL,323599765
1571,2025-07-17T16:00:46.803097192Z,2025-07-17T16:00:46.803097192Z,10,2,1108,C,A,0,13.720000000,15,130,165268,270102799,13.04,2,1,13.69,15,1,13.03,100,1,13.70,100,1,13.02,100,1,13.72,100,1,12.73,100,1,13.97,100,1,12.71,100,1,14.01,2,1,12.50,700,1,14.28,100,1,12.46,200,1,14.40,100,1,12.43,700,1,14.56,800,1,12.42,700,1,14.58,100,1,12.37,700,1,14.60,700,1,ARL,323238809
1572,2025-07-17T16:00:49.255465939Z,2025-07-17T16:00:49.255465939Z,10,2,1108,A,A,0,13.660000000,15,130,165325,270140405,13.04,2,1,13.66,15,1,13.03,100,1,13.69,15,1,13.02,100,1,13.70,100,1,12.73,100,1,13.72,100,1,12.71,100,1,13.97,100,1,12.50,700,1,14.01,2,1,12.46,200,1,14.28,100,1,12.43,700,1,14.40,100,1,12.42,700,1,14.56,800,1,12.37,700,1,14.58,100,1,ARL,323720189
1573,2025-07-17T16:00:49.739479408Z,2025-07-17T16:00:49.739479408Z,10,2,1108,A,A,0,13.700000000,100,130,165196,270146528,13.04,2,1,13.66,15,1,13.03,100,1,13.69,15,1,13.02,100,1,13.70,200,1,12.73,100,1,13.72,100,1,12.71,100,1,13.97,100,1,12.50,700,1,14.01,2,1,12.46,200,1,14.28,100,1,12.43,700,1,14.40,100,1,12.42,700,1,14.56,800,1,12.37,700,1,14.58,100,1,ARL,323730309
1574,2025-07-17T16:00:49.744872763Z,2025-07-17T16:00:49.744872763Z,10,2,1108,C,A,0,13.700000000,100,0,165498,270146577,13.04,2,1,13.66,15,1,13.03,100,1,13.69,15,1,13.02,100,1,13.70,100,1,12.73,100,1,13.72,100,1,12.71,100,1,13.97,100,1,12.50,700,1,14.01,2,1,12.46,200,1,14.28,100,1,12.43,700,1,14.40,100,1,12.42,700,1,14.56,800,1,12.37,700,1,14.58,100,1,ARL,323599605
1575,2025-07-17T16:00:49.744872763Z,2025-07-17T16:00:49.744872763Z,10,2,1108,A,A,0,13.670000000,100,130,165498,270146577,13.04,2,1,13.66,15,1,13.03,100,1,13.67,100,1,13.02,100,1,13.69,15,1,12.73,100,1,13.70,100,1,12.71,100,1,13.72,100,1,12.50,700,1,13.97,100,1,12.46,200,1,14.01,2,1,12.43,700,1,14.28,100,1,12.42,700,1,14.40,100,1,12.37,700,1,14.56,800,1,ARL,323730353
1576,2025-07-17T16:00:49.745613051Z,2025-07-17T16:00:49.745613051Z,10,2,1108,C,A,0,14.790000000,100,0,165674,270146581,13.04,2,1,13.66,15,1,13.03,100,1,13.67,100,1,13.02,100,1,13.69,15,1,12.73,100,1,13.70,100,1,12.71,100,1,13.72,100,1,12.50,700,1,13.97,100,1,12.46,200,1,14.01,2,1,12.43,700,1,14.28,100,1,12.42,700,1,14.40,100,1,12.37,700,1,14.56,800,1,ARL,321511477
1577,2025-07-17T16:00:49.745613051Z,2025-07-17T16:00:49.745613051Z,10,2,1108,A,A,0,14.730000000,100,130,165674,270146581,13.04,2,1,13.66,15,1,13.03,100,1,13.67,100,1,13.02,100,1,13.69,15,1,12.73,100,1,13.70,100,1,12.71,100,1,13.72,100,1,12.50,700,1,13.97,100,1,12.46,200,1,14.01,2,1,12.43,700,1,14.28,100,1,12.42,700,1,14.40,100,1,12.37,700,1,14.56,800,1,ARL,323730369
1578,2025-07-17T16:00:49.746256906Z,2025-07-17T16:00:49.746256906Z,10,2,1108,C,A,0,13.720000000,100,130,165236,270146586,13.04,2,1,13.66,15,1,13.03,100,1,13.67,100,1,13.02,100,1,13.69,15,1,12.73,100,1,13.70,100,1,12.71,100,1,13.97,100,1,12.50,700,1,14.01,2,1,12.46,200,1,14.28,100,1,12.43,700,1,14.40,100,1,12.42,700,1,14.56,800,1,12.37,700,1,14.58,100,1,ARL,323599609
1579,2025-07-17T16:00:49.772466772Z,2025-07-17T16:00:49.772466772Z,10,2,1108,A,A,0,15.590000000,100,130,165195,270146838,13.04,2,1,13.66,15,1,13.03,100,1,13.67,100,1,13.02,100,1,13.69,15,1,12.73,100,1,13.70,100,1,12.71,100,1,13.97,100,1,12.50,700,1,14.01,2,1,12.46,200,1,14.28,100,1,12.43,700,1,14.40,100,1,12.42,700,1,14.56,800,1,12.37,700,1,14.58,100,1,ARL,323730697
1580,2025-07-17T16:00:49.772479921Z,2025-07-17T16:00:49.772479921Z,10,2,1108,C,A,0,15.860000000,100,130,165382,270146839,13.04,2,1,13.66,15,1,13.03,100,1,13.67,100,1,13.02,100,1,13.69,15,1,12.73,100,1,13.70,100,1,12.71,100,1,13.97,100,1,12.50,700,1,14.01,2,1,12.46,200,1,14.28,100,1,12.43,700,1,14.40,100,1,12.42,700,1,14.56,800,1,12.37,700,1,14.58,100,1,ARL,312771645
1581,2025-07-17T16:00:51.624646272Z,2025-07-17T16:00:51.624646272Z,10,2,1108,C,A,0,14.650000000,100,0,165617,270181394,13.04,2,1,13.66,15,1,13.03,100,1,13.67,100,1,13.02,100,1,13.69,15,1,12.73,100,1,13.70,100,1,12.71,100,1,13.97,100,1,12.50,700,1,14.01,2,1,12.46,200,1,14.28,100,1,12.43,700,1,14.40,100,1,12.42,700,1,14.56,800,1,12.37,700,1,14.58,100,1,ARL,321293737
1582,2025-07-17T16:00:51.624646272Z,2025-07-17T16:00:51.624646272Z,10,2,1108,A,A,0,14.540000000,100,130,165617,270181394,13.04,2,1,13.66,15,1,13.03,100,1,13.67,100,1,13.02,100,1,13.69,15,1,12.73,100,1,13.70,100,1,12.71,100,1,13.97,100,1,12.50,700,1,14.01,2,1,12.46,200,1,14.28,100,1,12.43,700,1,14.40,100,1,12.42,700,1,14.54,100,1,12.37,700,1,14.56,800,1,ARL,323775433
1583,2025-07-17T16:00:51.625206675Z,2025-07-17T16:00:51.625206675Z,10,2,1108,C,A,0,14.640000000,100,0,165841,270181399,13.04,2,1,13.66,15,1,13.03,100,1,13.67,100,1,13.02,100,1,13.69,15,1,12.73,100,1,13.70,100,1,12.71,100,1,13.97,100,1,12.50,700,1,14.01,2,1,12.46,200,1,14.28,100,1,12.43,700,1,14.40,100,1,12.42,700,1,14.54,100,1,12.37,700,1,14.56,800,1,ARL,321293741
1584,2025-07-17T16:00:51.625206675Z,2025-07-17T16:00:51.625206675Z,10,2,1108,A,A,0,14.530000000,100,130,165841,270181399,13.04,2,1,13.66,15,1,13.03,100,1,13.67,100,1,13.02,100,1,13.69,15,1,12.73,100,1,13.70,100,1,12.71,100,1,13.97,100,1,12.50,700,1,14.01,2,1,12.46,200,1,14.28,100,1,12.43,700,1,14.40,100,1,12.42,700,1,14.53,100,1,12.37,700,1,14.54,100,1,ARL,323775457
1585,2025-07-17T16:00:53.749169565Z,2025-07-17T16:00:53.749169565Z,10,2,1108,A,A,0,13.670000000,100,130,165445,270204567,13.04,2,1,13.66,15,1,13.03,100,1,13.67,200,1,13.02,100,1,13.69,15,1,12.73,100,1,13.70,100,1,12.71,100,1,13.97,100,1,12.50,700,1,14.01,2,1,12.46,200,1,14.28,100,1,12.43,700,1,14.40,100,1,12.42,700,1,14.53,100,1,12.37,700,1,14.54,100,1,ARL,323803301
1586,2025-07-17T16:00:53.755801462Z,2025-07-17T16:00:53.755801462Z,10,2,1108,C,A,0,13.700000000,100,130,165218,270204616,13.04,2,1,13.66,15,1,13.03,100,1,13.67,200,1,13.02,100,1,13.69,15,1,12.73,100,1,13.97,100,1,12.71,100,1,14.01,2,1,12.50,700,1,14.28,100,1,12.46,200,1,14.40,100,1,12.43,700,1,14.53,100,1,12.42,700,1,14.54,100,1,12.37,700,1,14.56,800,1,ARL,323730309
1587,2025-07-17T16:01:00.801177403Z,2025-07-17T16:01:00.801177403Z,10,2,1108,C,A,0,13.690000000,15,130,165336,270319932,13.04,2,1,13.66,15,1,13.03,100,1,13.67,200,1,13.02,100,1,13.97,100,1,12.73,100,1,14.01,2,1,12.71,100,1,14.28,100,1,12.50,700,1,14.40,100,1,12.46,200,1,14.53,100,1,12.43,700,1,14.54,100,1,12.42,700,1,14.56,800,1,12.37,700,1,14.58,100,1,ARL,323455221
1588,2025-07-17T16:01:10.802712247Z,2025-07-17T16:01:10.802712247Z,10,2,1108,A,A,0,13.620000000,15,130,165323,270493149,13.04,2,1,13.62,15,1,13.03,100,1,13.66,15,1,13.02,100,1,13.67,200,1,12.73,100,1,13.97,100,1,12.71,100,1,14.01,2,1,12.50,700,1,14.28,100,1,12.46,200,1,14.40,100,1,12.43,700,1,14.53,100,1,12.42,700,1,14.54,100,1,12.37,700,1,14.56,800,1,ARL,324161541
1589,2025-07-17T16:01:11.418671671Z,2025-07-17T16:01:11.418671671Z,10,2,1108,A,A,0,13.650000000,100,130,165801,270503944,13.04,2,1,13.62,15,1,13.03,100,1,13.65,100,1,13.02,100,1,13.66,15,1,12.73,100,1,13.67,200,1,12.71,100,1,13.97,100,1,12.50,700,1,14.01,2,1,12.46,200,1,14.28,100,1,12.43,700,1,14.40,100,1,12.42,700,1,14.53,100,1,12.37,700,1,14.54,100,1,ARL,324175569
1590,2025-07-17T16:01:11.425757014Z,2025-07-17T16:01:11.425757014Z,10,2,1108,C,A,0,13.670000000,100,130,165170,270504009,13.04,2,1,13.62,15,1,13.03,100,1,13.65,100,1,13.02,100,1,13.66,15,1,12.73,100,1,13.67,100,1,12.71,100,1,13.97,100,1,12.50,700,1,14.01,2,1,12.46,200,1,14.28,100,1,12.43,700,1,14.40,100,1,12.42,700,1,14.53,100,1,12.37,700,1,14.54,100,1,ARL,323803301
1591,2025-07-17T16:01:11.820588141Z,2025-07-17T16:01:11.820588141Z,10,2,1108,C,A,0,13.670000000,100,0,165475,270509970,13.04,2,1,13.62,15,1,13.03,100,1,13.65,100,1,13.02,100,1,13.66,15,1,12.73,100,1,13.97,100,1,12.71,100,1,14.01,2,1,12.50,700,1,14.28,100,1,12.46,200,1,14.40,100,1,12.43,700,1,14.53,100,1,12.42,700,1,14.54,100,1,12.37,700,1,14.56,800,1,ARL,323730353
1592,2025-07-17T16:01:11.820588141Z,2025-07-17T16:01:11.820588141Z,10,2,1108,A,A,0,13.630000000,100,130,165475,270509970,13.04,2,1,13.62,15,1,13.03,100,1,13.63,100,1,13.02,100,1,13.65,100,1,12.73,100,1,13.66,15,1,12.71,100,1,13.97,100,1,12.50,700,1,14.01,2,1,12.46,200,1,14.28,100,1,12.43,700,1,14.40,100,1,12.42,700,1,14.53,100,1,12.37,700,1,14.54,100,1,ARL,324186213
1593,2025-07-17T16:01:11.821349600Z,2025-07-17T16:01:11.821349600Z,10,2,1108,C,A,0,14.730000000,100,0,165443,270509983,13.04,2,1,13.62,15,1,13.03,100,1,13.63,100,1,13.02,100,1,13.65,100,1,12.73,100,1,13.66,15,1,12.71,100,1,13.97,100,1,12.50,700,1,14.01,2,1,12.46,200,1,14.28,100,1,12.43,700,1,14.40,100,1,12.42,700,1,14.53,100,1,12.37,700,1,14.54,100,1,ARL,323730369
1594,2025-07-17T16:01:11.821349600Z,2025-07-17T16:01:11.821349600Z,10,2,1108,A,A,0,14.690000000,100,130,165443,270509983,13.04,2,1,13.62,15,1,13.03,100,1,13.63,100,1,13.02,100,1,13.65,100,1,12.73,100,1,13.66,15,1,12.71,100,1,13.97,100,1,12.50,700,1,14.01,2,1,12.46,200,1,14.28,100,1,12.43,700,1,14.40,100,1,12.42,700,1,14.53,100,1,12.37,700,1,14.54,100,1,ARL,324186233
1595,2025-07-17T16:01:11.826234488Z,2025-07-17T16:01:11.826234488Z,10,2,1108,C,A,0,13.970000000,100,130,165383,270510142,13.04,2,1,13.62,15,1,13.03,100,1,13.63,100,1,13.02,100,1,13.65,100,1,12.73,100,1,13.66,15,1,12.71,100,1,14.01,2,1,12.50,700,1,14.28,100,1,12.46,200,1,14.40,100,1,12.43,700,1,14.53,100,1,12.42,700,1,14.54,100,1,12.37,700,1,14.56,800,1,ARL,323599765
1596,2025-07-17T16:01:11.826286284Z,2025-07-17T16:01:11.826286284Z,10,2,1108,A,A,0,13.900000000,100,130,165163,270510143,13.04,2,1,13.62,15,1,13.03,100,1,13.63,100,1,13.02,100,1,13.65,100,1,12.73,100,1,13.66,15,1,12.71,100,1,13.90,100,1,12.50,700,1,14.01,2,1,12.46,200,1,14.28,100,1,12.43,700,1,14.40,100,1,12.42,700,1,14.53,100,1,12.37,700,1,14.54,100,1,ARL,324186721
1597,2025-07-17T16:01:11.828464891Z,2025-07-17T16:01:11.828464891Z,10,2,1108,C,A,0,14.580000000,100,0,165523,270510182,13.04,2,1,13.62,15,1,13.03,100,1,13.63,100,1,13.02,100,1,13.65,100,1,12.73,100,1,13.66,15,1,12.71,100,1,13.90,100,1,12.50,700,1,14.01,2,1,12.46,200,1,14.28,100,1,12.43,700,1,14.40,100,1,12.42,700,1,14.53,100,1,12.37,700,1,14.54,100,1,ARL,321309941
1598,2025-07-17T16:01:11.828464891Z,2025-07-17T16:01:11.828464891Z,10,2,1108,A,A,0,14.430000000,100,130,165523,270510182,13.04,2,1,13.62,15,1,13.03,100,1,13.63,100,1,13.02,100,1,13.65,100,1,12.73,100,1,13.66,15,1,12.71,100,1,13.90,100,1,12.50,700,1,14.01,2,1,12.46,200,1,14.28,100,1,12.43,700,1,14.40,100,1,12.42,700,1,14.43,100,1,12.37,700,1,14.53,100,1,ARL,324186781
1599,2025-07-17T16:01:22.802353061Z,2025-07-17T16:01:22.802353061Z,10,2,1108,C,A,0,13.660000000,15,130,165475,270674903,13.04,2,1,13.62,15,1,13.03,100,1,13.63,100,1,13.02,100,1,13.65,100,1,12.73,100,1,13.90,100,1,12.71,100,1,14.01,2,1,12.50,700,1,14.28,100,1,12.46,200,1,14.40,100,1,12.43,700,1,14.43,100,1,12.42,700,1,14.53,100,1,12.37,700,1,14.54,100,1,ARL,323720189
1600,2025-07-17T16:01:32.803839043Z,2025-07-17T16:01:32.803839043Z,10,2,1108,A,A,0,13.600000000,15,130,165596,270824320,13.04,2,1,13.60,15,1,13.03,100,1,13.62,15,1,13.02,100,1,13.63,100,1,12.73,100,1,13.65,100,1,12.71,100,1,13.90,100,1,12.50,700,1,14.01,2,1,12.46,200,1,14.28,100,1,12.43,700,1,14.40,100,1,12.42,700,1,14.43,100,1,12.37,700,1,14.53,100,1,ARL,324619361
1601,2025-07-17T16:01:32.804108576Z,2025-07-17T16:01:32.804108576Z,10,2,1108,C,A,0,13.630000000,100,0,165592,270824323,13.04,2,1,13.60,15,1,13.03,100,1,13.62,15,1,13.02,100,1,13.65,100,1,12.73,100,1,13.90,100,1,12.71,100,1,14.01,2,1,12.50,700,1,14.28,100,1,12.46,200,1,14.40,100,1,12.43,700,1,14.43,100,1,12.42,700,1,14.53,100,1,12.37,700,1,14.54,100,1,ARL,324186213
1602,2025-07-17T16:01:32.804108576Z,2025-07-17T16:01:32.804108576Z,10,2,1108,A,A,0,13.610000000,100,130,165592,270824323,13.04,2,1,13.60,15,1,13.03,100,1,13.61,100,1,13.02,100,1,13.62,15,1,12.73,100,1,13.65,100,1,12.71,100,1,13.90,100,1,12.50,700,1,14.01,2,1,12.46,200,1,14.28,100,1,12.43,700,1,14.40,100,1,12.42,700,1,14.43,100,1,12.37,700,1,14.53,100,1,ARL,324619369
1603,2025-07-17T16:01:32.806134020Z,2025-07-17T16:01:32.806134020Z,10,2,1108,C,A,0,14.730000000,100,0,165444,270824400,13.04,2,1,13.60,15,1,13.03,100,1,13.61,100,1,13.02,100,1,13.62,15,1,12.73,100,1,13.65,100,1,12.71,100,1,13.90,100,1,12.50,700,1,14.01,2,1,12.46,200,1,14.28,100,1,12.43,700,1,14.40,100,1,12.42,700,1,14.43,100,1,12.37,700,1,14.53,100,1,ARL,321500349
1604,2025-07-17T16:01:32.806134020Z,2025-07-17T16:01:32.806134020Z,10,2,1108,A,A,0,14.570000000,100,130,165444,270824400,13.04,2,1,13.60,15,1,13.03,100,1,13.61,100,1,13.02,100,1,13.62,15,1,12.73,100,1,13.65,100,1,12.71,100,1,13.90,100,1,12.50,700,1,14.01,2,1,12.46,200,1,14.28,100,1,12.43,700,1,14.40,100,1,12.42,700,1,14.43,100,1,12.37,700,1,14.53,100,1,ARL,324619409
1605,2025-07-17T16:01:32.815748258Z,2025-07-17T16:01:32.815748258Z,10,2,1108,A,A,0,13.630000000,100,130,165262,270824657,13.04,2,1,13.60,15,1,13.03,100,1,13.61,100,1,13.02,100,1,13.62,15,1,12.73,100,1,13.63,100,1,12.71,100,1,13.65,100,1,12.50,700,1,13.90,100,1,12.46,200,1,14.01,2,1,12.43,700,1,14.28,100,1,12.42,700,1,14.40,100,1,12.37,700,1,14.43,100,1,ARL,324619837
1606,2025-07-17T16:01:32.822443626Z,2025-07-17T16:01:32.822443626Z,10,2,1108,C,A,0,13.650000000,100,130,165340,270824747,13.04,2,1,13.60,15,1,13.03,100,1,13.61,100,1,13.02,100,1,13.62,15,1,12.73,100,1,13.63,100,1,12.71,100,1,13.90,100,1,12.50,700,1,14.01,2,1,12.46,200,1,14.28,100,1,12.43,700,1,14.40,100,1,12.42,700,1,14.43,100,1,12.37,700,1,14.53,100,1,ARL,324175569
1607,2025-07-17T16:01:37.242525208Z,2025-07-17T16:01:37.242525208Z,10,2,1108,C,A,0,13.620000000,15,130,165212,270889017,13.04,2,1,13.60,15,1,13.03,100,1,13.61,100,1,13.02,100,1,13.63,100,1,12.73,100,1,13.90,100,1,12.71,100,1,14.01,2,1,12.50,700,1,14.28,100,1,12.46,200,1,14.40,100,1,12.43,700,1,14.43,100,1,12.42,700,1,14.53,100,1,12.37,700,1,14.54,100,1,ARL,324161541
1608,2025-07-17T16:01:40.605632399Z,2025-07-17T16:01:40.605632399Z,10,2,1108,A,A,0,13.610000000,100,130,165366,270946497,13.04,2,1,13.60,15,1,13.03,100,1,13.61,200,1,13.02,100,1,13.63,100,1,12.73,100,1,13.90,100,1,12.71,100,1,14.01,2,1,12.50,700,1,14.28,100,1,12.46,200,1,14.40,100,1,12.43,700,1,14.43,100,1,12.42,700,1,14.53,100,1,12.37,700,1,14.54,100,1,ARL,324782841
1609,2025-07-17T16:01:40.653572805Z,2025-07-17T16:01:40.653572805Z,10,2,1108,C,A,0,13.630000000,100,130,165371,270946779,13.04,2,1,13.60,15,1,13.03,100,1,13.61,200,1,13.02,100,1,13.90,100,1,12.73,100,1,14.01,2,1,12.71,100,1,14.28,100,1,12.50,700,1,14.40,100,1,12.46,200,1,14.43,100,1,12.43,700,1,14.53,100,1,12.42,700,1,14.54,100,1,12.37,700,1,14.56,800,1,ARL,324619837
1610,2025-07-17T16:01:47.565825466Z,2025-07-17T16:01:47.565825466Z,10,2,1108,A,A,0,13.570000000,15,128,166218,271062350,13.04,2,1,13.57,15,1,13.03,100,1,13.60,15,1,13.02,100,1,13.61,200,1,12.73,100,1,13.90,100,1,12.71,100,1,14.01,2,1,12.50,700,1,14.28,100,1,12.46,200,1,14.40,100,1,12.43,700,1,14.43,100,1,12.42,700,1,14.53,100,1,12.37,700,1,14.54,100,1,ARL,324934601
1611,2025-07-17T16:01:47.902804446Z,2025-07-17T16:01:47.902804446Z,10,2,1108,C,A,0,13.610000000,100,0,165327,271068098,13.04,2,1,13.57,15,1,13.03,100,1,13.60,15,1,13.02,100,1,13.61,100,1,12.73,100,1,13.90,100,1,12.71,100,1,14.01,2,1,12.50,700,1,14.28,100,1,12.46,200,1,14.40,100,1,12.43,700,1,14.43,100,1,12.42,700,1,14.53,100,1,12.37,700,1,14.54,100,1,ARL,324619369
1612,2025-07-17T16:01:47.902804446Z,2025-07-17T16:01:47.902804446Z,10,2,1108,A,A,0,13.580000000,100,130,165327,271068098,13.04,2,1,13.57,15,1,13.03,100,1,13.58,100,1,13.02,100,1,13.60,15,1,12.73,100,1,13.61,100,1,12.71,100,1,13.90,100,1,12.50,700,1,14.01,2,1,12.46,200,1,14.28,100,1,12.43,700,1,14.40,100,1,12.42,700,1,14.43,100,1,12.37,700,1,14.53,100,1,ARL,324942229
1613,2025-07-17T16:01:47.903546622Z,2025-07-17T16:01:47.903546622Z,10,2,1108,C,A,0,14.400000000,100,130,165135,271068105,13.04,2,1,13.57,15,1,13.03,100,1,13.58,100,1,13.02,100,1,13.60,15,1,12.73,100,1,13.61,100,1,12.71,100,1,13.90,100,1,12.50,700,1,14.01,2,1,12.46,200,1,14.28,100,1,12.43,700,1,14.43,100,1,12.42,700,1,14.53,100,1,12.37,700,1,14.54,100,1,ARL,289726421
1614,2025-07-17T16:01:47.903548861Z,2025-07-17T16:01:47.903548861Z,10,2,1108,C,A,0,14.690000000,100,0,165462,271068106,13.04,2,1,13.57,15,1,13.03,100,1,13.58,100,1,13.02,100,1,13.60,15,1,12.73,100,1,13.61,100,1,12.71,100,1,13.90,100,1,12.50,700,1,14.01,2,1,12.46,200,1,14.28,100,1,12.43,700,1,14.43,100,1,12.42,700,1,14.53,100,1,12.37,700,1,14.54,100,1,ARL,324186233
1615,2025-07-17T16:01:47.903548861Z,2025-07-17T16:01:47.903548861Z,10,2,1108,A,A,0,14.630000000,100,130,165462,271068106,13.04,2,1,13.57,15,1,13.03,100,1,13.58,100,1,13.02,100,1,13.60,15,1,12.73,100,1,13.61,100,1,12.71,100,1,13.90,100,1,12.50,700,1,14.01,2,1,12.46,200,1,14.28,100,1,12.43,700,1,14.43,100,1,12.42,700,1,14.53,100,1,12.37,700,1,14.54,100,1,ARL,324942257
1616,2025-07-17T16:01:47.903902473Z,2025-07-17T16:01:47.903902473Z,10,2,1108,A,A,0,14.190000000,100,130,165213,271068115,13.04,2,1,13.57,15,1,13.03,100,1,13.58,100,1,13.02,100,1,13.60,15,1,12.73,100,1,13.61,100,1,12.71,100,1,13.90,100,1,12.50,700,1,14.01,2,1,12.46,200,1,14.19,100,1,12.43,700,1,14.28,100,1,12.42,700,1,14.43,100,1,12.37,700,1,14.53,100,1,ARL,324942273
1617,2025-07-17T16:01:47.905189816Z,2025-07-17T16:01:47.905189816Z,10,2,1108,C,A,0,15.230000000,100,0,165963,271068134,13.04,2,1,13.57,15,1,13.03,100,1,13.58,100,1,13.02,100,1,13.60,15,1,12.73,100,1,13.61,100,1,12.71,100,1,13.90,100,1,12.50,700,1,14.01,2,1,12.46,200,1,14.19,100,1,12.43,700,1,14.28,100,1,12.42,700,1,14.43,100,1,12.37,700,1,14.53,100,1,ARL,282776017
1618,2025-07-17T16:01:47.905189816Z,2025-07-17T16:01:47.905189816Z,10,2,1108,A,A,0,14.940000000,100,130,165963,271068134,13.04,2,1,13.57,15,1,13.03,100,1,13.58,100,1,13.02,100,1,13.60,15,1,12.73,100,1,13.61,100,1,12.71,100,1,13.90,100,1,12.50,700,1,14.01,2,1,12.46,200,1,14.19,100,1,12.43,700,1,14.28,100,1,12.42,700,1,14.43,100,1,12.37,700,1,14.53,100,1,ARL,324942277
1619,2025-07-17T16:01:47.909314303Z,2025-07-17T16:01:47.909314303Z,10,2,1108,C,A,0,17.400000000,100,0,165421,271068173,13.04,2,1,13.57,15,1,13.03,100,1,13.58,100,1,13.02,100,1,13.60,15,1,12.73,100,1,13.61,100,1,12.71,100,1,13.90,100,1,12.50,700,1,14.01,2,1,12.46,200,1,14.19,100,1,12.43,700,1,14.28,100,1,12.42,700,1,14.43,100,1,12.37,700,1,14.53,100,1,ARL,323599633
1620,2025-07-17T16:01:47.909314303Z,2025-07-17T16:01:47.909314303Z,10,2,1108,A,A,0,17.250000000,100,130,165421,271068173,13.04,2,1,13.57,15,1,13.03,100,1,13.58,100,1,13.02,100,1,13.60,15,1,12.73,100,1,13.61,100,1,12.71,100,1,13.90,100,1,12.50,700,1,14.01,2,1,12.46,200,1,14.19,100,1,12.43,700,1,14.28,100,1,12.42,700,1,14.43,100,1,12.37,700,1,14.53,100,1,ARL,324942361
1621,2025-07-17T16:01:50.798934838Z,2025-07-17T16:01:50.798934838Z,10,2,1108,A,A,0,13.590000000,100,130,165666,271131418,13.04,2,1,13.57,15,1,13.03,100,1,13.58,100,1,13.02,100,1,13.59,100,1,12.73,100,1,13.60,15,1,12.71,100,1,13.61,100,1,12.50,700,1,13.90,100,1,12.46,200,1,14.01,2,1,12.43,700,1,14.19,100,1,12.42,700,1,14.28,100,1,12.37,700,1,14.43,100,1,ARL,325022101
1622,2025-07-17T16:01:50.805488726Z,2025-07-17T16:01:50.805488726Z,10,2,1108,C,A,0,13.610000000,100,130,165235,271131583,13.04,2,1,13.57,15,1,13.03,100,1,13.58,100,1,13.02,100,1,13.59,100,1,12.73,100,1,13.60,15,1,12.71,100,1,13.90,100,1,12.50,700,1,14.01,2,1,12.46,200,1,14.19,100,1,12.43,700,1,14.28,100,1,12.42,700,1,14.43,100,1,12.37,700,1,14.53,100,1,ARL,324782841
1623,2025-07-17T16:01:52.132898568Z,2025-07-17T16:01:52.132898568Z,10,2,1108,C,A,0,13.600000000,15,130,165193,271153294,13.04,2,1,13.57,15,1,13.03,100,1,13.58,100,1,13.02,100,1,13.59,100,1,12.73,100,1,13.90,100,1,12.71,100,1,14.01,2,1,12.50,700,1,14.19,100,1,12.46,200,1,14.28,100,1,12.43,700,1,14.43,100,1,12.42,700,1,14.53,100,1,12.37,700,1,14.54,100,1,ARL,324619361
1624,2025-07-17T16:01:53.137336077Z,2025-07-17T16:01:53.137336077Z,10,2,1108,A,A,0,13.550000000,15,130,165885,271200452,13.04,2,1,13.55,15,1,13.03,100,1,13.57,15,1,13.02,100,1,13.58,100,1,12.73,100,1,13.59,100,1,12.71,100,1,13.90,100,1,12.50,700,1,14.01,2,1,12.46,200,1,14.19,100,1,12.43,700,1,14.28,100,1,12.42,700,1,14.43,100,1,12.37,700,1,14.53,100,1,ARL,325109165
1625,2025-07-17T16:01:56.263988198Z,2025-07-17T16:01:56.263988198Z,10,2,1108,C,A,0,13.580000000,100,0,165897,271251019,13.04,2,1,13.55,15,1,13.03,100,1,13.57,15,1,13.02,100,1,13.59,100,1,12.73,100,1,13.90,100,1,12.71,100,1,14.01,2,1,12.50,700,1,14.19,100,1,12.46,200,1,14.28,100,1,12.43,700,1,14.43,100,1,12.42,700,1,14.53,100,1,12.37,700,1,14.54,100,1,ARL,324942229
1626,2025-07-17T16:01:56.263988198Z,2025-07-17T16:01:56.263988198Z,10,2,1108,A,A,0,13.560000000,100,130,165897,271251019,13.04,2,1,13.55,15,1,13.03,100,1,13.56,100,1,13.02,100,1,13.57,15,1,12.73,100,1,13.59,100,1,12.71,100,1,13.90,100,1,12.50,700,1,14.01,2,1,12.46,200,1,14.19,100,1,12.43,700,1,14.28,100,1,12.42,700,1,14.43,100,1,12.37,700,1,14.53,100,1,ARL,325176181
1627,2025-07-17T16:01:56.269458197Z,2025-07-17T16:01:56.269458197Z,10,2,1108,C,A,0,13.900000000,100,130,165591,271251357,13.04,2,1,13.55,15,1,13.03,100,1,13.56,100,1,13.02,100,1,13.57,15,1,12.73,100,1,13.59,100,1,12.71,100,1,14.01,2,1,12.50,700,1,14.19,100,1,12.46,200,1,14.28,100,1,12.43,700,1,14.43,100,1,12.42,700,1,14.53,100,1,12.37,700,1,14.54,100,1,ARL,324186721
1628,2025-07-17T16:01:56.269508928Z,2025-07-17T16:01:56.269508928Z,10,2,1108,A,A,0,13.830000000,100,130,165304,271251358,13.04,2,1,13.55,15,1,13.03,100,1,13.56,100,1,13.02,100,1,13.57,15,1,12.73,100,1,13.59,100,1,12.71,100,1,13.83,100,1,12.50,700,1,14.01,2,1,12.46,200,1,14.19,100,1,12.43,700,1,14.28,100,1,12.42,700,1,14.43,100,1,12.37,700,1,14.53,100,1,ARL,325176373
1629,2025-07-17T16:01:56.272175169Z,2025-07-17T16:01:56.272175169Z,10,2,1108,C,A,0,15.760000000,100,0,165561,271251490,13.04,2,1,13.55,15,1,13.03,100,1,13.56,100,1,13.02,100,1,13.57,15,1,12.73,100,1,13.59,100,1,12.71,100,1,13.83,100,1,12.50,700,1,14.01,2,1,12.46,200,1,14.19,100,1,12.43,700,1,14.28,100,1,12.42,700,1,14.43,100,1,12.37,700,1,14.53,100,1,ARL,323599629
1630,2025-07-17T16:01:56.272175169Z,2025-07-17T16:01:56.272175169Z,10,2,1108,A,A,0,15.600000000,100,130,165561,271251490,13.04,2,1,13.55,15,1,13.03,100,1,13.56,100,1,13.02,100,1,13.57,15,1,12.73,100,1,13.59,100,1,12.71,100,1,13.83,100,1,12.50,700,1,14.01,2,1,12.46,200,1,14.19,100,1,12.43,700,1,14.28,100,1,12.42,700,1,14.43,100,1,12.37,700,1,14.53,100,1,ARL,325176677
1631,2025-07-17T16:01:56.300723805Z,2025-07-17T16:01:56.300723805Z,10,2,1108,C,A,0,14.660000000,100,0,165573,271252044,13.04,2,1,13.55,15,1,13.03,100,1,13.56,100,1,13.02,100,1,13.57,15,1,12.73,100,1,13.59,100,1,12.71,100,1,13.83,100,1,12.50,700,1,14.01,2,1,12.46,200,1,14.19,100,1,12.43,700,1,14.28,100,1,12.42,700,1,14.43,100,1,12.37,700,1,14.53,100,1,ARL,323599625
1632,2025-07-17T16:01:56.300723805Z,2025-07-17T16:01:56.300723805Z,10,2,1108,A,A,0,14.510000000,100,130,165573,271252044,13.04,2,1,13.55,15,1,13.03,100,1,13.56,100,1,13.02,100,1,13.57,15,1,12.73,100,1,13.59,100,1,12.71,100,1,13.83,100,1,12.50,700,1,14.01,2,1,12.46,200,1,14.19,100,1,12.43,700,1,14.28,100,1,12.42,700,1,14.43,100,1,12.37,700,1,14.51,100,1,ARL,325177757
1633,2025-07-17T16:01:56.776814001Z,2025-07-17T16:01:56.776814001Z,10,2,1108,T,N,0,13.410000000,16,130,166243,271255700,13.04,2,1,13.55,15,1,13.03,100,1,13.56,100,1,13.02,100,1,13.57,15,1,12.73,100,1,13.59,100,1,12.71,100,1,13.83,100,1,12.50,700,1,14.01,2,1,12.46,200,1,14.19,100,1,12.43,700,1,14.28,100,1,12.42,700,1,14.43,100,1,12.37,700,1,14.51,100,1,ARL,0
1634,2025-07-17T16:01:56.777248616Z,2025-07-17T16:01:56.777248616Z,10,2,1108,T,N,0,13.410000000,16,130,165716,271255708,13.04,2,1,13.55,15,1,13.03,100,1,13.56,100,1,13.02,100,1,13.57,15,1,12.73,100,1,13.59,100,1,12.71,100,1,13.83,100,1,12.50,700,1,14.01,2,1,12.46,200,1,14.19,100,1,12.43,700,1,14.28,100,1,12.42,700,1,14.43,100,1,12.37,700,1,14.51,100,1,ARL,0
1635,2025-07-17T16:01:56.777739254Z,2025-07-17T16:01:56.777739254Z,10,2,1108,T,N,0,13.410000000,4,130,166815,271255712,13.04,2,1,13.55,15,1,13.03,100,1,13.56,100,1,13.02,100,1,13.57,15,1,12.73,100,1,13.59,100,1,12.71,100,1,13.83,100,1,12.50,700,1,14.01,2,1,12.46,200,1,14.19,100,1,12.43,700,1,14.28,100,1,12.42,700,1,14.43,100,1,12.37,700,1,14.51,100,1,ARL,0
1636,2025-07-17T16:02:01.992379223Z,2025-07-17T16:02:01.992379223Z,10,2,1108,C,A,0,14.010000000,2,0,165384,271343251,13.04,2,1,13.55,15,1,13.03,100,1,13.56,100,1,13.02,100,1,13.57,15,1,12.73,100,1,13.59,100,1,12.71,100,1,13.83,100,1,12.50,700,1,14.19,100,1,12.46,200,1,14.28,100,1,12.43,700,1,14.43,100,1,12.42,700,1,14.51,100,1,12.37,700,1,14.53,100,1,ARL,322898193
1637,2025-07-17T16:02:01.992379223Z,2025-07-17T16:02:01.992379223Z,10,2,1108,A,A,0,13.920000000,2,130,165384,271343251,13.04,2,1,13.55,15,1,13.03,100,1,13.56,100,1,13.02,100,1,13.57,15,1,12.73,100,1,13.59,100,1,12.71,100,1,13.83,100,1,12.50,700,1,13.92,2,1,12.46,200,1,14.19,100,1,12.43,700,1,14.28,100,1,12.42,700,1,14.43,100,1,12.37,700,1,14.51,100,1,ARL,325297093
1638,2025-07-17T16:02:03.207555626Z,2025-07-17T16:02:03.207555626Z,10,2,1108,C,A,0,13.570000000,15,130,165200,271367066,13.04,2,1,13.55,15,1,13.03,100,1,13.56,100,1,13.02,100,1,13.59,100,1,12.73,100,1,13.83,100,1,12.71,100,1,13.92,2,1,12.50,700,1,14.19,100,1,12.46,200,1,14.28,100,1,12.43,700,1,14.43,100,1,12.42,700,1,14.51,100,1,12.37,700,1,14.53,100,1,ARL,324934601
1639,2025-07-17T16:02:04.212791108Z,2025-07-17T16:02:04.212791108Z,10,2,1108,A,A,0,13.530000000,15,130,165231,271415821,13.04,2,1,13.53,15,1,13.03,100,1,13.55,15,1,13.02,100,1,13.56,100,1,12.73,100,1,13.59,100,1,12.71,100,1,13.83,100,1,12.50,700,1,13.92,2,1,12.46,200,1,14.19,100,1,12.43,700,1,14.28,100,1,12.42,700,1,14.43,100,1,12.37,700,1,14.51,100,1,ARL,325382429
1640,2025-07-17T16:02:04.214183279Z,2025-07-17T16:02:04.214183279Z,10,2,1108,C,A,0,14.540000000,100,0,165535,271415834,13.04,2,1,13.53,15,1,13.03,100,1,13.55,15,1,13.02,100,1,13.56,100,1,12.73,100,1,13.59,100,1,12.71,100,1,13.83,100,1,12.50,700,1,13.92,2,1,12.46,200,1,14.19,100,1,12.43,700,1,14.28,100,1,12.42,700,1,14.43,100,1,12.37,700,1,14.51,100,1,ARL,323775433
1641,2025-07-17T16:02:04.214183279Z,2025-07-17T16:02:04.214183279Z,10,2,1108,A,A,0,14.430000000,100,130,165535,271415834,13.04,2,1,13.53,15,1,13.03,100,1,13.55,15,1,13.02,100,1,13.56,100,1,12.73,100,1,13.59,100,1,12.71,100,1,13.83,100,1,12.50,700,1,13.92,2,1,12.46,200,1,14.19,100,1,12.43,700,1,14.28,100,1,12.42,700,1,14.43,200,1,12.37,700,1,14.51,100,1,ARL,325382437
1642,2025-07-17T16:02:04.839967173Z,2025-07-17T16:02:04.839967173Z,10,2,1108,C,A,0,13.560000000,100,0,165495,271432190,13.04,2,1,13.53,15,1,13.03,100,1,13.55,15,1,13.02,100,1,13.59,100,1,12.73,100,1,13.83,100,1,12.71,100,1,13.92,2,1,12.50,700,1,14.19,100,1,12.46,200,1,14.28,100,1,12.43,700,1,14.43,200,1,12.42,700,1,14.51,100,1,12.37,700,1,14.53,100,1,ARL,325176181
1643,2025-07-17T16:02:04.839967173Z,2025-07-17T16:02:04.839967173Z,10,2,1108,A,A,0,13.540000000,100,130,165495,271432190,13.04,2,1,13.53,15,1,13.03,100,1,13.54,100,1,13.02,100,1,13.55,15,1,12.73,100,1,13.59,100,1,12.71,100,1,13.83,100,1,12.50,700,1,13.92,2,1,12.46,200,1,14.19,100,1,12.43,700,1,14.28,100,1,12.42,700,1,14.43,200,1,12.37,700,1,14.51,100,1,ARL,325400045
1644,2025-07-17T16:02:04.840006082Z,2025-07-17T16:02:04.840006082Z,10,2,1108,A,A,0,14.270000000,700,130,165158,271432192,13.04,2,1,13.53,15,1,13.03,100,1,13.54,100,1,13.02,100,1,13.55,15,1,12.73,100,1,13.59,100,1,12.71,100,1,13.83,100,1,12.50,700,1,13.92,2,1,12.46,200,1,14.19,100,1,12.43,700,1,14.27,700,1,12.42,700,1,14.28,100,1,12.37,700,1,14.43,200,1,ARL,325400053
1645,2025-07-17T16:02:04.840045694Z,2025-07-17T16:02:04.840045694Z,10,2,1108,C,A,0,14.680000000,700,130,165186,271432193,13.04,2,1,13.53,15,1,13.03,100,1,13.54,100,1,13.02,100,1,13.55,15,1,12.73,100,1,13.59,100,1,12.71,100,1,13.83,100,1,12.50,700,1,13.92,2,1,12.46,200,1,14.19,100,1,12.43,700,1,14.27,700,1,12.42,700,1,14.28,100,1,12.37,700,1,14.43,200,1,ARL,283592941
1646,2025-07-17T16:02:04.840711803Z,2025-07-17T16:02:04.840711803Z,10,2,1108,C,A,0,14.630000000,100,0,165800,271432231,13.04,2,1,13.53,15,1,13.03,100,1,13.54,100,1,13.02,100,1,13.55,15,1,12.73,100,1,13.59,100,1,12.71,100,1,13.83,100,1,12.50,700,1,13.92,2,1,12.46,200,1,14.19,100,1,12.43,700,1,14.27,700,1,12.42,700,1,14.28,100,1,12.37,700,1,14.43,200,1,ARL,324942257
1647,2025-07-17T16:02:04.840711803Z,2025-07-17T16:02:04.840711803Z,10,2,1108,A,A,0,14.590000000,100,130,165800,271432231,13.04,2,1,13.53,15,1,13.03,100,1,13.54,100,1,13.02,100,1,13.55,15,1,12.73,100,1,13.59,100,1,12.71,100,1,13.83,100,1,12.50,700,1,13.92,2,1,12.46,200,1,14.19,100,1,12.43,700,1,14.27,700,1,12.42,700,1,14.28,100,1,12.37,700,1,14.43,200,1,ARL,325400105
1648,2025-07-17T16:02:11.249125653Z,2025-07-17T16:02:11.249125653Z,10,2,1108,C,A,0,14.530000000,100,0,165489,271526467,13.04,2,1,13.53,15,1,13.03,100,1,13.54,100,1,13.02,100,1,13.55,15,1,12.73,100,1,13.59,100,1,12.71,100,1,13.83,100,1,12.50,700,1,13.92,2,1,12.46,200,1,14.19,100,1,12.43,700,1,14.27,700,1,12.42,700,1,14.28,100,1,12.37,700,1,14.43,200,1,ARL,323775457
1649,2025-07-17T16:02:11.249125653Z,2025-07-17T16:02:11.249125653Z,10,2,1108,A,A,0,14.420000000,100,130,165489,271526467,13.04,2,1,13.53,15,1,13.03,100,1,13.54,100,1,13.02,100,1,13.55,15,1,12.73,100,1,13.59,100,1,12.71,100,1,13.83,100,1,12.50,700,1,13.92,2,1,12.46,200,1,14.19,100,1,12.43,700,1,14.27,700,1,12.42,700,1,14.28,100,1,12.37,700,1,14.42,100,1,ARL,325520705
1650,2025-07-17T16:02:15.062605521Z,2025-07-17T16:02:15.062605521Z,10,2,1108,C,A,0,13.530000000,15,128,169140,271576282,13.04,2,1,13.54,100,1,13.03,100,1,13.55,15,1,13.02,100,1,13.59,100,1,12.73,100,1,13.83,100,1,12.71,100,1,13.92,2,1,12.50,700,1,14.19,100,1,12.46,200,1,14.27,700,1,12.43,700,1,14.28,100,1,12.42,700,1,14.42,100,1,12.37,700,1,14.43,200,1,ARL,325382429
1651,2025-07-17T16:02:15.068283706Z,2025-07-17T16:02:15.068283706Z,10,2,1108,C,A,0,13.550000000,15,130,165342,271577104,13.04,2,1,13.54,100,1,13.03,100,1,13.59,100,1,13.02,100,1,13.83,100,1,12.73,100,1,13.92,2,1,12.71,100,1,14.19,100,1,12.50,700,1,14.27,700,1,12.46,200,1,14.28,100,1,12.43,700,1,14.42,100,1,12.42,700,1,14.43,200,1,12.37,700,1,14.51,100,1,ARL,325109165
